<?xml version="1.0" ?>
<!-- =================================================================================== -->
<!-- |    This document was autogenerated by xacro from /home/neal/ws_humble/src/human_description/robots/M92C/M92C.urdf.xacro | -->
<!-- |    EDITING THIS FILE BY HAND IS NOT RECOMMENDED                                 | -->
<!-- =================================================================================== -->
<robot name="M92C">
  <link name="base_footprint">
            </link>
  <joint name="base_footprint_fixed_joint" type="fixed">
    <parent link="base_footprint"/>
    <child link="base_link"/>
    <origin rpy="0 0 0" xyz="0 0 0.95"/>
  </joint>
  <link name="base_link">
    <visual name="base_link_vis">
      <geometry>
        <mesh filename="package://human_description/meshes/M92C/visual/base_link.stl" scale="1e-3 1e-3 1e-3"/>
      </geometry>
      <material name="steel">
        <color rgba="0.7 0.65 0.55 1"/>
      </material>
    </visual>
    <collision name="base_link_col">
      <geometry>
        <mesh filename="package://human_description/meshes/M92C/collision/base_link.stl" scale="1e-3 1e-3 1e-3"/>
      </geometry>
    </collision>
    <inertial>
      <origin rpy="0.0 0.0 0.0" xyz="-0.04674316973808486 4.243775826414283e-05 -0.04593932252884735"/>
      <mass value="4.582832371613902"/>
      <inertia ixx="0.026938242317904135" ixy="0.00016805004318506462" ixz="0.00031440502263900636" iyy="0.0069147873987483125" iyz="-0.00017810480444606385" izz="0.029031175439499908"/>
    </inertial>
  </link>
  <gazebo reference="base_link">
    <mu1 value="0.85"/>
    <mu2 value="0.85"/>
    <maxContacts>10</maxContacts>
    <minDepth>0.0001</minDepth>
    <maxVel>0.01</maxVel>
    <selfCollide value="True"/>
  </gazebo>
  <link name="l_leg1_hip_y_link">
    <visual name="l_leg1_hip_y_link_vis">
      <geometry>
        <mesh filename="package://human_description/meshes/M92C/visual/l_leg1_hip_y_link.stl" scale="1e-3 1e-3 1e-3"/>
      </geometry>
      <material name="metal">
        <color rgba="0.85 0.85 0.85 1"/>
      </material>
    </visual>
    <collision name="l_leg1_hip_y_link_col">
      <geometry>
        <mesh filename="package://human_description/meshes/M92C/collision/l_leg1_hip_y_link.stl" scale="1e-3 1e-3 1e-3"/>
      </geometry>
    </collision>
    <inertial>
      <origin rpy="0.0 0.0 0.0" xyz="0.0008850229572728041 5.843723944565227e-06 0.002410102237999933"/>
      <mass value="1.6682261293788896"/>
      <inertia ixx="0.0016489016346544062" ixy="1.1338909680756251e-06" ixz="-4.594603902098548e-05" iyy="0.0015528054330462516" iyz="2.3316569553201646e-07" izz="0.0013879925130855925"/>
    </inertial>
  </link>
  <gazebo reference="l_leg1_hip_y_link">
    <mu1 value="0.85"/>
    <mu2 value="0.85"/>
    <maxContacts>10</maxContacts>
    <minDepth>0.0001</minDepth>
    <maxVel>0.01</maxVel>
    <selfCollide value="True"/>
  </gazebo>
  <joint name="l_leg1_hip_y_joint" type="revolute">
    <parent link="base_link"/>
    <child link="l_leg1_hip_y_link"/>
    <origin rpy="0.0 0.7854 0.0" xyz="-0.108293 0.075 -0.108293"/>
    <axis xyz="0 0 1"/>
    <limit effort="200.0" lower="-0.7853981633974483" upper="1.5707963267948966" velocity="22.19"/>
    <safety_controller k_position="121.0" k_velocity="540.0" soft_lower_limit="-0.7330382858376184" soft_upper_limit="1.5184364492350666"/>
    <dynamics damping="0.0" friction="0.0"/>
  </joint>
  <gazebo reference="l_leg1_hip_y_joint">
    <!-- Needed for ODE to output external wrenches on joints -->
    <provideFeedback>true</provideFeedback>
    <preserveFixedJoint>true</preserveFixedJoint>
    <disableFixedJointLumping>true</disableFixedJointLumping>
  </gazebo>
  <link name="l_leg2_hip_r_link">
    <visual name="l_leg2_hip_r_link_vis">
      <geometry>
        <mesh filename="package://human_description/meshes/M92C/visual/l_leg2_hip_r_link.stl" scale="1e-3 1e-3 1e-3"/>
      </geometry>
      <material name="metal">
        <color rgba="0.85 0.85 0.85 1"/>
      </material>
    </visual>
    <collision name="l_leg2_hip_r_link_col">
      <geometry>
        <mesh filename="package://human_description/meshes/M92C/collision/l_leg2_hip_r_link.stl" scale="1e-3 1e-3 1e-3"/>
      </geometry>
    </collision>
    <inertial>
      <origin rpy="0.0 0.0 0.0" xyz="0.14900213418763666 0.0021476222290698816 8.845763064364575e-05"/>
      <mass value="4.007992430034036"/>
      <inertia ixx="0.011693994358873725" ixy="-9.274739833332958e-06" ixz="-8.624794970012456e-05" iyy="0.02343703854529649" iyz="1.1322262112806104e-05" izz="0.013482601595282608"/>
    </inertial>
  </link>
  <gazebo reference="l_leg2_hip_r_link">
    <mu1 value="0.85"/>
    <mu2 value="0.85"/>
    <maxContacts>10</maxContacts>
    <minDepth>0.0001</minDepth>
    <maxVel>0.01</maxVel>
    <selfCollide value="True"/>
  </gazebo>
  <joint name="l_leg2_hip_r_joint" type="revolute">
    <parent link="l_leg1_hip_y_link"/>
    <child link="l_leg2_hip_r_link"/>
    <origin rpy="0.0 0.0 0.0" xyz="0.0 0.0 0.0"/>
    <axis xyz="1 0 0"/>
    <limit effort="100.0" lower="-0.7853981633974483" upper="0.7853981633974483" velocity="20.22"/>
    <safety_controller k_position="121.0" k_velocity="540.0" soft_lower_limit="-0.7330382858376184" soft_upper_limit="0.7330382858376184"/>
    <dynamics damping="0.0" friction="0.0"/>
  </joint>
  <gazebo reference="l_leg2_hip_r_joint">
    <!-- Needed for ODE to output external wrenches on joints -->
    <provideFeedback>true</provideFeedback>
    <preserveFixedJoint>true</preserveFixedJoint>
    <disableFixedJointLumping>true</disableFixedJointLumping>
  </gazebo>
  <link name="l_leg3_hip_p_link">
    <visual name="l_leg3_hip_p_link_vis">
      <geometry>
        <mesh filename="package://human_description/meshes/M92C/visual/l_leg3_hip_p_link.stl" scale="1e-3 1e-3 1e-3"/>
      </geometry>
      <material name="metal">
        <color rgba="0.85 0.85 0.85 1"/>
      </material>
    </visual>
    <collision name="l_leg3_hip_p_link_col">
      <geometry>
        <mesh filename="package://human_description/meshes/M92C/collision/l_leg3_hip_p_link.stl" scale="1e-3 1e-3 1e-3"/>
      </geometry>
    </collision>
    <inertial>
      <origin rpy="0.0 0.0 0.0" xyz="0.001777498283024403 0.06609405204667318 -0.06548805431118004"/>
      <mass value="6.861170839249381"/>
      <inertia ixx="0.08209203289624244" ixy="4.8951279013623674e-05" ixz="0.003804575952713313" iyy="0.09174731120828715" iyz="-0.005732136409648308" izz="0.0210784970572199"/>
    </inertial>
  </link>
  <gazebo reference="l_leg3_hip_p_link">
    <mu1 value="0.85"/>
    <mu2 value="0.85"/>
    <maxContacts>10</maxContacts>
    <minDepth>0.0001</minDepth>
    <maxVel>0.01</maxVel>
    <selfCollide value="True"/>
  </gazebo>
  <joint name="l_leg3_hip_p_joint" type="revolute">
    <parent link="l_leg2_hip_r_link"/>
    <child link="l_leg3_hip_p_link"/>
    <origin rpy="0.0 -0.7854 0.0" xyz="0.1575 0.0 0.0"/>
    <axis xyz="0 1 0"/>
    <limit effort="350.0" lower="-2.321287905152458" upper="1.361356816555577" velocity="27.27"/>
    <safety_controller k_position="121.0" k_velocity="540.0" soft_lower_limit="-2.2689280275926285" soft_upper_limit="1.3089969389957472"/>
    <dynamics damping="0.0" friction="0.0"/>
  </joint>
  <gazebo reference="l_leg3_hip_p_joint">
    <!-- Needed for ODE to output external wrenches on joints -->
    <provideFeedback>true</provideFeedback>
    <preserveFixedJoint>true</preserveFixedJoint>
    <disableFixedJointLumping>true</disableFixedJointLumping>
  </gazebo>
  <link name="l_leg4_knee_p_link">
    <visual name="l_leg4_knee_p_link_vis">
      <geometry>
        <mesh filename="package://human_description/meshes/M92C/visual/l_leg4_knee_p_link.stl" scale="1e-3 1e-3 1e-3"/>
      </geometry>
      <material name="metal">
        <color rgba="0.85 0.85 0.85 1"/>
      </material>
    </visual>
    <collision name="l_leg4_knee_p_link_col">
      <geometry>
        <mesh filename="package://human_description/meshes/M92C/collision/l_leg4_knee_p_link.stl" scale="1e-3 1e-3 1e-3"/>
      </geometry>
    </collision>
    <inertial>
      <origin rpy="0.0 0.0 0.0" xyz="0.026276416699445766 0.0006239679967631234 -0.1669593832478771"/>
      <mass value="3.251382635339728"/>
      <inertia ixx="0.03882460227929094" ixy="-0.0001626615225407489" ixz="0.003120886772307399" iyy="0.03943104044910984" iyz="-0.0003856289904792427" izz="0.004759512026890702"/>
    </inertial>
  </link>
  <gazebo reference="l_leg4_knee_p_link">
    <mu1 value="0.85"/>
    <mu2 value="0.85"/>
    <maxContacts>10</maxContacts>
    <minDepth>0.0001</minDepth>
    <maxVel>0.01</maxVel>
    <selfCollide value="True"/>
  </gazebo>
  <joint name="l_leg4_knee_p_joint" type="revolute">
    <parent link="l_leg3_hip_p_link"/>
    <child link="l_leg4_knee_p_link"/>
    <origin rpy="0.0 0.0 0.0" xyz="0.0 0.0435 -0.35"/>
    <axis xyz="0 1 0"/>
    <limit effort="350.0" lower="-0.17453292519943295" upper="2.651155133779387" velocity="27.27"/>
    <safety_controller k_position="121.0" k_velocity="540.0" soft_lower_limit="-0.12217304763960307" soft_upper_limit="2.5987952562195566"/>
    <dynamics damping="0.0" friction="0.0"/>
  </joint>
  <gazebo reference="l_leg4_knee_p_joint">
    <!-- Needed for ODE to output external wrenches on joints -->
    <provideFeedback>true</provideFeedback>
    <preserveFixedJoint>true</preserveFixedJoint>
    <disableFixedJointLumping>true</disableFixedJointLumping>
  </gazebo>
  <link name="l_leg5_ankle_p_link">
    <visual name="l_leg5_ankle_p_link_vis">
      <geometry>
        <mesh filename="package://human_description/meshes/M92C/visual/l_leg5_ankle_p_link.stl" scale="1e-3 1e-3 1e-3"/>
      </geometry>
      <material name="metal">
        <color rgba="0.85 0.85 0.85 1"/>
      </material>
    </visual>
    <collision name="l_leg5_ankle_p_link_col">
      <geometry>
        <mesh filename="package://human_description/meshes/M92C/collision/l_leg5_ankle_p_link.stl" scale="1e-3 1e-3 1e-3"/>
      </geometry>
    </collision>
    <inertial>
      <origin rpy="0.0 0.0 0.0" xyz="0.0028303307 0.0 0.0"/>
      <mass value="0.11492616"/>
      <inertia ixx="1.4387333e-05" ixy="0.0" ixz="0.0" iyy="2.2649914e-05" iyz="0.0" izz="3.0265224e-05"/>
    </inertial>
  </link>
  <gazebo reference="l_leg5_ankle_p_link">
    <mu1 value="0.85"/>
    <mu2 value="0.85"/>
    <maxContacts>10</maxContacts>
    <minDepth>0.0001</minDepth>
    <maxVel>0.01</maxVel>
    <selfCollide value="True"/>
  </gazebo>
  <joint name="l_leg5_ankle_p_joint" type="revolute">
    <parent link="l_leg4_knee_p_link"/>
    <child link="l_leg5_ankle_p_link"/>
    <origin rpy="0.0 0.0 0.0" xyz="0.0 -0.005 -0.35"/>
    <axis xyz="0 1 0"/>
    <limit effort="150.0" lower="-1.2217304763960306" upper="0.6457718232379019" velocity="33.0"/>
    <safety_controller k_position="121.0" k_velocity="540.0" soft_lower_limit="-1.1693705988362006" soft_upper_limit="0.5934119456780721"/>
    <dynamics damping="0.0" friction="0.0"/>
  </joint>
  <gazebo reference="l_leg5_ankle_p_joint">
    <!-- Needed for ODE to output external wrenches on joints -->
    <provideFeedback>true</provideFeedback>
    <preserveFixedJoint>true</preserveFixedJoint>
    <disableFixedJointLumping>true</disableFixedJointLumping>
  </gazebo>
  <link name="l_leg6_ankle_r_link">
    <visual name="l_leg6_ankle_r_link_vis">
      <geometry>
        <mesh filename="package://human_description/meshes/M92C/visual/l_leg6_ankle_r_link.stl" scale="1e-3 1e-3 1e-3"/>
      </geometry>
      <material name="metal">
        <color rgba="0.85 0.85 0.85 1"/>
      </material>
    </visual>
    <collision name="l_leg6_ankle_r_link_col">
      <geometry>
        <mesh filename="package://human_description/meshes/M92C/collision/l_leg6_ankle_r_link.stl" scale="1e-3 1e-3 1e-3"/>
      </geometry>
    </collision>
    <inertial>
      <origin rpy="0.0 0.0 0.0" xyz="0.05231358618601275 2.8064972453501938e-05 -0.0379930283494815"/>
      <mass value="1.1273201594692528"/>
      <inertia ixx="0.001132228521183826" ixy="-4.766733513667394e-07" ixz="0.00011099562072101504" iyy="0.004074718655562373" iyz="2.367253415282658e-07" izz="0.004449576486150568"/>
    </inertial>
  </link>
  <gazebo reference="l_leg6_ankle_r_link">
    <mu1 value="0.85"/>
    <mu2 value="0.85"/>
    <maxContacts>10</maxContacts>
    <minDepth>0.0001</minDepth>
    <maxVel>0.01</maxVel>
    <selfCollide value="True"/>
  </gazebo>
  <joint name="l_leg6_ankle_r_joint" type="revolute">
    <parent link="l_leg5_ankle_p_link"/>
    <child link="l_leg6_ankle_r_link"/>
    <origin rpy="0.0 0.0 0.0" xyz="0.0 0.0 0.0"/>
    <axis xyz="1 0 0"/>
    <limit effort="150.0" lower="-0.5235987755982988" upper="0.5235987755982988" velocity="33.0"/>
    <safety_controller k_position="121.0" k_velocity="540.0" soft_lower_limit="-0.47123889803846897" soft_upper_limit="0.47123889803846897"/>
    <dynamics damping="0.0" friction="0.0"/>
  </joint>
  <gazebo reference="l_leg6_ankle_r_joint">
    <!-- Needed for ODE to output external wrenches on joints -->
    <provideFeedback>true</provideFeedback>
    <preserveFixedJoint>true</preserveFixedJoint>
    <disableFixedJointLumping>true</disableFixedJointLumping>
  </gazebo>
  <ros2_control name="l_leg_system" type="system">
    <hardware>
      <plugin>ign_ros2_control/IgnitionSystem</plugin>
    </hardware>
    <joint name="l_leg1_hip_y_joint">
      <param name="initial_position">0.0</param>
      <command_interface name="position"/>
      <state_interface name="position">
        <param name="initial_value">0.0</param>
      </state_interface>
      <state_interface name="velocity"/>
      <state_interface name="effort"/>
    </joint>
    <transmission name="l_leg1_hip_y_transmission">
      <plugin>transmission_interface/SimpleTransmission</plugin>
      <joint name="l_leg1_hip_y_joint" role="joint1">
        <mechanical_reduction>1.0</mechanical_reduction>
        <offset>0</offset>
      </joint>
      <actuator name="l_leg1_hip_y_actuator" role="actuator1">
        <mechanical_reduction>1.0</mechanical_reduction>
        <offset>0</offset>
      </actuator>
    </transmission>
    <joint name="l_leg2_hip_r_joint">
      <param name="initial_position">0.0</param>
      <command_interface name="position"/>
      <state_interface name="position">
        <param name="initial_value">0.0</param>
      </state_interface>
      <state_interface name="velocity"/>
      <state_interface name="effort"/>
    </joint>
    <transmission name="l_leg2_hip_r_transmission">
      <plugin>transmission_interface/SimpleTransmission</plugin>
      <joint name="l_leg2_hip_r_joint" role="joint1">
        <mechanical_reduction>1.0</mechanical_reduction>
        <offset>0</offset>
      </joint>
      <actuator name="l_leg2_hip_r_actuator" role="actuator1">
        <mechanical_reduction>1.0</mechanical_reduction>
        <offset>0</offset>
      </actuator>
    </transmission>
    <joint name="l_leg3_hip_p_joint">
      <param name="initial_position">0.0</param>
      <command_interface name="position"/>
      <state_interface name="position">
        <param name="initial_value">0.0</param>
      </state_interface>
      <state_interface name="velocity"/>
      <state_interface name="effort"/>
    </joint>
    <transmission name="l_leg3_hip_p_transmission">
      <plugin>transmission_interface/SimpleTransmission</plugin>
      <joint name="l_leg3_hip_p_joint" role="joint1">
        <mechanical_reduction>1.0</mechanical_reduction>
        <offset>0</offset>
      </joint>
      <actuator name="l_leg3_hip_p_actuator" role="actuator1">
        <mechanical_reduction>1.0</mechanical_reduction>
        <offset>0</offset>
      </actuator>
    </transmission>
    <joint name="l_leg4_knee_p_joint">
      <param name="initial_position">0.0</param>
      <command_interface name="position"/>
      <state_interface name="position">
        <param name="initial_value">0.0</param>
      </state_interface>
      <state_interface name="velocity"/>
      <state_interface name="effort"/>
    </joint>
    <transmission name="l_leg4_knee_p_transmission">
      <plugin>transmission_interface/SimpleTransmission</plugin>
      <joint name="l_leg4_knee_p_joint" role="joint1">
        <mechanical_reduction>1.0</mechanical_reduction>
        <offset>0</offset>
      </joint>
      <actuator name="l_leg4_knee_p_actuator" role="actuator1">
        <mechanical_reduction>1.0</mechanical_reduction>
        <offset>0</offset>
      </actuator>
    </transmission>
    <joint name="l_leg5_ankle_p_joint">
      <param name="initial_position">0.0</param>
      <command_interface name="position"/>
      <state_interface name="position">
        <param name="initial_value">0.0</param>
      </state_interface>
      <state_interface name="velocity"/>
      <state_interface name="effort"/>
    </joint>
    <transmission name="l_leg5_ankle_p_transmission">
      <plugin>transmission_interface/SimpleTransmission</plugin>
      <joint name="l_leg5_ankle_p_joint" role="joint1">
        <mechanical_reduction>1.0</mechanical_reduction>
        <offset>0</offset>
      </joint>
      <actuator name="l_leg5_ankle_p_actuator" role="actuator1">
        <mechanical_reduction>1.0</mechanical_reduction>
        <offset>0</offset>
      </actuator>
    </transmission>
    <joint name="l_leg6_ankle_r_joint">
      <param name="initial_position">0.0</param>
      <command_interface name="position"/>
      <state_interface name="position">
        <param name="initial_value">0.0</param>
      </state_interface>
      <state_interface name="velocity"/>
      <state_interface name="effort"/>
    </joint>
    <transmission name="l_leg6_ankle_r_transmission">
      <plugin>transmission_interface/SimpleTransmission</plugin>
      <joint name="l_leg6_ankle_r_joint" role="joint1">
        <mechanical_reduction>1.0</mechanical_reduction>
        <offset>0</offset>
      </joint>
      <actuator name="l_leg6_ankle_r_actuator" role="actuator1">
        <mechanical_reduction>1.0</mechanical_reduction>
        <offset>0</offset>
      </actuator>
    </transmission>
  </ros2_control>
  <link name="r_leg1_hip_y_link">
    <visual name="r_leg1_hip_y_link_vis">
      <geometry>
        <mesh filename="package://human_description/meshes/M92C/visual/r_leg1_hip_y_link.stl" scale="1e-3 1e-3 1e-3"/>
      </geometry>
      <material name="metal">
        <color rgba="0.85 0.85 0.85 1"/>
      </material>
    </visual>
    <collision name="r_leg1_hip_y_link_col">
      <geometry>
        <mesh filename="package://human_description/meshes/M92C/collision/r_leg1_hip_y_link.stl" scale="1e-3 1e-3 1e-3"/>
      </geometry>
    </collision>
    <inertial>
      <origin rpy="0.0 0.0 0.0" xyz="0.0008850229572728041 5.843723944565227e-06 0.002410102237999933"/>
      <mass value="1.6682261293788896"/>
      <inertia ixx="0.0016489016346544062" ixy="1.1338909680756251e-06" ixz="-4.594603902098548e-05" iyy="0.0015528054330462516" iyz="2.3316569553201646e-07" izz="0.0013879925130855925"/>
    </inertial>
  </link>
  <gazebo reference="r_leg1_hip_y_link">
    <mu1 value="0.85"/>
    <mu2 value="0.85"/>
    <maxContacts>10</maxContacts>
    <minDepth>0.0001</minDepth>
    <maxVel>0.01</maxVel>
    <selfCollide value="True"/>
  </gazebo>
  <joint name="r_leg1_hip_y_joint" type="revolute">
    <parent link="base_link"/>
    <child link="r_leg1_hip_y_link"/>
    <origin rpy="0.0 0.7854 0.0" xyz="-0.108293 -0.075 -0.108293"/>
    <axis xyz="0 0 1"/>
    <limit effort="200.0" lower="-1.5707963267948966" upper="0.7853981633974483" velocity="22.19"/>
    <safety_controller k_position="121.0" k_velocity="540.0" soft_lower_limit="-1.5184364492350666" soft_upper_limit="0.7330382858376184"/>
    <dynamics damping="0.0" friction="0.0"/>
  </joint>
  <gazebo reference="r_leg1_hip_y_joint">
    <!-- Needed for ODE to output external wrenches on joints -->
    <provideFeedback>true</provideFeedback>
    <preserveFixedJoint>true</preserveFixedJoint>
    <disableFixedJointLumping>true</disableFixedJointLumping>
  </gazebo>
  <link name="r_leg2_hip_r_link">
    <visual name="r_leg2_hip_r_link_vis">
      <geometry>
        <mesh filename="package://human_description/meshes/M92C/visual/r_leg2_hip_r_link.stl" scale="1e-3 1e-3 1e-3"/>
      </geometry>
      <material name="metal">
        <color rgba="0.85 0.85 0.85 1"/>
      </material>
    </visual>
    <collision name="r_leg2_hip_r_link_col">
      <geometry>
        <mesh filename="package://human_description/meshes/M92C/collision/r_leg2_hip_r_link.stl" scale="1e-3 1e-3 1e-3"/>
      </geometry>
    </collision>
    <inertial>
      <origin rpy="0.0 0.0 0.0" xyz="0.14900213418763666 -0.0021476222290698816 8.845763064364575e-05"/>
      <mass value="4.007992430034036"/>
      <inertia ixx="0.011693994358873725" ixy="9.274739833332958e-06" ixz="-8.624794970012456e-05" iyy="0.02343703854529649" iyz="-1.1322262112806104e-05" izz="0.013482601595282608"/>
    </inertial>
  </link>
  <gazebo reference="r_leg2_hip_r_link">
    <mu1 value="0.85"/>
    <mu2 value="0.85"/>
    <maxContacts>10</maxContacts>
    <minDepth>0.0001</minDepth>
    <maxVel>0.01</maxVel>
    <selfCollide value="True"/>
  </gazebo>
  <joint name="r_leg2_hip_r_joint" type="revolute">
    <parent link="r_leg1_hip_y_link"/>
    <child link="r_leg2_hip_r_link"/>
    <origin rpy="0.0 0.0 0.0" xyz="0.0 0.0 0.0"/>
    <axis xyz="1 0 0"/>
    <limit effort="100.0" lower="-0.7853981633974483" upper="0.7853981633974483" velocity="20.22"/>
    <safety_controller k_position="121.0" k_velocity="540.0" soft_lower_limit="-0.7330382858376184" soft_upper_limit="0.7330382858376184"/>
    <dynamics damping="0.0" friction="0.0"/>
  </joint>
  <gazebo reference="r_leg2_hip_r_joint">
    <!-- Needed for ODE to output external wrenches on joints -->
    <provideFeedback>true</provideFeedback>
    <preserveFixedJoint>true</preserveFixedJoint>
    <disableFixedJointLumping>true</disableFixedJointLumping>
  </gazebo>
  <link name="r_leg3_hip_p_link">
    <visual name="r_leg3_hip_p_link_vis">
      <geometry>
        <mesh filename="package://human_description/meshes/M92C/visual/r_leg3_hip_p_link.stl" scale="1e-3 1e-3 1e-3"/>
      </geometry>
      <material name="metal">
        <color rgba="0.85 0.85 0.85 1"/>
      </material>
    </visual>
    <collision name="r_leg3_hip_p_link_col">
      <geometry>
        <mesh filename="package://human_description/meshes/M92C/collision/r_leg3_hip_p_link.stl" scale="1e-3 1e-3 1e-3"/>
      </geometry>
    </collision>
    <inertial>
      <origin rpy="0.0 0.0 0.0" xyz="0.001777498283024403 -0.06609405204667318 -0.06548805431118004"/>
      <mass value="6.861170839249381"/>
      <inertia ixx="0.08209203289624244" ixy="-4.8951279013623674e-05" ixz="0.003804575952713313" iyy="0.09174731120828715" iyz="0.005732136409648308" izz="0.0210784970572199"/>
    </inertial>
  </link>
  <gazebo reference="r_leg3_hip_p_link">
    <mu1 value="0.85"/>
    <mu2 value="0.85"/>
    <maxContacts>10</maxContacts>
    <minDepth>0.0001</minDepth>
    <maxVel>0.01</maxVel>
    <selfCollide value="True"/>
  </gazebo>
  <joint name="r_leg3_hip_p_joint" type="revolute">
    <parent link="r_leg2_hip_r_link"/>
    <child link="r_leg3_hip_p_link"/>
    <origin rpy="0.0 -0.7854 0.0" xyz="0.1575 0.0 0.0"/>
    <axis xyz="0 1 0"/>
    <limit effort="350.0" lower="-2.321287905152458" upper="1.361356816555577" velocity="27.27"/>
    <safety_controller k_position="121.0" k_velocity="540.0" soft_lower_limit="-2.2689280275926285" soft_upper_limit="1.3089969389957472"/>
    <dynamics damping="0.0" friction="0.0"/>
  </joint>
  <gazebo reference="r_leg3_hip_p_joint">
    <!-- Needed for ODE to output external wrenches on joints -->
    <provideFeedback>true</provideFeedback>
    <preserveFixedJoint>true</preserveFixedJoint>
    <disableFixedJointLumping>true</disableFixedJointLumping>
  </gazebo>
  <link name="r_leg4_knee_p_link">
    <visual name="r_leg4_knee_p_link_vis">
      <geometry>
        <mesh filename="package://human_description/meshes/M92C/visual/r_leg4_knee_p_link.stl" scale="1e-3 1e-3 1e-3"/>
      </geometry>
      <material name="metal">
        <color rgba="0.85 0.85 0.85 1"/>
      </material>
    </visual>
    <collision name="r_leg4_knee_p_link_col">
      <geometry>
        <mesh filename="package://human_description/meshes/M92C/collision/r_leg4_knee_p_link.stl" scale="1e-3 1e-3 1e-3"/>
      </geometry>
    </collision>
    <inertial>
      <origin rpy="0.0 0.0 0.0" xyz="0.026276416699445766 -0.0006239679967631234 -0.1669593832478771"/>
      <mass value="3.251382635339728"/>
      <inertia ixx="0.03882460227929094" ixy="0.0001626615225407489" ixz="0.003120886772307399" iyy="0.03943104044910984" iyz="0.0003856289904792427" izz="0.004759512026890702"/>
    </inertial>
  </link>
  <gazebo reference="r_leg4_knee_p_link">
    <mu1 value="0.85"/>
    <mu2 value="0.85"/>
    <maxContacts>10</maxContacts>
    <minDepth>0.0001</minDepth>
    <maxVel>0.01</maxVel>
    <selfCollide value="True"/>
  </gazebo>
  <joint name="r_leg4_knee_p_joint" type="revolute">
    <parent link="r_leg3_hip_p_link"/>
    <child link="r_leg4_knee_p_link"/>
    <origin rpy="0.0 0.0 0.0" xyz="0.0 -0.0435 -0.35"/>
    <axis xyz="0 1 0"/>
    <limit effort="350.0" lower="-0.17453292519943295" upper="2.651155133779387" velocity="27.27"/>
    <safety_controller k_position="121.0" k_velocity="540.0" soft_lower_limit="-0.12217304763960307" soft_upper_limit="2.5987952562195566"/>
    <dynamics damping="0.0" friction="0.0"/>
  </joint>
  <gazebo reference="r_leg4_knee_p_joint">
    <!-- Needed for ODE to output external wrenches on joints -->
    <provideFeedback>true</provideFeedback>
    <preserveFixedJoint>true</preserveFixedJoint>
    <disableFixedJointLumping>true</disableFixedJointLumping>
  </gazebo>
  <link name="r_leg5_ankle_p_link">
    <visual name="r_leg5_ankle_p_link_vis">
      <geometry>
        <mesh filename="package://human_description/meshes/M92C/visual/r_leg5_ankle_p_link.stl" scale="1e-3 1e-3 1e-3"/>
      </geometry>
      <material name="metal">
        <color rgba="0.85 0.85 0.85 1"/>
      </material>
    </visual>
    <collision name="r_leg5_ankle_p_link_col">
      <geometry>
        <mesh filename="package://human_description/meshes/M92C/collision/r_leg5_ankle_p_link.stl" scale="1e-3 1e-3 1e-3"/>
      </geometry>
    </collision>
    <inertial>
      <origin rpy="0.0 0.0 0.0" xyz="0.0028303307 0.0 0.0"/>
      <mass value="0.11492616"/>
      <inertia ixx="1.4387333e-05" ixy="0.0" ixz="0.0" iyy="2.2649914e-05" iyz="0.0" izz="3.0265224e-05"/>
    </inertial>
  </link>
  <gazebo reference="r_leg5_ankle_p_link">
    <mu1 value="0.85"/>
    <mu2 value="0.85"/>
    <maxContacts>10</maxContacts>
    <minDepth>0.0001</minDepth>
    <maxVel>0.01</maxVel>
    <selfCollide value="True"/>
  </gazebo>
  <joint name="r_leg5_ankle_p_joint" type="revolute">
    <parent link="r_leg4_knee_p_link"/>
    <child link="r_leg5_ankle_p_link"/>
    <origin rpy="0.0 0.0 0.0" xyz="0.0 0.005 -0.35"/>
    <axis xyz="0 1 0"/>
    <limit effort="150.0" lower="-1.2217304763960306" upper="0.6457718232379019" velocity="33.0"/>
    <safety_controller k_position="121.0" k_velocity="540.0" soft_lower_limit="-1.1693705988362006" soft_upper_limit="0.5934119456780721"/>
    <dynamics damping="0.0" friction="0.0"/>
  </joint>
  <gazebo reference="r_leg5_ankle_p_joint">
    <!-- Needed for ODE to output external wrenches on joints -->
    <provideFeedback>true</provideFeedback>
    <preserveFixedJoint>true</preserveFixedJoint>
    <disableFixedJointLumping>true</disableFixedJointLumping>
  </gazebo>
  <link name="r_leg6_ankle_r_link">
    <visual name="r_leg6_ankle_r_link_vis">
      <geometry>
        <mesh filename="package://human_description/meshes/M92C/visual/r_leg6_ankle_r_link.stl" scale="1e-3 1e-3 1e-3"/>
      </geometry>
      <material name="metal">
        <color rgba="0.85 0.85 0.85 1"/>
      </material>
    </visual>
    <collision name="r_leg6_ankle_r_link_col">
      <geometry>
        <mesh filename="package://human_description/meshes/M92C/collision/r_leg6_ankle_r_link.stl" scale="1e-3 1e-3 1e-3"/>
      </geometry>
    </collision>
    <inertial>
      <origin rpy="0.0 0.0 0.0" xyz="0.05231358618601275 2.8064972453501938e-05 -0.0379930283494815"/>
      <mass value="1.1273201594692528"/>
      <inertia ixx="0.001132228521183826" ixy="-4.766733513667394e-07" ixz="0.00011099562072101504" iyy="0.004074718655562373" iyz="2.367253415282658e-07" izz="0.004449576486150568"/>
    </inertial>
  </link>
  <gazebo reference="r_leg6_ankle_r_link">
    <mu1 value="0.85"/>
    <mu2 value="0.85"/>
    <maxContacts>10</maxContacts>
    <minDepth>0.0001</minDepth>
    <maxVel>0.01</maxVel>
    <selfCollide value="True"/>
  </gazebo>
  <joint name="r_leg6_ankle_r_joint" type="revolute">
    <parent link="r_leg5_ankle_p_link"/>
    <child link="r_leg6_ankle_r_link"/>
    <origin rpy="0.0 0.0 0.0" xyz="0.0 0.0 0.0"/>
    <axis xyz="1 0 0"/>
    <limit effort="150.0" lower="-0.5235987755982988" upper="0.5235987755982988" velocity="33.0"/>
    <safety_controller k_position="121.0" k_velocity="540.0" soft_lower_limit="-0.47123889803846897" soft_upper_limit="0.47123889803846897"/>
    <dynamics damping="0.0" friction="0.0"/>
  </joint>
  <gazebo reference="r_leg6_ankle_r_joint">
    <!-- Needed for ODE to output external wrenches on joints -->
    <provideFeedback>true</provideFeedback>
    <preserveFixedJoint>true</preserveFixedJoint>
    <disableFixedJointLumping>true</disableFixedJointLumping>
  </gazebo>
  <ros2_control name="r_leg_system" type="system">
    <hardware>
      <plugin>ign_ros2_control/IgnitionSystem</plugin>
    </hardware>
    <joint name="r_leg1_hip_y_joint">
      <param name="initial_position">0.0</param>
      <command_interface name="position"/>
      <state_interface name="position">
        <param name="initial_value">0.0</param>
      </state_interface>
      <state_interface name="velocity"/>
      <state_interface name="effort"/>
    </joint>
    <transmission name="r_leg1_hip_y_transmission">
      <plugin>transmission_interface/SimpleTransmission</plugin>
      <joint name="r_leg1_hip_y_joint" role="joint1">
        <mechanical_reduction>1.0</mechanical_reduction>
        <offset>0</offset>
      </joint>
      <actuator name="r_leg1_hip_y_actuator" role="actuator1">
        <mechanical_reduction>1.0</mechanical_reduction>
        <offset>0</offset>
      </actuator>
    </transmission>
    <joint name="r_leg2_hip_r_joint">
      <param name="initial_position">0.0</param>
      <command_interface name="position"/>
      <state_interface name="position">
        <param name="initial_value">0.0</param>
      </state_interface>
      <state_interface name="velocity"/>
      <state_interface name="effort"/>
    </joint>
    <transmission name="r_leg2_hip_r_transmission">
      <plugin>transmission_interface/SimpleTransmission</plugin>
      <joint name="r_leg2_hip_r_joint" role="joint1">
        <mechanical_reduction>1.0</mechanical_reduction>
        <offset>0</offset>
      </joint>
      <actuator name="r_leg2_hip_r_actuator" role="actuator1">
        <mechanical_reduction>1.0</mechanical_reduction>
        <offset>0</offset>
      </actuator>
    </transmission>
    <joint name="r_leg3_hip_p_joint">
      <param name="initial_position">0.0</param>
      <command_interface name="position"/>
      <state_interface name="position">
        <param name="initial_value">0.0</param>
      </state_interface>
      <state_interface name="velocity"/>
      <state_interface name="effort"/>
    </joint>
    <transmission name="r_leg3_hip_p_transmission">
      <plugin>transmission_interface/SimpleTransmission</plugin>
      <joint name="r_leg3_hip_p_joint" role="joint1">
        <mechanical_reduction>1.0</mechanical_reduction>
        <offset>0</offset>
      </joint>
      <actuator name="r_leg3_hip_p_actuator" role="actuator1">
        <mechanical_reduction>1.0</mechanical_reduction>
        <offset>0</offset>
      </actuator>
    </transmission>
    <joint name="r_leg4_knee_p_joint">
      <param name="initial_position">0.0</param>
      <command_interface name="position"/>
      <state_interface name="position">
        <param name="initial_value">0.0</param>
      </state_interface>
      <state_interface name="velocity"/>
      <state_interface name="effort"/>
    </joint>
    <transmission name="r_leg4_knee_p_transmission">
      <plugin>transmission_interface/SimpleTransmission</plugin>
      <joint name="r_leg4_knee_p_joint" role="joint1">
        <mechanical_reduction>1.0</mechanical_reduction>
        <offset>0</offset>
      </joint>
      <actuator name="r_leg4_knee_p_actuator" role="actuator1">
        <mechanical_reduction>1.0</mechanical_reduction>
        <offset>0</offset>
      </actuator>
    </transmission>
    <joint name="r_leg5_ankle_p_joint">
      <param name="initial_position">0.0</param>
      <command_interface name="position"/>
      <state_interface name="position">
        <param name="initial_value">0.0</param>
      </state_interface>
      <state_interface name="velocity"/>
      <state_interface name="effort"/>
    </joint>
    <transmission name="r_leg5_ankle_p_transmission">
      <plugin>transmission_interface/SimpleTransmission</plugin>
      <joint name="r_leg5_ankle_p_joint" role="joint1">
        <mechanical_reduction>1.0</mechanical_reduction>
        <offset>0</offset>
      </joint>
      <actuator name="r_leg5_ankle_p_actuator" role="actuator1">
        <mechanical_reduction>1.0</mechanical_reduction>
        <offset>0</offset>
      </actuator>
    </transmission>
    <joint name="r_leg6_ankle_r_joint">
      <param name="initial_position">0.0</param>
      <command_interface name="position"/>
      <state_interface name="position">
        <param name="initial_value">0.0</param>
      </state_interface>
      <state_interface name="velocity"/>
      <state_interface name="effort"/>
    </joint>
    <transmission name="r_leg6_ankle_r_transmission">
      <plugin>transmission_interface/SimpleTransmission</plugin>
      <joint name="r_leg6_ankle_r_joint" role="joint1">
        <mechanical_reduction>1.0</mechanical_reduction>
        <offset>0</offset>
      </joint>
      <actuator name="r_leg6_ankle_r_actuator" role="actuator1">
        <mechanical_reduction>1.0</mechanical_reduction>
        <offset>0</offset>
      </actuator>
    </transmission>
  </ros2_control>
  <link name="waist1_y_link">
    <visual name="waist1_y_link_vis">
      <geometry>
        <mesh filename="package://human_description/meshes/M92C/visual/waist1_y_link.stl" scale="1e-3 1e-3 1e-3"/>
      </geometry>
      <material name="metal">
        <color rgba="0.85 0.85 0.85 1"/>
      </material>
    </visual>
    <collision name="waist1_y_link_col">
      <geometry>
        <mesh filename="package://human_description/meshes/M92C/collision/waist1_y_link.stl" scale="1e-3 1e-3 1e-3"/>
      </geometry>
    </collision>
    <inertial>
      <origin rpy="0.0 0.0 0.0" xyz="0.05228227436909447 -0.0019631353622728462 -0.007856317778003358"/>
      <mass value="4.5102068001828"/>
      <inertia ixx="0.007130659310212181" ixy="0.0004182105123634317" ixz="-0.002860047424946122" iyy="0.018821749702855318" iyz="7.15299568415304e-05" izz="0.019071307195176378"/>
    </inertial>
  </link>
  <gazebo reference="waist1_y_link">
    <mu1 value="0.85"/>
    <mu2 value="0.85"/>
    <maxContacts>10</maxContacts>
    <minDepth>0.0001</minDepth>
    <maxVel>0.01</maxVel>
    <selfCollide value="True"/>
  </gazebo>
  <joint name="waist1_y_joint" type="revolute">
    <parent link="base_link"/>
    <child link="waist1_y_link"/>
    <origin rpy="0.0 0.0 0.0" xyz="-0.0669241 0.0 0.0593373"/>
    <axis xyz="0 0 1"/>
    <limit effort="200.0" lower="-1.0471975511965976" upper="1.0471975511965976" velocity="6.0"/>
    <safety_controller k_position="121.0" k_velocity="540.0" soft_lower_limit="-0.9948376736367678" soft_upper_limit="0.9948376736367678"/>
    <dynamics damping="0.0" friction="0.0"/>
  </joint>
  <gazebo reference="waist1_y_joint">
    <!-- Needed for ODE to output external wrenches on joints -->
    <provideFeedback>true</provideFeedback>
    <preserveFixedJoint>true</preserveFixedJoint>
    <disableFixedJointLumping>true</disableFixedJointLumping>
  </gazebo>
  <link name="waist2_p_link">
    <visual name="waist2_p_link_vis">
      <geometry>
        <mesh filename="package://human_description/meshes/M92C/visual/waist2_p_link.stl" scale="1e-3 1e-3 1e-3"/>
      </geometry>
      <material name="metal">
        <color rgba="0.85 0.85 0.85 1"/>
      </material>
    </visual>
    <collision name="waist2_p_link_col">
      <geometry>
        <mesh filename="package://human_description/meshes/M92C/collision/waist2_p_link.stl" scale="1e-3 1e-3 1e-3"/>
      </geometry>
    </collision>
    <inertial>
      <origin rpy="0.0 0.0 0.0" xyz="-0.04219957199812197 -0.001238008200819568 0.27864890346280985"/>
      <mass value="22.300457191032756"/>
      <inertia ixx="0.7323354518342496" ixy="0.00048155852160940155" ixz="-0.07069783702279761" iyy="0.6880022781892486" iyz="0.0005725217970312026" izz="0.20674940877633646"/>
    </inertial>
  </link>
  <gazebo reference="waist2_p_link">
    <mu1 value="0.85"/>
    <mu2 value="0.85"/>
    <maxContacts>10</maxContacts>
    <minDepth>0.0001</minDepth>
    <maxVel>0.01</maxVel>
    <selfCollide value="True"/>
  </gazebo>
  <joint name="waist2_p_joint" type="revolute">
    <parent link="waist1_y_link"/>
    <child link="waist2_p_link"/>
    <origin rpy="0.0 0.0 0.0" xyz="0.1 0.0 0.0"/>
    <axis xyz="0 1 0"/>
    <limit effort="200.0" lower="-0.05235987755982988" upper="1.2217304763960306" velocity="6.0"/>
    <safety_controller k_position="121.0" k_velocity="540.0" soft_lower_limit="0.0" soft_upper_limit="1.1693705988362006"/>
    <dynamics damping="0.0" friction="0.0"/>
  </joint>
  <gazebo reference="waist2_p_joint">
    <!-- Needed for ODE to output external wrenches on joints -->
    <provideFeedback>true</provideFeedback>
    <preserveFixedJoint>true</preserveFixedJoint>
    <disableFixedJointLumping>true</disableFixedJointLumping>
  </gazebo>
  <ros2_control name="waist_system" type="system">
    <hardware>
      <plugin>ign_ros2_control/IgnitionSystem</plugin>
    </hardware>
    <joint name="waist1_y_joint">
      <param name="initial_position">0.0</param>
      <command_interface name="position"/>
      <state_interface name="position">
        <param name="initial_value">0.0</param>
      </state_interface>
      <state_interface name="velocity"/>
      <state_interface name="effort"/>
    </joint>
    <transmission name="waist1_y_transmission">
      <plugin>transmission_interface/SimpleTransmission</plugin>
      <joint name="waist1_y_joint" role="joint1">
        <mechanical_reduction>1.0</mechanical_reduction>
        <offset>0</offset>
      </joint>
      <actuator name="waist1_y_actuator" role="actuator1">
        <mechanical_reduction>1.0</mechanical_reduction>
        <offset>0</offset>
      </actuator>
    </transmission>
    <joint name="waist2_p_joint">
      <param name="initial_position">0.0</param>
      <command_interface name="position"/>
      <state_interface name="position">
        <param name="initial_value">0.0</param>
      </state_interface>
      <state_interface name="velocity"/>
      <state_interface name="effort"/>
    </joint>
    <transmission name="waist2_p_transmission">
      <plugin>transmission_interface/SimpleTransmission</plugin>
      <joint name="waist2_p_joint" role="joint1">
        <mechanical_reduction>1.0</mechanical_reduction>
        <offset>0</offset>
      </joint>
      <actuator name="waist2_p_actuator" role="actuator1">
        <mechanical_reduction>1.0</mechanical_reduction>
        <offset>0</offset>
      </actuator>
    </transmission>
  </ros2_control>
  <link name="l_arm1_shoulder_p_link">
    <visual name="l_arm1_shoulder_p_link_vis">
      <geometry>
        <mesh filename="package://human_description/meshes/M92C/visual/l_arm1_shoulder_p_link.stl" scale="1e-3 1e-3 1e-3"/>
      </geometry>
      <material name="metal">
        <color rgba="0.85 0.85 0.85 1"/>
      </material>
    </visual>
    <collision name="l_arm1_shoulder_p_link_col">
      <geometry>
        <mesh filename="package://human_description/meshes/M92C/collision/l_arm1_shoulder_p_link.stl" scale="1e-3 1e-3 1e-3"/>
      </geometry>
    </collision>
    <inertial>
      <origin rpy="0.0 0.0 0.0" xyz="-0.0131 -0.00467 -0.00365"/>
      <mass value="1.55"/>
      <inertia ixx="0.00364" ixy="0.00254" ixz="-0.00295" iyy="0.014875019" iyz="0.000635" izz="0.015"/>
    </inertial>
  </link>
  <gazebo reference="l_arm1_shoulder_p_link">
    <mu1 value="0.85"/>
    <mu2 value="0.85"/>
    <maxContacts>10</maxContacts>
    <minDepth>0.0001</minDepth>
    <maxVel>0.01</maxVel>
    <selfCollide value="True"/>
  </gazebo>
  <joint name="l_arm1_shoulder_p_joint" type="revolute">
    <parent link="waist2_p_link"/>
    <child link="l_arm1_shoulder_p_link"/>
    <origin rpy="-0.087 0.008 0.08722222" xyz="-0.04647802646 0.236711636842 0.357156560927"/>
    <axis xyz="0 1 0"/>
    <limit effort="102.0" lower="-3.141592653589793" upper="1.0000736613927508" velocity="4.71"/>
    <safety_controller k_position="121.0" k_velocity="540.0" soft_lower_limit="-3.0892327760299634" soft_upper_limit="0.9477137838329208"/>
    <dynamics damping="0.0" friction="0.0"/>
  </joint>
  <gazebo reference="l_arm1_shoulder_p_joint">
    <!-- Needed for ODE to output external wrenches on joints -->
    <provideFeedback>true</provideFeedback>
    <preserveFixedJoint>true</preserveFixedJoint>
    <disableFixedJointLumping>true</disableFixedJointLumping>
  </gazebo>
  <link name="l_arm2_shoulder_r_link">
    <visual name="l_arm2_shoulder_r_link_vis">
      <geometry>
        <mesh filename="package://human_description/meshes/M92C/visual/l_arm2_shoulder_r_link.stl" scale="1e-3 1e-3 1e-3"/>
      </geometry>
      <material name="metal">
        <color rgba="0.85 0.85 0.85 1"/>
      </material>
    </visual>
    <collision name="l_arm2_shoulder_r_link_col">
      <geometry>
        <mesh filename="package://human_description/meshes/M92C/collision/l_arm2_shoulder_r_link.stl" scale="1e-3 1e-3 1e-3"/>
      </geometry>
    </collision>
    <inertial>
      <origin rpy="0.0 0.0 0.0" xyz="0.000165 0.00054 -0.111"/>
      <mass value="1.25"/>
      <inertia ixx="0.0046617" ixy="2.33e-06" ixz="3.53e-05" iyy="0.00522" iyz="-5.66e-05" izz="0.00195"/>
    </inertial>
  </link>
  <gazebo reference="l_arm2_shoulder_r_link">
    <mu1 value="0.85"/>
    <mu2 value="0.85"/>
    <maxContacts>10</maxContacts>
    <minDepth>0.0001</minDepth>
    <maxVel>0.01</maxVel>
    <selfCollide value="True"/>
  </gazebo>
  <joint name="l_arm2_shoulder_r_joint" type="revolute">
    <parent link="l_arm1_shoulder_p_link"/>
    <child link="l_arm2_shoulder_r_link"/>
    <origin rpy="0.0 0.0 0.0" xyz="0.0 0.0 0.0"/>
    <axis xyz="1 0 0"/>
    <limit effort="102.0" lower="-0.17453292519943295" upper="1.5707963267948966" velocity="4.71"/>
    <safety_controller k_position="121.0" k_velocity="540.0" soft_lower_limit="-0.12217304763960307" soft_upper_limit="1.5184364492350666"/>
    <dynamics damping="0.0" friction="0.0"/>
  </joint>
  <gazebo reference="l_arm2_shoulder_r_joint">
    <!-- Needed for ODE to output external wrenches on joints -->
    <provideFeedback>true</provideFeedback>
    <preserveFixedJoint>true</preserveFixedJoint>
    <disableFixedJointLumping>true</disableFixedJointLumping>
  </gazebo>
  <link name="l_arm3_shoulder_y_link">
    <visual name="l_arm3_shoulder_y_link_vis">
      <geometry>
        <mesh filename="package://human_description/meshes/M92C/visual/l_arm3_shoulder_y_link.stl" scale="1e-3 1e-3 1e-3"/>
      </geometry>
      <material name="metal">
        <color rgba="0.85 0.85 0.85 1"/>
      </material>
    </visual>
    <collision name="l_arm3_shoulder_y_link_col">
      <geometry>
        <mesh filename="package://human_description/meshes/M92C/collision/l_arm3_shoulder_y_link.stl" scale="1e-3 1e-3 1e-3"/>
      </geometry>
    </collision>
    <inertial>
      <origin rpy="0.0 0.0 0.0" xyz="5.4e-05 0.00362 -0.273"/>
      <mass value="1.11"/>
      <inertia ixx="0.00277" ixy="-2.31e-06" ixz="8.59e-07" iyy="0.00289" iyz="9.1e-06" izz="0.0010087315"/>
    </inertial>
  </link>
  <gazebo reference="l_arm3_shoulder_y_link">
    <mu1 value="0.85"/>
    <mu2 value="0.85"/>
    <maxContacts>10</maxContacts>
    <minDepth>0.0001</minDepth>
    <maxVel>0.01</maxVel>
    <selfCollide value="True"/>
  </gazebo>
  <joint name="l_arm3_shoulder_y_joint" type="revolute">
    <parent link="l_arm2_shoulder_r_link"/>
    <child link="l_arm3_shoulder_y_link"/>
    <origin rpy="0.0 0.0 0.0" xyz="0.0 0.0 0.0"/>
    <axis xyz="0 0 1"/>
    <limit effort="29.0" lower="-3.139847324337799" upper="3.139847324337799" velocity="8.12"/>
    <safety_controller k_position="121.0" k_velocity="540.0" soft_lower_limit="-3.087487446777969" soft_upper_limit="3.087487446777969"/>
    <dynamics damping="0.0" friction="0.0"/>
  </joint>
  <gazebo reference="l_arm3_shoulder_y_joint">
    <!-- Needed for ODE to output external wrenches on joints -->
    <provideFeedback>true</provideFeedback>
    <preserveFixedJoint>true</preserveFixedJoint>
    <disableFixedJointLumping>true</disableFixedJointLumping>
  </gazebo>
  <link name="l_arm4_elbow_p_link">
    <visual name="l_arm4_elbow_p_link_vis">
      <geometry>
        <mesh filename="package://human_description/meshes/M92C/visual/l_arm4_elbow_p_link.stl" scale="1e-3 1e-3 1e-3"/>
      </geometry>
      <material name="metal">
        <color rgba="0.85 0.85 0.85 1"/>
      </material>
    </visual>
    <collision name="l_arm4_elbow_p_link_col">
      <geometry>
        <mesh filename="package://human_description/meshes/M92C/collision/l_arm4_elbow_p_link.stl" scale="1e-3 1e-3 1e-3"/>
      </geometry>
    </collision>
    <inertial>
      <origin rpy="0.0 0.0 0.0" xyz="-0.000896 0.00121 -0.0832"/>
      <mass value="0.875"/>
      <inertia ixx="0.00181" ixy="-9.68e-06" ixz="2.67e-05" iyy="0.0016062824" iyz="-6.85e-05" izz="0.00106"/>
    </inertial>
  </link>
  <gazebo reference="l_arm4_elbow_p_link">
    <mu1 value="0.85"/>
    <mu2 value="0.85"/>
    <maxContacts>10</maxContacts>
    <minDepth>0.0001</minDepth>
    <maxVel>0.01</maxVel>
    <selfCollide value="True"/>
  </gazebo>
  <joint name="l_arm4_elbow_p_joint" type="revolute">
    <parent link="l_arm3_shoulder_y_link"/>
    <child link="l_arm4_elbow_p_link"/>
    <origin rpy="0.0 0.0 0.0" xyz="0.0 0.0 -0.3012"/>
    <axis xyz="0 1 0"/>
    <limit effort="29.0" lower="-1.9198621771937625" upper="0.05235987755982988" velocity="8.12"/>
    <safety_controller k_position="121.0" k_velocity="540.0" soft_lower_limit="-1.8675022996339325" soft_upper_limit="0.0"/>
    <dynamics damping="0.0" friction="0.0"/>
  </joint>
  <gazebo reference="l_arm4_elbow_p_joint">
    <!-- Needed for ODE to output external wrenches on joints -->
    <provideFeedback>true</provideFeedback>
    <preserveFixedJoint>true</preserveFixedJoint>
    <disableFixedJointLumping>true</disableFixedJointLumping>
  </gazebo>
  <link name="l_arm5_wrist_y_link">
    <visual name="l_arm5_wrist_y_link_vis">
      <geometry>
        <mesh filename="package://human_description/meshes/M92C/visual/l_arm5_wrist_y_link.stl" scale="1e-3 1e-3 1e-3"/>
      </geometry>
      <material name="metal">
        <color rgba="0.85 0.85 0.85 1"/>
      </material>
    </visual>
    <collision name="l_arm5_wrist_y_link_col">
      <geometry>
        <mesh filename="package://human_description/meshes/M92C/collision/l_arm5_wrist_y_link.stl" scale="1e-3 1e-3 1e-3"/>
      </geometry>
    </collision>
    <inertial>
      <origin rpy="0.0 0.0 0.0" xyz="0.000146818 -0.003847154 -0.23219571"/>
      <mass value="1.08"/>
      <inertia ixx="0.002762795" ixy="-1.0506e-05" ixz="-0.000167739" iyy="0.002773731" iyz="6.679e-05" izz="0.00081377"/>
    </inertial>
  </link>
  <gazebo reference="l_arm5_wrist_y_link">
    <mu1 value="0.85"/>
    <mu2 value="0.85"/>
    <maxContacts>10</maxContacts>
    <minDepth>0.0001</minDepth>
    <maxVel>0.01</maxVel>
    <selfCollide value="True"/>
  </gazebo>
  <joint name="l_arm5_wrist_y_joint" type="revolute">
    <parent link="l_arm4_elbow_p_link"/>
    <child link="l_arm5_wrist_y_link"/>
    <origin rpy="0.0 0.0 0.0" xyz="0.0 0.0 0.0"/>
    <axis xyz="0 0 1"/>
    <limit effort="38.76" lower="-3.141592653589793" upper="3.141592653589793" velocity="14.37"/>
    <safety_controller k_position="121.0" k_velocity="540.0" soft_lower_limit="-3.0892327760299634" soft_upper_limit="3.0892327760299634"/>
    <dynamics damping="0.0" friction="0.0"/>
  </joint>
  <gazebo reference="l_arm5_wrist_y_joint">
    <!-- Needed for ODE to output external wrenches on joints -->
    <provideFeedback>true</provideFeedback>
    <preserveFixedJoint>true</preserveFixedJoint>
    <disableFixedJointLumping>true</disableFixedJointLumping>
  </gazebo>
  <link name="l_arm6_wrist_r_link">
    <visual name="l_arm6_wrist_r_link_vis">
      <geometry>
        <mesh filename="package://human_description/meshes/M92C/visual/l_arm6_wrist_r_link.stl" scale="1e-3 1e-3 1e-3"/>
      </geometry>
      <material name="metal">
        <color rgba="0.85 0.85 0.85 1"/>
      </material>
    </visual>
    <collision name="l_arm6_wrist_r_link_col">
      <geometry>
        <mesh filename="package://human_description/meshes/M92C/collision/l_arm6_wrist_r_link.stl" scale="1e-3 1e-3 1e-3"/>
      </geometry>
    </collision>
    <inertial>
      <origin rpy="0.0 0.0 0.0" xyz="0 0.002745123 -0.013160251"/>
      <mass value="0.04337905"/>
      <inertia ixx="8.2871654e-06" ixy="-0.0" ixz="0.0" iyy="4.136e-06" iyz="5.76e-07" izz="6.065e-06"/>
    </inertial>
  </link>
  <gazebo reference="l_arm6_wrist_r_link">
    <mu1 value="0.85"/>
    <mu2 value="0.85"/>
    <maxContacts>10</maxContacts>
    <minDepth>0.0001</minDepth>
    <maxVel>0.01</maxVel>
    <selfCollide value="True"/>
  </gazebo>
  <joint name="l_arm6_wrist_r_joint" type="revolute">
    <parent link="l_arm5_wrist_y_link"/>
    <child link="l_arm6_wrist_r_link"/>
    <origin rpy="0.0 0.0 0.0" xyz="0.0 -0.01 -0.3232"/>
    <axis xyz="1 0 0"/>
    <limit effort="21.6" lower="-1.4294246573833558" upper="0.7906341511534313" velocity="8.81"/>
    <safety_controller k_position="121.0" k_velocity="540.0" soft_lower_limit="-1.377064779823526" soft_upper_limit="0.7382742735936014"/>
    <dynamics damping="0.0" friction="0.0"/>
  </joint>
  <gazebo reference="l_arm6_wrist_r_joint">
    <!-- Needed for ODE to output external wrenches on joints -->
    <provideFeedback>true</provideFeedback>
    <preserveFixedJoint>true</preserveFixedJoint>
    <disableFixedJointLumping>true</disableFixedJointLumping>
  </gazebo>
  <link name="l_arm7_wrist_p_link">
    <visual name="l_arm7_wrist_p_link_vis">
      <geometry>
        <mesh filename="package://human_description/meshes/M92C/visual/l_arm7_wrist_p_link.stl" scale="1e-3 1e-3 1e-3"/>
      </geometry>
      <material name="metal">
        <color rgba="0.85 0.85 0.85 1"/>
      </material>
    </visual>
    <collision name="l_arm7_wrist_p_link_col">
      <geometry>
        <mesh filename="package://human_description/meshes/M92C/collision/l_arm7_wrist_p_link.stl" scale="1e-3 1e-3 1e-3"/>
      </geometry>
    </collision>
    <inertial>
      <origin rpy="0.0 0.0 0.0" xyz="0.0043 0.00502 -0.0929"/>
      <mass value="1.04"/>
      <inertia ixx="0.004646142" ixy="0.000167163" ixz="0.000213092" iyy="0.0046271044" iyz="-0.000190965" izz="0.001358704"/>
    </inertial>
  </link>
  <gazebo reference="l_arm7_wrist_p_link">
    <mu1 value="0.85"/>
    <mu2 value="0.85"/>
    <maxContacts>10</maxContacts>
    <minDepth>0.0001</minDepth>
    <maxVel>0.01</maxVel>
    <selfCollide value="True"/>
  </gazebo>
  <joint name="l_arm7_wrist_p_joint" type="revolute">
    <parent link="l_arm6_wrist_r_link"/>
    <child link="l_arm7_wrist_p_link"/>
    <origin rpy="0.0 0.0 0.0" xyz="0.0 0.0 -0.018"/>
    <axis xyz="0 1 0"/>
    <limit effort="21.6" lower="-0.8098327729253689" upper="0.6894050545377601" velocity="8.81"/>
    <safety_controller k_position="121.0" k_velocity="540.0" soft_lower_limit="-0.7574728953655391" soft_upper_limit="0.6370451769779303"/>
    <dynamics damping="0.0" friction="0.0"/>
  </joint>
  <gazebo reference="l_arm7_wrist_p_joint">
    <!-- Needed for ODE to output external wrenches on joints -->
    <provideFeedback>true</provideFeedback>
    <preserveFixedJoint>true</preserveFixedJoint>
    <disableFixedJointLumping>true</disableFixedJointLumping>
  </gazebo>
  <link name="l_end_effector_link"/>
  <joint name="l_end_effector_fixed_joint" type="fixed">
    <parent link="l_arm7_wrist_p_link"/>
    <child link="l_end_effector_link"/>
    <origin rpy="0 0 0" xyz="0 0 0"/>
    <axis xyz="0 0 1"/>
  </joint>
  <ros2_control name="l_arm_system" type="system">
    <hardware>
      <plugin>ign_ros2_control/IgnitionSystem</plugin>
    </hardware>
    <joint name="l_arm1_shoulder_p_joint">
      <param name="initial_position">0.0</param>
      <command_interface name="position"/>
      <state_interface name="position">
        <param name="initial_value">0.0</param>
      </state_interface>
      <state_interface name="velocity"/>
      <state_interface name="effort"/>
    </joint>
    <transmission name="l_arm1_shoulder_p_transmission">
      <plugin>transmission_interface/SimpleTransmission</plugin>
      <joint name="l_arm1_shoulder_p_joint" role="joint1">
        <mechanical_reduction>1.0</mechanical_reduction>
        <offset>0</offset>
      </joint>
      <actuator name="l_arm1_shoulder_p_actuator" role="actuator1">
        <mechanical_reduction>1.0</mechanical_reduction>
        <offset>0</offset>
      </actuator>
    </transmission>
    <joint name="l_arm2_shoulder_r_joint">
      <param name="initial_position">0.0</param>
      <command_interface name="position"/>
      <state_interface name="position">
        <param name="initial_value">0.0</param>
      </state_interface>
      <state_interface name="velocity"/>
      <state_interface name="effort"/>
    </joint>
    <transmission name="l_arm2_shoulder_r_transmission">
      <plugin>transmission_interface/SimpleTransmission</plugin>
      <joint name="l_arm2_shoulder_r_joint" role="joint1">
        <mechanical_reduction>1.0</mechanical_reduction>
        <offset>0</offset>
      </joint>
      <actuator name="l_arm2_shoulder_r_actuator" role="actuator1">
        <mechanical_reduction>1.0</mechanical_reduction>
        <offset>0</offset>
      </actuator>
    </transmission>
    <joint name="l_arm3_shoulder_y_joint">
      <param name="initial_position">0.0</param>
      <command_interface name="position"/>
      <state_interface name="position">
        <param name="initial_value">0.0</param>
      </state_interface>
      <state_interface name="velocity"/>
      <state_interface name="effort"/>
    </joint>
    <transmission name="l_arm3_shoulder_y_transmission">
      <plugin>transmission_interface/SimpleTransmission</plugin>
      <joint name="l_arm3_shoulder_y_joint" role="joint1">
        <mechanical_reduction>1.0</mechanical_reduction>
        <offset>0</offset>
      </joint>
      <actuator name="l_arm3_shoulder_y_actuator" role="actuator1">
        <mechanical_reduction>1.0</mechanical_reduction>
        <offset>0</offset>
      </actuator>
    </transmission>
    <joint name="l_arm4_elbow_p_joint">
      <param name="initial_position">0.0</param>
      <command_interface name="position"/>
      <state_interface name="position">
        <param name="initial_value">0.0</param>
      </state_interface>
      <state_interface name="velocity"/>
      <state_interface name="effort"/>
    </joint>
    <transmission name="l_arm4_elbow_p_transmission">
      <plugin>transmission_interface/SimpleTransmission</plugin>
      <joint name="l_arm4_elbow_p_joint" role="joint1">
        <mechanical_reduction>1.0</mechanical_reduction>
        <offset>0</offset>
      </joint>
      <actuator name="l_arm4_elbow_p_actuator" role="actuator1">
        <mechanical_reduction>1.0</mechanical_reduction>
        <offset>0</offset>
      </actuator>
    </transmission>
    <joint name="l_arm5_wrist_y_joint">
      <param name="initial_position">0.0</param>
      <command_interface name="position"/>
      <state_interface name="position">
        <param name="initial_value">0.0</param>
      </state_interface>
      <state_interface name="velocity"/>
      <state_interface name="effort"/>
    </joint>
    <transmission name="l_arm5_wrist_y_transmission">
      <plugin>transmission_interface/SimpleTransmission</plugin>
      <joint name="l_arm5_wrist_y_joint" role="joint1">
        <mechanical_reduction>1.0</mechanical_reduction>
        <offset>0</offset>
      </joint>
      <actuator name="l_arm5_wrist_y_actuator" role="actuator1">
        <mechanical_reduction>1.0</mechanical_reduction>
        <offset>0</offset>
      </actuator>
    </transmission>
    <joint name="l_arm6_wrist_r_joint">
      <param name="initial_position">0.0</param>
      <command_interface name="position"/>
      <state_interface name="position">
        <param name="initial_value">0.0</param>
      </state_interface>
      <state_interface name="velocity"/>
      <state_interface name="effort"/>
    </joint>
    <transmission name="l_arm6_wrist_r_transmission">
      <plugin>transmission_interface/SimpleTransmission</plugin>
      <joint name="l_arm6_wrist_r_joint" role="joint1">
        <mechanical_reduction>1.0</mechanical_reduction>
        <offset>0</offset>
      </joint>
      <actuator name="l_arm6_wrist_r_actuator" role="actuator1">
        <mechanical_reduction>1.0</mechanical_reduction>
        <offset>0</offset>
      </actuator>
    </transmission>
    <joint name="l_arm7_wrist_p_joint">
      <param name="initial_position">0.0</param>
      <command_interface name="position"/>
      <state_interface name="position">
        <param name="initial_value">0.0</param>
      </state_interface>
      <state_interface name="velocity"/>
      <state_interface name="effort"/>
    </joint>
    <transmission name="l_arm7_wrist_p_transmission">
      <plugin>transmission_interface/SimpleTransmission</plugin>
      <joint name="l_arm7_wrist_p_joint" role="joint1">
        <mechanical_reduction>1.0</mechanical_reduction>
        <offset>0</offset>
      </joint>
      <actuator name="l_arm7_wrist_p_actuator" role="actuator1">
        <mechanical_reduction>1.0</mechanical_reduction>
        <offset>0</offset>
      </actuator>
    </transmission>
  </ros2_control>
  <link name="r_arm1_shoulder_p_link">
    <visual name="r_arm1_shoulder_p_link_vis">
      <geometry>
        <mesh filename="package://human_description/meshes/M92C/visual/r_arm1_shoulder_p_link.stl" scale="1e-3 1e-3 1e-3"/>
      </geometry>
      <material name="metal">
        <color rgba="0.85 0.85 0.85 1"/>
      </material>
    </visual>
    <collision name="r_arm1_shoulder_p_link_col">
      <geometry>
        <mesh filename="package://human_description/meshes/M92C/collision/r_arm1_shoulder_p_link.stl" scale="1e-3 1e-3 1e-3"/>
      </geometry>
    </collision>
    <inertial>
      <origin rpy="0.0 0.0 0.0" xyz="-0.0131 0.00467 -0.00365"/>
      <mass value="1.55"/>
      <inertia ixx="0.00364" ixy="-0.00254" ixz="-0.00295" iyy="0.014875019" iyz="-0.000635" izz="0.015"/>
    </inertial>
  </link>
  <gazebo reference="r_arm1_shoulder_p_link">
    <mu1 value="0.85"/>
    <mu2 value="0.85"/>
    <maxContacts>10</maxContacts>
    <minDepth>0.0001</minDepth>
    <maxVel>0.01</maxVel>
    <selfCollide value="True"/>
  </gazebo>
  <joint name="r_arm1_shoulder_p_joint" type="revolute">
    <parent link="waist2_p_link"/>
    <child link="r_arm1_shoulder_p_link"/>
    <origin rpy="0.087 0.008 -0.08722222" xyz="-0.04647802646 -0.236711636842 0.357156560927"/>
    <axis xyz="0 1 0"/>
    <limit effort="102.0" lower="-3.141592653589793" upper="1.0000736613927508" velocity="4.71"/>
    <safety_controller k_position="121.0" k_velocity="540.0" soft_lower_limit="-3.0892327760299634" soft_upper_limit="0.9477137838329208"/>
    <dynamics damping="0.0" friction="0.0"/>
  </joint>
  <gazebo reference="r_arm1_shoulder_p_joint">
    <!-- Needed for ODE to output external wrenches on joints -->
    <provideFeedback>true</provideFeedback>
    <preserveFixedJoint>true</preserveFixedJoint>
    <disableFixedJointLumping>true</disableFixedJointLumping>
  </gazebo>
  <link name="r_arm2_shoulder_r_link">
    <visual name="r_arm2_shoulder_r_link_vis">
      <geometry>
        <mesh filename="package://human_description/meshes/M92C/visual/r_arm2_shoulder_r_link.stl" scale="1e-3 1e-3 1e-3"/>
      </geometry>
      <material name="metal">
        <color rgba="0.85 0.85 0.85 1"/>
      </material>
    </visual>
    <collision name="r_arm2_shoulder_r_link_col">
      <geometry>
        <mesh filename="package://human_description/meshes/M92C/collision/r_arm2_shoulder_r_link.stl" scale="1e-3 1e-3 1e-3"/>
      </geometry>
    </collision>
    <inertial>
      <origin rpy="0.0 0.0 0.0" xyz="0.000165 -0.00054 -0.111"/>
      <mass value="1.25"/>
      <inertia ixx="0.0046617" ixy="-2.33e-06" ixz="3.53e-05" iyy="0.00522" iyz="5.66e-05" izz="0.00195"/>
    </inertial>
  </link>
  <gazebo reference="r_arm2_shoulder_r_link">
    <mu1 value="0.85"/>
    <mu2 value="0.85"/>
    <maxContacts>10</maxContacts>
    <minDepth>0.0001</minDepth>
    <maxVel>0.01</maxVel>
    <selfCollide value="True"/>
  </gazebo>
  <joint name="r_arm2_shoulder_r_joint" type="revolute">
    <parent link="r_arm1_shoulder_p_link"/>
    <child link="r_arm2_shoulder_r_link"/>
    <origin rpy="0.0 0.0 0.0" xyz="0.0 0.0 0.0"/>
    <axis xyz="1 0 0"/>
    <limit effort="102.0" lower="-1.5707963267948966" upper="0.17453292519943295" velocity="4.71"/>
    <safety_controller k_position="121.0" k_velocity="540.0" soft_lower_limit="-1.5184364492350666" soft_upper_limit="0.12217304763960307"/>
    <dynamics damping="0.0" friction="0.0"/>
  </joint>
  <gazebo reference="r_arm2_shoulder_r_joint">
    <!-- Needed for ODE to output external wrenches on joints -->
    <provideFeedback>true</provideFeedback>
    <preserveFixedJoint>true</preserveFixedJoint>
    <disableFixedJointLumping>true</disableFixedJointLumping>
  </gazebo>
  <link name="r_arm3_shoulder_y_link">
    <visual name="r_arm3_shoulder_y_link_vis">
      <geometry>
        <mesh filename="package://human_description/meshes/M92C/visual/r_arm3_shoulder_y_link.stl" scale="1e-3 1e-3 1e-3"/>
      </geometry>
      <material name="metal">
        <color rgba="0.85 0.85 0.85 1"/>
      </material>
    </visual>
    <collision name="r_arm3_shoulder_y_link_col">
      <geometry>
        <mesh filename="package://human_description/meshes/M92C/collision/r_arm3_shoulder_y_link.stl" scale="1e-3 1e-3 1e-3"/>
      </geometry>
    </collision>
    <inertial>
      <origin rpy="0.0 0.0 0.0" xyz="5.4e-05 -0.00362 -0.273"/>
      <mass value="1.11"/>
      <inertia ixx="0.00277" ixy="2.31e-06" ixz="8.59e-07" iyy="0.00289" iyz="-9.1e-06" izz="0.0010087315"/>
    </inertial>
  </link>
  <gazebo reference="r_arm3_shoulder_y_link">
    <mu1 value="0.85"/>
    <mu2 value="0.85"/>
    <maxContacts>10</maxContacts>
    <minDepth>0.0001</minDepth>
    <maxVel>0.01</maxVel>
    <selfCollide value="True"/>
  </gazebo>
  <joint name="r_arm3_shoulder_y_joint" type="revolute">
    <parent link="r_arm2_shoulder_r_link"/>
    <child link="r_arm3_shoulder_y_link"/>
    <origin rpy="0.0 0.0 0.0" xyz="0.0 0.0 0.0"/>
    <axis xyz="0 0 1"/>
    <limit effort="29.0" lower="-3.139847324337799" upper="3.139847324337799" velocity="8.12"/>
    <safety_controller k_position="121.0" k_velocity="540.0" soft_lower_limit="-3.087487446777969" soft_upper_limit="3.087487446777969"/>
    <dynamics damping="0.0" friction="0.0"/>
  </joint>
  <gazebo reference="r_arm3_shoulder_y_joint">
    <!-- Needed for ODE to output external wrenches on joints -->
    <provideFeedback>true</provideFeedback>
    <preserveFixedJoint>true</preserveFixedJoint>
    <disableFixedJointLumping>true</disableFixedJointLumping>
  </gazebo>
  <link name="r_arm4_elbow_p_link">
    <visual name="r_arm4_elbow_p_link_vis">
      <geometry>
        <mesh filename="package://human_description/meshes/M92C/visual/r_arm4_elbow_p_link.stl" scale="1e-3 1e-3 1e-3"/>
      </geometry>
      <material name="metal">
        <color rgba="0.85 0.85 0.85 1"/>
      </material>
    </visual>
    <collision name="r_arm4_elbow_p_link_col">
      <geometry>
        <mesh filename="package://human_description/meshes/M92C/collision/r_arm4_elbow_p_link.stl" scale="1e-3 1e-3 1e-3"/>
      </geometry>
    </collision>
    <inertial>
      <origin rpy="0.0 0.0 0.0" xyz="-0.000896 -0.00121 -0.0832"/>
      <mass value="0.875"/>
      <inertia ixx="0.00181" ixy="9.68e-06" ixz="2.67e-05" iyy="0.0016062824" iyz="6.85e-05" izz="0.00106"/>
    </inertial>
  </link>
  <gazebo reference="r_arm4_elbow_p_link">
    <mu1 value="0.85"/>
    <mu2 value="0.85"/>
    <maxContacts>10</maxContacts>
    <minDepth>0.0001</minDepth>
    <maxVel>0.01</maxVel>
    <selfCollide value="True"/>
  </gazebo>
  <joint name="r_arm4_elbow_p_joint" type="revolute">
    <parent link="r_arm3_shoulder_y_link"/>
    <child link="r_arm4_elbow_p_link"/>
    <origin rpy="0.0 0.0 0.0" xyz="0.0 0.0 -0.3012"/>
    <axis xyz="0 1 0"/>
    <limit effort="29.0" lower="-1.9198621771937625" upper="0.05235987755982988" velocity="8.12"/>
    <safety_controller k_position="121.0" k_velocity="540.0" soft_lower_limit="-1.8675022996339325" soft_upper_limit="0.0"/>
    <dynamics damping="0.0" friction="0.0"/>
  </joint>
  <gazebo reference="r_arm4_elbow_p_joint">
    <!-- Needed for ODE to output external wrenches on joints -->
    <provideFeedback>true</provideFeedback>
    <preserveFixedJoint>true</preserveFixedJoint>
    <disableFixedJointLumping>true</disableFixedJointLumping>
  </gazebo>
  <link name="r_arm5_wrist_y_link">
    <visual name="r_arm5_wrist_y_link_vis">
      <geometry>
        <mesh filename="package://human_description/meshes/M92C/visual/r_arm5_wrist_y_link.stl" scale="1e-3 1e-3 1e-3"/>
      </geometry>
      <material name="metal">
        <color rgba="0.85 0.85 0.85 1"/>
      </material>
    </visual>
    <collision name="r_arm5_wrist_y_link_col">
      <geometry>
        <mesh filename="package://human_description/meshes/M92C/collision/r_arm5_wrist_y_link.stl" scale="1e-3 1e-3 1e-3"/>
      </geometry>
    </collision>
    <inertial>
      <origin rpy="0.0 0.0 0.0" xyz="0.000146818 0.003847154 -0.23219571"/>
      <mass value="1.08"/>
      <inertia ixx="0.002762795" ixy="1.0506e-05" ixz="-0.000167739" iyy="0.002773731" iyz="-6.679e-05" izz="0.00081377"/>
    </inertial>
  </link>
  <gazebo reference="r_arm5_wrist_y_link">
    <mu1 value="0.85"/>
    <mu2 value="0.85"/>
    <maxContacts>10</maxContacts>
    <minDepth>0.0001</minDepth>
    <maxVel>0.01</maxVel>
    <selfCollide value="True"/>
  </gazebo>
  <joint name="r_arm5_wrist_y_joint" type="revolute">
    <parent link="r_arm4_elbow_p_link"/>
    <child link="r_arm5_wrist_y_link"/>
    <origin rpy="0.0 0.0 0.0" xyz="0.0 0.0 0.0"/>
    <axis xyz="0 0 1"/>
    <limit effort="38.76" lower="-3.141592653589793" upper="3.141592653589793" velocity="14.37"/>
    <safety_controller k_position="121.0" k_velocity="540.0" soft_lower_limit="-3.0892327760299634" soft_upper_limit="3.0892327760299634"/>
    <dynamics damping="0.0" friction="0.0"/>
  </joint>
  <gazebo reference="r_arm5_wrist_y_joint">
    <!-- Needed for ODE to output external wrenches on joints -->
    <provideFeedback>true</provideFeedback>
    <preserveFixedJoint>true</preserveFixedJoint>
    <disableFixedJointLumping>true</disableFixedJointLumping>
  </gazebo>
  <link name="r_arm6_wrist_r_link">
    <visual name="r_arm6_wrist_r_link_vis">
      <geometry>
        <mesh filename="package://human_description/meshes/M92C/visual/r_arm6_wrist_r_link.stl" scale="1e-3 1e-3 1e-3"/>
      </geometry>
      <material name="metal">
        <color rgba="0.85 0.85 0.85 1"/>
      </material>
    </visual>
    <collision name="r_arm6_wrist_r_link_col">
      <geometry>
        <mesh filename="package://human_description/meshes/M92C/collision/r_arm6_wrist_r_link.stl" scale="1e-3 1e-3 1e-3"/>
      </geometry>
    </collision>
    <inertial>
      <origin rpy="0.0 0.0 0.0" xyz="0 -0.002745123 -0.013160251"/>
      <mass value="0.04337905"/>
      <inertia ixx="8.2871654e-06" ixy="0.0" ixz="0.0" iyy="4.136e-06" iyz="-5.76e-07" izz="6.065e-06"/>
    </inertial>
  </link>
  <gazebo reference="r_arm6_wrist_r_link">
    <mu1 value="0.85"/>
    <mu2 value="0.85"/>
    <maxContacts>10</maxContacts>
    <minDepth>0.0001</minDepth>
    <maxVel>0.01</maxVel>
    <selfCollide value="True"/>
  </gazebo>
  <joint name="r_arm6_wrist_r_joint" type="revolute">
    <parent link="r_arm5_wrist_y_link"/>
    <child link="r_arm6_wrist_r_link"/>
    <origin rpy="0.0 0.0 0.0" xyz="0.0 0.01 -0.3232"/>
    <axis xyz="1 0 0"/>
    <limit effort="21.6" lower="-0.7906341511534313" upper="1.4294246573833558" velocity="8.81"/>
    <safety_controller k_position="121.0" k_velocity="540.0" soft_lower_limit="-0.7382742735936014" soft_upper_limit="1.377064779823526"/>
    <dynamics damping="0.0" friction="0.0"/>
  </joint>
  <gazebo reference="r_arm6_wrist_r_joint">
    <!-- Needed for ODE to output external wrenches on joints -->
    <provideFeedback>true</provideFeedback>
    <preserveFixedJoint>true</preserveFixedJoint>
    <disableFixedJointLumping>true</disableFixedJointLumping>
  </gazebo>
  <link name="r_arm7_wrist_p_link">
    <visual name="r_arm7_wrist_p_link_vis">
      <geometry>
        <mesh filename="package://human_description/meshes/M92C/visual/r_arm7_wrist_p_link.stl" scale="1e-3 1e-3 1e-3"/>
      </geometry>
      <material name="metal">
        <color rgba="0.85 0.85 0.85 1"/>
      </material>
    </visual>
    <collision name="r_arm7_wrist_p_link_col">
      <geometry>
        <mesh filename="package://human_description/meshes/M92C/collision/r_arm7_wrist_p_link.stl" scale="1e-3 1e-3 1e-3"/>
      </geometry>
    </collision>
    <inertial>
      <origin rpy="0.0 0.0 0.0" xyz="0.0043 -0.00502 -0.0929"/>
      <mass value="1.04"/>
      <inertia ixx="0.004646142" ixy="-0.000167163" ixz="0.000213092" iyy="0.0046271044" iyz="0.000190965" izz="0.001358704"/>
    </inertial>
  </link>
  <gazebo reference="r_arm7_wrist_p_link">
    <mu1 value="0.85"/>
    <mu2 value="0.85"/>
    <maxContacts>10</maxContacts>
    <minDepth>0.0001</minDepth>
    <maxVel>0.01</maxVel>
    <selfCollide value="True"/>
  </gazebo>
  <joint name="r_arm7_wrist_p_joint" type="revolute">
    <parent link="r_arm6_wrist_r_link"/>
    <child link="r_arm7_wrist_p_link"/>
    <origin rpy="0.0 0.0 0.0" xyz="0.0 0.0 -0.018"/>
    <axis xyz="0 1 0"/>
    <limit effort="21.6" lower="-0.8098327729253689" upper="0.6894050545377601" velocity="8.81"/>
    <safety_controller k_position="121.0" k_velocity="540.0" soft_lower_limit="-0.7574728953655391" soft_upper_limit="0.6370451769779303"/>
    <dynamics damping="0.0" friction="0.0"/>
  </joint>
  <gazebo reference="r_arm7_wrist_p_joint">
    <!-- Needed for ODE to output external wrenches on joints -->
    <provideFeedback>true</provideFeedback>
    <preserveFixedJoint>true</preserveFixedJoint>
    <disableFixedJointLumping>true</disableFixedJointLumping>
  </gazebo>
  <link name="r_end_effector_link"/>
  <joint name="r_end_effector_fixed_joint" type="fixed">
    <parent link="r_arm7_wrist_p_link"/>
    <child link="r_end_effector_link"/>
    <origin rpy="0 0 0" xyz="0 0 0"/>
    <axis xyz="0 0 1"/>
  </joint>
  <ros2_control name="r_arm_system" type="system">
    <hardware>
      <plugin>ign_ros2_control/IgnitionSystem</plugin>
    </hardware>
    <joint name="r_arm1_shoulder_p_joint">
      <param name="initial_position">0.0</param>
      <command_interface name="position"/>
      <state_interface name="position">
        <param name="initial_value">0.0</param>
      </state_interface>
      <state_interface name="velocity"/>
      <state_interface name="effort"/>
    </joint>
    <transmission name="r_arm1_shoulder_p_transmission">
      <plugin>transmission_interface/SimpleTransmission</plugin>
      <joint name="r_arm1_shoulder_p_joint" role="joint1">
        <mechanical_reduction>1.0</mechanical_reduction>
        <offset>0</offset>
      </joint>
      <actuator name="r_arm1_shoulder_p_actuator" role="actuator1">
        <mechanical_reduction>1.0</mechanical_reduction>
        <offset>0</offset>
      </actuator>
    </transmission>
    <joint name="r_arm2_shoulder_r_joint">
      <param name="initial_position">0.0</param>
      <command_interface name="position"/>
      <state_interface name="position">
        <param name="initial_value">0.0</param>
      </state_interface>
      <state_interface name="velocity"/>
      <state_interface name="effort"/>
    </joint>
    <transmission name="r_arm2_shoulder_r_transmission">
      <plugin>transmission_interface/SimpleTransmission</plugin>
      <joint name="r_arm2_shoulder_r_joint" role="joint1">
        <mechanical_reduction>1.0</mechanical_reduction>
        <offset>0</offset>
      </joint>
      <actuator name="r_arm2_shoulder_r_actuator" role="actuator1">
        <mechanical_reduction>1.0</mechanical_reduction>
        <offset>0</offset>
      </actuator>
    </transmission>
    <joint name="r_arm3_shoulder_y_joint">
      <param name="initial_position">0.0</param>
      <command_interface name="position"/>
      <state_interface name="position">
        <param name="initial_value">0.0</param>
      </state_interface>
      <state_interface name="velocity"/>
      <state_interface name="effort"/>
    </joint>
    <transmission name="r_arm3_shoulder_y_transmission">
      <plugin>transmission_interface/SimpleTransmission</plugin>
      <joint name="r_arm3_shoulder_y_joint" role="joint1">
        <mechanical_reduction>1.0</mechanical_reduction>
        <offset>0</offset>
      </joint>
      <actuator name="r_arm3_shoulder_y_actuator" role="actuator1">
        <mechanical_reduction>1.0</mechanical_reduction>
        <offset>0</offset>
      </actuator>
    </transmission>
    <joint name="r_arm4_elbow_p_joint">
      <param name="initial_position">0.0</param>
      <command_interface name="position"/>
      <state_interface name="position">
        <param name="initial_value">0.0</param>
      </state_interface>
      <state_interface name="velocity"/>
      <state_interface name="effort"/>
    </joint>
    <transmission name="r_arm4_elbow_p_transmission">
      <plugin>transmission_interface/SimpleTransmission</plugin>
      <joint name="r_arm4_elbow_p_joint" role="joint1">
        <mechanical_reduction>1.0</mechanical_reduction>
        <offset>0</offset>
      </joint>
      <actuator name="r_arm4_elbow_p_actuator" role="actuator1">
        <mechanical_reduction>1.0</mechanical_reduction>
        <offset>0</offset>
      </actuator>
    </transmission>
    <joint name="r_arm5_wrist_y_joint">
      <param name="initial_position">0.0</param>
      <command_interface name="position"/>
      <state_interface name="position">
        <param name="initial_value">0.0</param>
      </state_interface>
      <state_interface name="velocity"/>
      <state_interface name="effort"/>
    </joint>
    <transmission name="r_arm5_wrist_y_transmission">
      <plugin>transmission_interface/SimpleTransmission</plugin>
      <joint name="r_arm5_wrist_y_joint" role="joint1">
        <mechanical_reduction>1.0</mechanical_reduction>
        <offset>0</offset>
      </joint>
      <actuator name="r_arm5_wrist_y_actuator" role="actuator1">
        <mechanical_reduction>1.0</mechanical_reduction>
        <offset>0</offset>
      </actuator>
    </transmission>
    <joint name="r_arm6_wrist_r_joint">
      <param name="initial_position">0.0</param>
      <command_interface name="position"/>
      <state_interface name="position">
        <param name="initial_value">0.0</param>
      </state_interface>
      <state_interface name="velocity"/>
      <state_interface name="effort"/>
    </joint>
    <transmission name="r_arm6_wrist_r_transmission">
      <plugin>transmission_interface/SimpleTransmission</plugin>
      <joint name="r_arm6_wrist_r_joint" role="joint1">
        <mechanical_reduction>1.0</mechanical_reduction>
        <offset>0</offset>
      </joint>
      <actuator name="r_arm6_wrist_r_actuator" role="actuator1">
        <mechanical_reduction>1.0</mechanical_reduction>
        <offset>0</offset>
      </actuator>
    </transmission>
    <joint name="r_arm7_wrist_p_joint">
      <param name="initial_position">0.0</param>
      <command_interface name="position"/>
      <state_interface name="position">
        <param name="initial_value">0.0</param>
      </state_interface>
      <state_interface name="velocity"/>
      <state_interface name="effort"/>
    </joint>
    <transmission name="r_arm7_wrist_p_transmission">
      <plugin>transmission_interface/SimpleTransmission</plugin>
      <joint name="r_arm7_wrist_p_joint" role="joint1">
        <mechanical_reduction>1.0</mechanical_reduction>
        <offset>0</offset>
      </joint>
      <actuator name="r_arm7_wrist_p_actuator" role="actuator1">
        <mechanical_reduction>1.0</mechanical_reduction>
        <offset>0</offset>
      </actuator>
    </transmission>
  </ros2_control>
  <link name="l_hand_palm_link">
    <visual name="l_hand_palm_link_vis">
      <origin rpy="0 0 0" xyz="0 0 0"/>
      <geometry>
        <sphere radius="0.005"/>
      </geometry>
      <material name="yellow">
        <color rgba="0.9 1.0 0.0 1.0"/>
      </material>
    </visual>
    <collision name="l_hand_palm_link_col">
      <origin rpy="0 0 0" xyz="0 0 0"/>
      <geometry>
        <sphere radius="0.005"/>
      </geometry>
    </collision>
    <inertial>
      <origin rpy="0. 0. 0." xyz="0. 0. 0."/>
      <mass value="1e-05"/>
      <inertia ixx="8.333333333333334e-11" ixy="0" ixz="0" iyy="8.333333333333334e-11" iyz="0" izz="1.25e-10"/>
    </inertial>
  </link>
  <gazebo reference="l_hand_palm_link">
    <mu1 value="0.85"/>
    <mu2 value="0.85"/>
    <maxContacts>10</maxContacts>
    <minDepth>0.0001</minDepth>
    <maxVel>0.01</maxVel>
    <selfCollide value="True"/>
  </gazebo>
  <joint name="l_hand_palm_fixed_joint" type="fixed">
    <parent link="l_arm7_wrist_p_link"/>
    <child link="l_hand_palm_link"/>
    <origin rpy="-3.1415926 0.0 1.5707963" xyz="0.0 0.0099 -0.0525"/>
    <axis xyz="0 0 1"/>
  </joint>
  <link name="l_thumb_cmc_y_link">
    <visual name="l_thumb_cmc_y_link_vis">
      <origin rpy="0 0 0" xyz="0 0 0"/>
      <geometry>
        <mesh filename="package://human_description/meshes/robot_hands/m92c_hand/visual/l_thumb_cmc_y_link.stl" scale="1e-3 1e-3 1e-3"/>
      </geometry>
      <material name="metal">
        <color rgba="0.85 0.85 0.85 1"/>
      </material>
    </visual>
    <collision name="l_thumb_cmc_y_link_col">
      <origin rpy="0 0 0" xyz="0 0 0"/>
      <geometry>
        <mesh filename="package://human_description/meshes/robot_hands/m92c_hand/collision/l_thumb_cmc_y_link.stl" scale="1e-3 1e-3 1e-3"/>
      </geometry>
    </collision>
    <inertial>
      <origin rpy="0.0 0.0 0.0" xyz="-0.0043445795 0.00073516028 0.00092114437"/>
      <mass value="4.5684539e-08"/>
      <inertia ixx="1.2807232e-07" ixy="-2.6031726e-08" ixz="9.2990531e-09" iyy="2.0994928e-07" iyz="2.3599758e-09" izz="1.8089779e-07"/>
    </inertial>
    <gazebo reference="l_thumb_cmc_y_link">
      <mu1 value="0.85"/>
      <mu2 value="0.85"/>
      <maxContacts>10</maxContacts>
      <minDepth>0.0001</minDepth>
      <maxVel>0.01</maxVel>
      <selfCollide value="True"/>
    </gazebo>
  </link>
  <joint name="l_thumb_cmc_y_joint" type="revolute">
    <parent link="l_hand_palm_link"/>
    <child link="l_thumb_cmc_y_link"/>
    <origin rpy="0.0 0.0 0.0" xyz="-0.021 0.02025 0.03885"/>
    <axis xyz="0 0 1"/>
    <limit effort="1000.0" lower="1.7627825445142729" upper="3.0962140930379407" velocity="1.0"/>
    <dynamics damping="0.05" friction="0.2"/>
  </joint>
  <gazebo reference="l_thumb_cmc_y_joint">
    <!-- Needed for ODE to output external wrenches on joints -->
    <provideFeedback>true</provideFeedback>
    <preserveFixedJoint>true</preserveFixedJoint>
    <disableFixedJointLumping>true</disableFixedJointLumping>
  </gazebo>
  <link name="l_thumb_cmc_p_link">
    <visual name="l_thumb_cmc_p_link_vis">
      <origin rpy="0 0 0" xyz="0 0 0"/>
      <geometry>
        <mesh filename="package://human_description/meshes/robot_hands/m92c_hand/visual/l_thumb_cmc_p_link.stl" scale="1e-3 1e-3 1e-3"/>
      </geometry>
      <material name="metal">
        <color rgba="0.85 0.85 0.85 1"/>
      </material>
    </visual>
    <collision name="l_thumb_cmc_p_link_col">
      <origin rpy="0 0 0" xyz="0 0 0"/>
      <geometry>
        <mesh filename="package://human_description/meshes/robot_hands/m92c_hand/collision/l_thumb_cmc_p_link.stl" scale="1e-3 1e-3 1e-3"/>
      </geometry>
    </collision>
    <inertial>
      <origin rpy="0.0 0.0 0.0" xyz="0.0037146239 0.0 0.025714396"/>
      <mass value="4.8359764e-07"/>
      <inertia ixx="1.1564874e-05" ixy="0.0" ixz="9.8057604e-07" iyy="1.2950704e-05" iyz="0.0" izz="4.7469757e-06"/>
    </inertial>
    <gazebo reference="l_thumb_cmc_p_link">
      <mu1 value="0.85"/>
      <mu2 value="0.85"/>
      <maxContacts>10</maxContacts>
      <minDepth>0.0001</minDepth>
      <maxVel>0.01</maxVel>
      <selfCollide value="True"/>
    </gazebo>
  </link>
  <joint name="l_thumb_cmc_p_joint" type="revolute">
    <parent link="l_thumb_cmc_y_link"/>
    <child link="l_thumb_cmc_p_link"/>
    <origin rpy="0.0 0.0 0.0" xyz="0.011 0.0 0.0"/>
    <axis xyz="0 1 0"/>
    <limit effort="1000.0" lower="0.31590459461097364" upper="0.9581857593448869" velocity="1.0"/>
    <dynamics damping="0.05" friction="0.2"/>
  </joint>
  <gazebo reference="l_thumb_cmc_p_joint">
    <!-- Needed for ODE to output external wrenches on joints -->
    <provideFeedback>true</provideFeedback>
    <preserveFixedJoint>true</preserveFixedJoint>
    <disableFixedJointLumping>true</disableFixedJointLumping>
  </gazebo>
  <link name="l_thumb_mcp_link">
    <visual name="l_thumb_mcp_link_vis">
      <origin rpy="0 0 0" xyz="0 0 0"/>
      <geometry>
        <mesh filename="package://human_description/meshes/robot_hands/m92c_hand/visual/l_thumb_mcp_link.stl" scale="1e-3 1e-3 1e-3"/>
      </geometry>
      <material name="metal">
        <color rgba="0.85 0.85 0.85 1"/>
      </material>
    </visual>
    <collision name="l_thumb_mcp_link_col">
      <origin rpy="0 0 0" xyz="0 0 0"/>
      <geometry>
        <mesh filename="package://human_description/meshes/robot_hands/m92c_hand/collision/l_thumb_mcp_link.stl" scale="1e-3 1e-3 1e-3"/>
      </geometry>
    </collision>
    <inertial>
      <origin rpy="0.0 0.0 0.0" xyz="0.0034051517 0 0.010727105"/>
      <mass value="7.5745038e-08"/>
      <inertia ixx="6.6016669e-07" ixy="0.0" ixz="-1.9329706e-08" iyy="6.3533864e-07" iyz="0.0" izz="6.546447e-07"/>
    </inertial>
    <gazebo reference="l_thumb_mcp_link">
      <mu1 value="0.85"/>
      <mu2 value="0.85"/>
      <maxContacts>10</maxContacts>
      <minDepth>0.0001</minDepth>
      <maxVel>0.01</maxVel>
      <selfCollide value="True"/>
    </gazebo>
  </link>
  <joint name="l_thumb_mcp_joint" type="revolute">
    <parent link="l_thumb_cmc_p_link"/>
    <child link="l_thumb_mcp_link"/>
    <origin rpy="0.0 0.0 0.0" xyz="0.0 0.0 0.05572"/>
    <axis xyz="0 1 0"/>
    <limit effort="1000.0" lower="0.0" upper="1.0000736613927508" velocity="1.0"/>
    <dynamics damping="0.05" friction="0.2"/>
    <mimic joint="l_thumb_cmc_p_joint" multiplier="1.257" offset="-1.192"/>
  </joint>
  <gazebo reference="l_thumb_mcp_joint">
    <!-- Needed for ODE to output external wrenches on joints -->
    <provideFeedback>true</provideFeedback>
    <preserveFixedJoint>true</preserveFixedJoint>
    <disableFixedJointLumping>true</disableFixedJointLumping>
  </gazebo>
  <link name="l_thumb_ip_link">
    <visual name="l_thumb_ip_link_vis">
      <origin rpy="0 0 0" xyz="0 0 0"/>
      <geometry>
        <mesh filename="package://human_description/meshes/robot_hands/m92c_hand/visual/l_thumb_ip_link.stl" scale="1e-3 1e-3 1e-3"/>
      </geometry>
      <material name="metal">
        <color rgba="0.85 0.85 0.85 1"/>
      </material>
    </visual>
    <collision name="l_thumb_ip_link_col">
      <origin rpy="0 0 0" xyz="0 0 0"/>
      <geometry>
        <mesh filename="package://human_description/meshes/robot_hands/m92c_hand/collision/l_thumb_ip_link.stl" scale="1e-3 1e-3 1e-3"/>
      </geometry>
    </collision>
    <inertial>
      <origin rpy="0.0 0.0 0.0" xyz="0.00058212386 4.4266405e-06 0.014881067"/>
      <mass value="8.7566711e-07"/>
      <inertia ixx="1.0204087e-06" ixy="-8.9029655e-11" ixz="7.0098201e-08" iyy="9.9146034e-07" iyz="1.7085357e-10" izz="3.1951504e-07"/>
    </inertial>
    <gazebo reference="l_thumb_ip_link">
      <mu1 value="0.85"/>
      <mu2 value="0.85"/>
      <maxContacts>10</maxContacts>
      <minDepth>0.0001</minDepth>
      <maxVel>0.01</maxVel>
      <selfCollide value="True"/>
    </gazebo>
  </link>
  <joint name="l_thumb_ip_joint" type="revolute">
    <parent link="l_thumb_mcp_link"/>
    <child link="l_thumb_ip_link"/>
    <origin rpy="0.0 0.0 0.0" xyz="0.0 0.0 0.02305"/>
    <axis xyz="0 1 0"/>
    <limit effort="1000.0" lower="0.0" upper="1.0000736613927508" velocity="1.0"/>
    <dynamics damping="0.05" friction="0.2"/>
    <mimic joint="l_thumb_cmc_p_joint" multiplier="1.009" offset="-0.85"/>
  </joint>
  <gazebo reference="l_thumb_ip_joint">
    <!-- Needed for ODE to output external wrenches on joints -->
    <provideFeedback>true</provideFeedback>
    <preserveFixedJoint>true</preserveFixedJoint>
    <disableFixedJointLumping>true</disableFixedJointLumping>
  </gazebo>
  <link name="l_index_mcp_link">
    <visual name="l_index_mcp_link_vis">
      <origin rpy="0 0 0" xyz="0 0 0"/>
      <geometry>
        <mesh filename="package://human_description/meshes/robot_hands/m92c_hand/visual/l_index_mcp_link.stl" scale="1e-3 1e-3 1e-3"/>
      </geometry>
      <material name="metal">
        <color rgba="0.85 0.85 0.85 1"/>
      </material>
    </visual>
    <collision name="l_index_mcp_link_col">
      <origin rpy="0 0 0" xyz="0 0 0"/>
      <geometry>
        <mesh filename="package://human_description/meshes/robot_hands/m92c_hand/collision/l_index_mcp_link.stl" scale="1e-3 1e-3 1e-3"/>
      </geometry>
    </collision>
    <inertial>
      <origin rpy="0 0 0" xyz="-0.0024318988 3.328481e-07 0.010028137"/>
      <mass value="9.3522071e-09"/>
      <inertia ixx="1.1533308e-06" ixy="-1.327215e-11" ixz="2.5106055e-08" iyy="1.1732561e-06" iyz="2.2192538e-11" izz="5.6009882e-07"/>
    </inertial>
    <gazebo reference="l_index_mcp_link">
      <mu1 value="0.85"/>
      <mu2 value="0.85"/>
      <maxContacts>10</maxContacts>
      <minDepth>0.0001</minDepth>
      <maxVel>0.01</maxVel>
      <selfCollide value="True"/>
    </gazebo>
  </link>
  <joint name="l_index_mcp_joint" type="revolute">
    <parent link="l_hand_palm_link"/>
    <child link="l_index_mcp_link"/>
    <origin rpy="-0.05236 0.0 0.0" xyz="-0.00227 0.02766 0.11556"/>
    <axis xyz="0 1 0"/>
    <limit effort="1000.0" lower="-1.7662732030182617" upper="-0.16406094968746698" velocity="1.0"/>
    <dynamics damping="0.05" friction="0.2"/>
  </joint>
  <gazebo reference="l_index_mcp_joint">
    <!-- Needed for ODE to output external wrenches on joints -->
    <provideFeedback>true</provideFeedback>
    <preserveFixedJoint>true</preserveFixedJoint>
    <disableFixedJointLumping>true</disableFixedJointLumping>
  </gazebo>
  <link name="l_index_pip_link">
    <visual name="l_index_pip_link_vis">
      <origin rpy="0 0 0" xyz="0 0 0"/>
      <geometry>
        <mesh filename="package://human_description/meshes/robot_hands/m92c_hand/visual/l_index_pip_link.stl" scale="1e-3 1e-3 1e-3"/>
      </geometry>
      <material name="metal">
        <color rgba="0.85 0.85 0.85 1"/>
      </material>
    </visual>
    <collision name="l_index_pip_link_col">
      <origin rpy="0 0 0" xyz="0 0 0"/>
      <geometry>
        <mesh filename="package://human_description/meshes/robot_hands/m92c_hand/collision/l_index_pip_link.stl" scale="1e-3 1e-3 1e-3"/>
      </geometry>
    </collision>
    <inertial>
      <origin rpy="0 0 0" xyz="-0.0021920592 2.81739e-06 0.023240314"/>
      <mass value="1.2033694e-10"/>
      <inertia ixx="2.8856205e-06" ixy="-5.3997072e-11" ixz="-2.4954332e-07" iyy="2.8726183e-06" iyz="-9.9600212e-11" izz="3.6244504e-07"/>
    </inertial>
    <gazebo reference="l_index_pip_link">
      <mu1 value="0.85"/>
      <mu2 value="0.85"/>
      <maxContacts>10</maxContacts>
      <minDepth>0.0001</minDepth>
      <maxVel>0.01</maxVel>
      <selfCollide value="True"/>
    </gazebo>
  </link>
  <joint name="l_index_pip_joint" type="revolute">
    <parent link="l_index_mcp_link"/>
    <child link="l_index_pip_link"/>
    <origin rpy="0.0 0.0 0.0" xyz="0.0 0.0 0.0325"/>
    <axis xyz="0 1 0"/>
    <limit effort="1000.0" lower="0.3385938748868999" upper="3.5831609543443586" velocity="1.0"/>
    <dynamics damping="0.05" friction="0.2"/>
    <mimic joint="l_index_mcp_joint" multiplier="0.9845" offset="0.3017"/>
  </joint>
  <gazebo reference="l_index_pip_joint">
    <!-- Needed for ODE to output external wrenches on joints -->
    <provideFeedback>true</provideFeedback>
    <preserveFixedJoint>true</preserveFixedJoint>
    <disableFixedJointLumping>true</disableFixedJointLumping>
  </gazebo>
  <link name="l_middle_mcp_link">
    <visual name="l_middle_mcp_link_vis">
      <origin rpy="0 0 0" xyz="0 0 0"/>
      <geometry>
        <mesh filename="package://human_description/meshes/robot_hands/m92c_hand/visual/l_middle_mcp_link.stl" scale="1e-3 1e-3 1e-3"/>
      </geometry>
      <material name="metal">
        <color rgba="0.85 0.85 0.85 1"/>
      </material>
    </visual>
    <collision name="l_middle_mcp_link_col">
      <origin rpy="0 0 0" xyz="0 0 0"/>
      <geometry>
        <mesh filename="package://human_description/meshes/robot_hands/m92c_hand/collision/l_middle_mcp_link.stl" scale="1e-3 1e-3 1e-3"/>
      </geometry>
    </collision>
    <inertial>
      <origin rpy="0 0 0" xyz="-0.0024318988 3.328481e-07 0.010028137"/>
      <mass value="9.3522071e-09"/>
      <inertia ixx="1.1533308e-06" ixy="-1.327215e-11" ixz="2.5106055e-08" iyy="1.1732561e-06" iyz="2.2192538e-11" izz="5.6009882e-07"/>
    </inertial>
    <gazebo reference="l_middle_mcp_link">
      <mu1 value="0.85"/>
      <mu2 value="0.85"/>
      <maxContacts>10</maxContacts>
      <minDepth>0.0001</minDepth>
      <maxVel>0.01</maxVel>
      <selfCollide value="True"/>
    </gazebo>
  </link>
  <joint name="l_middle_mcp_joint" type="revolute">
    <parent link="l_hand_palm_link"/>
    <child link="l_middle_mcp_link"/>
    <origin rpy="0.0 0.0 0.0" xyz="-0.00227 0.00675 0.1161"/>
    <axis xyz="0 1 0"/>
    <limit effort="1000.0" lower="-1.7662732030182617" upper="-0.16406094968746698" velocity="1.0"/>
    <dynamics damping="0.05" friction="0.2"/>
  </joint>
  <gazebo reference="l_middle_mcp_joint">
    <!-- Needed for ODE to output external wrenches on joints -->
    <provideFeedback>true</provideFeedback>
    <preserveFixedJoint>true</preserveFixedJoint>
    <disableFixedJointLumping>true</disableFixedJointLumping>
  </gazebo>
  <link name="l_middle_pip_link">
    <visual name="l_middle_pip_link_vis">
      <origin rpy="0 0 0" xyz="0 0 0"/>
      <geometry>
        <mesh filename="package://human_description/meshes/robot_hands/m92c_hand/visual/l_middle_pip_link.stl" scale="1e-3 1e-3 1e-3"/>
      </geometry>
      <material name="metal">
        <color rgba="0.85 0.85 0.85 1"/>
      </material>
    </visual>
    <collision name="l_middle_pip_link_col">
      <origin rpy="0 0 0" xyz="0 0 0"/>
      <geometry>
        <mesh filename="package://human_description/meshes/robot_hands/m92c_hand/collision/l_middle_pip_link.stl" scale="1e-3 1e-3 1e-3"/>
      </geometry>
    </collision>
    <inertial>
      <origin rpy="0 0 0" xyz="-0.0021920592 2.81739e-06 0.023240314"/>
      <mass value="1.2033694e-10"/>
      <inertia ixx="2.8856205e-06" ixy="-5.3997072e-11" ixz="-2.4954332e-07" iyy="2.8726183e-06" iyz="-9.9600212e-11" izz="3.6244504e-07"/>
    </inertial>
    <gazebo reference="l_middle_pip_link">
      <mu1 value="0.85"/>
      <mu2 value="0.85"/>
      <maxContacts>10</maxContacts>
      <minDepth>0.0001</minDepth>
      <maxVel>0.01</maxVel>
      <selfCollide value="True"/>
    </gazebo>
  </link>
  <joint name="l_middle_pip_joint" type="revolute">
    <parent link="l_middle_mcp_link"/>
    <child link="l_middle_pip_link"/>
    <origin rpy="0.0 0.0 0.0" xyz="0.0 0.0 0.0325"/>
    <axis xyz="0 1 0"/>
    <limit effort="1000.0" lower="0.3385938748868999" upper="3.5831609543443586" velocity="1.0"/>
    <dynamics damping="0.05" friction="0.2"/>
    <mimic joint="l_middle_mcp_joint" multiplier="0.9845" offset="0.3017"/>
  </joint>
  <gazebo reference="l_middle_pip_joint">
    <!-- Needed for ODE to output external wrenches on joints -->
    <provideFeedback>true</provideFeedback>
    <preserveFixedJoint>true</preserveFixedJoint>
    <disableFixedJointLumping>true</disableFixedJointLumping>
  </gazebo>
  <link name="l_ring_mcp_link">
    <visual name="l_ring_mcp_link_vis">
      <origin rpy="0 0 0" xyz="0 0 0"/>
      <geometry>
        <mesh filename="package://human_description/meshes/robot_hands/m92c_hand/visual/l_ring_mcp_link.stl" scale="1e-3 1e-3 1e-3"/>
      </geometry>
      <material name="metal">
        <color rgba="0.85 0.85 0.85 1"/>
      </material>
    </visual>
    <collision name="l_ring_mcp_link_col">
      <origin rpy="0 0 0" xyz="0 0 0"/>
      <geometry>
        <mesh filename="package://human_description/meshes/robot_hands/m92c_hand/collision/l_ring_mcp_link.stl" scale="1e-3 1e-3 1e-3"/>
      </geometry>
    </collision>
    <inertial>
      <origin rpy="0 0 0" xyz="-0.0024318988 3.328481e-07 0.010028137"/>
      <mass value="9.3522071e-09"/>
      <inertia ixx="1.1533308e-06" ixy="-1.327215e-11" ixz="2.5106055e-08" iyy="1.1732561e-06" iyz="2.2192538e-11" izz="5.6009882e-07"/>
    </inertial>
    <gazebo reference="l_ring_mcp_link">
      <mu1 value="0.85"/>
      <mu2 value="0.85"/>
      <maxContacts>10</maxContacts>
      <minDepth>0.0001</minDepth>
      <maxVel>0.01</maxVel>
      <selfCollide value="True"/>
    </gazebo>
  </link>
  <joint name="l_ring_mcp_joint" type="revolute">
    <parent link="l_hand_palm_link"/>
    <child link="l_ring_mcp_link"/>
    <origin rpy="0.06108 0.0 0.0" xyz="-0.00227 -0.01395 0.11541"/>
    <axis xyz="0 1 0"/>
    <limit effort="1000.0" lower="-1.7662732030182617" upper="-0.16406094968746698" velocity="1.0"/>
    <dynamics damping="0.05" friction="0.2"/>
  </joint>
  <gazebo reference="l_ring_mcp_joint">
    <!-- Needed for ODE to output external wrenches on joints -->
    <provideFeedback>true</provideFeedback>
    <preserveFixedJoint>true</preserveFixedJoint>
    <disableFixedJointLumping>true</disableFixedJointLumping>
  </gazebo>
  <link name="l_ring_pip_link">
    <visual name="l_ring_pip_link_vis">
      <origin rpy="0 0 0" xyz="0 0 0"/>
      <geometry>
        <mesh filename="package://human_description/meshes/robot_hands/m92c_hand/visual/l_ring_pip_link.stl" scale="1e-3 1e-3 1e-3"/>
      </geometry>
      <material name="metal">
        <color rgba="0.85 0.85 0.85 1"/>
      </material>
    </visual>
    <collision name="l_ring_pip_link_col">
      <origin rpy="0 0 0" xyz="0 0 0"/>
      <geometry>
        <mesh filename="package://human_description/meshes/robot_hands/m92c_hand/collision/l_ring_pip_link.stl" scale="1e-3 1e-3 1e-3"/>
      </geometry>
    </collision>
    <inertial>
      <origin rpy="0 0 0" xyz="-0.0021920592 2.81739e-06 0.023240314"/>
      <mass value="1.2033694e-10"/>
      <inertia ixx="2.8856205e-06" ixy="-5.3997072e-11" ixz="-2.4954332e-07" iyy="2.8726183e-06" iyz="-9.9600212e-11" izz="3.6244504e-07"/>
    </inertial>
    <gazebo reference="l_ring_pip_link">
      <mu1 value="0.85"/>
      <mu2 value="0.85"/>
      <maxContacts>10</maxContacts>
      <minDepth>0.0001</minDepth>
      <maxVel>0.01</maxVel>
      <selfCollide value="True"/>
    </gazebo>
  </link>
  <joint name="l_ring_pip_joint" type="revolute">
    <parent link="l_ring_mcp_link"/>
    <child link="l_ring_pip_link"/>
    <origin rpy="0.0 0.0 0.0" xyz="0.0 0.0 0.0325"/>
    <axis xyz="0 1 0"/>
    <limit effort="1000.0" lower="0.3385938748868999" upper="3.5831609543443586" velocity="1.0"/>
    <dynamics damping="0.05" friction="0.2"/>
    <mimic joint="l_ring_mcp_joint" multiplier="0.9845" offset="0.3017"/>
  </joint>
  <gazebo reference="l_ring_pip_joint">
    <!-- Needed for ODE to output external wrenches on joints -->
    <provideFeedback>true</provideFeedback>
    <preserveFixedJoint>true</preserveFixedJoint>
    <disableFixedJointLumping>true</disableFixedJointLumping>
  </gazebo>
  <link name="l_pinky_mcp_link">
    <visual name="l_pinky_mcp_link_vis">
      <origin rpy="0 0 0" xyz="0 0 0"/>
      <geometry>
        <mesh filename="package://human_description/meshes/robot_hands/m92c_hand/visual/l_pinky_mcp_link.stl" scale="1e-3 1e-3 1e-3"/>
      </geometry>
      <material name="metal">
        <color rgba="0.85 0.85 0.85 1"/>
      </material>
    </visual>
    <collision name="l_pinky_mcp_link_col">
      <origin rpy="0 0 0" xyz="0 0 0"/>
      <geometry>
        <mesh filename="package://human_description/meshes/robot_hands/m92c_hand/collision/l_pinky_mcp_link.stl" scale="1e-3 1e-3 1e-3"/>
      </geometry>
    </collision>
    <inertial>
      <origin rpy="0 0 0" xyz="-0.0024318988 3.328481e-07 0.010028137"/>
      <mass value="9.3522071e-09"/>
      <inertia ixx="1.1533308e-06" ixy="-1.327215e-11" ixz="2.5106055e-08" iyy="1.1732561e-06" iyz="2.2192538e-11" izz="5.6009882e-07"/>
    </inertial>
    <gazebo reference="l_pinky_mcp_link">
      <mu1 value="0.85"/>
      <mu2 value="0.85"/>
      <maxContacts>10</maxContacts>
      <minDepth>0.0001</minDepth>
      <maxVel>0.01</maxVel>
      <selfCollide value="True"/>
    </gazebo>
  </link>
  <joint name="l_pinky_mcp_joint" type="revolute">
    <parent link="l_hand_palm_link"/>
    <child link="l_pinky_mcp_link"/>
    <origin rpy="0.12211 0.0 0.0" xyz="-0.00227 -0.03431 0.11361"/>
    <axis xyz="0 1 0"/>
    <limit effort="1000.0" lower="-1.7662732030182617" upper="-0.16406094968746698" velocity="1.0"/>
    <dynamics damping="0.05" friction="0.2"/>
  </joint>
  <gazebo reference="l_pinky_mcp_joint">
    <!-- Needed for ODE to output external wrenches on joints -->
    <provideFeedback>true</provideFeedback>
    <preserveFixedJoint>true</preserveFixedJoint>
    <disableFixedJointLumping>true</disableFixedJointLumping>
  </gazebo>
  <link name="l_pinky_pip_link">
    <visual name="l_pinky_pip_link_vis">
      <origin rpy="0 0 0" xyz="0 0 0"/>
      <geometry>
        <mesh filename="package://human_description/meshes/robot_hands/m92c_hand/visual/l_pinky_pip_link.stl" scale="1e-3 1e-3 1e-3"/>
      </geometry>
      <material name="metal">
        <color rgba="0.85 0.85 0.85 1"/>
      </material>
    </visual>
    <collision name="l_pinky_pip_link_col">
      <origin rpy="0 0 0" xyz="0 0 0"/>
      <geometry>
        <mesh filename="package://human_description/meshes/robot_hands/m92c_hand/collision/l_pinky_pip_link.stl" scale="1e-3 1e-3 1e-3"/>
      </geometry>
    </collision>
    <inertial>
      <origin rpy="0 0 0" xyz="-0.0021920592 2.81739e-06 0.023240314"/>
      <mass value="1.2033694e-10"/>
      <inertia ixx="2.8856205e-06" ixy="-5.3997072e-11" ixz="-2.4954332e-07" iyy="2.8726183e-06" iyz="-9.9600212e-11" izz="3.6244504e-07"/>
    </inertial>
    <gazebo reference="l_pinky_pip_link">
      <mu1 value="0.85"/>
      <mu2 value="0.85"/>
      <maxContacts>10</maxContacts>
      <minDepth>0.0001</minDepth>
      <maxVel>0.01</maxVel>
      <selfCollide value="True"/>
    </gazebo>
  </link>
  <joint name="l_pinky_pip_joint" type="revolute">
    <parent link="l_pinky_mcp_link"/>
    <child link="l_pinky_pip_link"/>
    <origin rpy="0.0 0.0 0.0" xyz="0.0 0.0 0.0325"/>
    <axis xyz="0 1 0"/>
    <limit effort="1000.0" lower="0.3385938748868999" upper="3.5831609543443586" velocity="1.0"/>
    <dynamics damping="0.05" friction="0.2"/>
    <mimic joint="l_pinky_mcp_joint" multiplier="0.9845" offset="0.3017"/>
  </joint>
  <gazebo reference="l_pinky_pip_joint">
    <!-- Needed for ODE to output external wrenches on joints -->
    <provideFeedback>true</provideFeedback>
    <preserveFixedJoint>true</preserveFixedJoint>
    <disableFixedJointLumping>true</disableFixedJointLumping>
  </gazebo>
  <ros2_control name="l_hand_system" type="system">
    <hardware>
      <plugin>ign_ros2_control/IgnitionSystem</plugin>
    </hardware>
    <joint name="l_thumb_cmc_y_joint">
      <param name="initial_position">0.0</param>
      <command_interface name="position"/>
      <state_interface name="position">
        <param name="initial_value">0.0</param>
      </state_interface>
      <state_interface name="velocity"/>
      <state_interface name="effort"/>
    </joint>
    <transmission name="l_thumb_cmc_y_transmission">
      <plugin>transmission_interface/SimpleTransmission</plugin>
      <joint name="l_thumb_cmc_y_joint" role="joint1">
        <mechanical_reduction>1.0</mechanical_reduction>
        <offset>0</offset>
      </joint>
      <actuator name="l_thumb_cmc_y_actuator" role="actuator1">
        <mechanical_reduction>1.0</mechanical_reduction>
        <offset>0</offset>
      </actuator>
    </transmission>
    <joint name="l_thumb_cmc_p_joint">
      <param name="initial_position">0.0</param>
      <command_interface name="position"/>
      <state_interface name="position">
        <param name="initial_value">0.0</param>
      </state_interface>
      <state_interface name="velocity"/>
      <state_interface name="effort"/>
    </joint>
    <transmission name="l_thumb_cmc_p_transmission">
      <plugin>transmission_interface/SimpleTransmission</plugin>
      <joint name="l_thumb_cmc_p_joint" role="joint1">
        <mechanical_reduction>1.0</mechanical_reduction>
        <offset>0</offset>
      </joint>
      <actuator name="l_thumb_cmc_p_actuator" role="actuator1">
        <mechanical_reduction>1.0</mechanical_reduction>
        <offset>0</offset>
      </actuator>
    </transmission>
    <joint name="l_thumb_mcp_joint">
      <param name="initial_position">0.0</param>
      <param name="mimic">l_thumb_cmc_p_joint</param>
      <param name="multiplier">1</param>
      <command_interface name="position"/>
      <state_interface name="position">
        <param name="initial_value">0.0</param>
      </state_interface>
      <state_interface name="velocity"/>
      <state_interface name="effort"/>
    </joint>
    <joint name="l_thumb_ip_joint">
      <param name="initial_position">0.0</param>
      <param name="mimic">l_thumb_cmc_p_joint</param>
      <param name="multiplier">1</param>
      <command_interface name="position"/>
      <state_interface name="position">
        <param name="initial_value">0.0</param>
      </state_interface>
      <state_interface name="velocity"/>
      <state_interface name="effort"/>
    </joint>
    <joint name="l_index_mcp_joint">
      <param name="initial_position">0.0</param>
      <command_interface name="position"/>
      <state_interface name="position">
        <param name="initial_value">0.0</param>
      </state_interface>
      <state_interface name="velocity"/>
      <state_interface name="effort"/>
    </joint>
    <transmission name="l_index_mcp_transmission">
      <plugin>transmission_interface/SimpleTransmission</plugin>
      <joint name="l_index_mcp_joint" role="joint1">
        <mechanical_reduction>1.0</mechanical_reduction>
        <offset>0</offset>
      </joint>
      <actuator name="l_index_mcp_actuator" role="actuator1">
        <mechanical_reduction>1.0</mechanical_reduction>
        <offset>0</offset>
      </actuator>
    </transmission>
    <joint name="l_index_pip_joint">
      <param name="initial_position">0.0</param>
      <param name="mimic">l_index_mcp_joint</param>
      <param name="multiplier">1</param>
      <command_interface name="position"/>
      <state_interface name="position">
        <param name="initial_value">0.0</param>
      </state_interface>
      <state_interface name="velocity"/>
      <state_interface name="effort"/>
    </joint>
    <joint name="l_middle_mcp_joint">
      <param name="initial_position">0.0</param>
      <command_interface name="position"/>
      <state_interface name="position">
        <param name="initial_value">0.0</param>
      </state_interface>
      <state_interface name="velocity"/>
      <state_interface name="effort"/>
    </joint>
    <transmission name="l_middle_mcp_transmission">
      <plugin>transmission_interface/SimpleTransmission</plugin>
      <joint name="l_middle_mcp_joint" role="joint1">
        <mechanical_reduction>1.0</mechanical_reduction>
        <offset>0</offset>
      </joint>
      <actuator name="l_middle_mcp_actuator" role="actuator1">
        <mechanical_reduction>1.0</mechanical_reduction>
        <offset>0</offset>
      </actuator>
    </transmission>
    <joint name="l_middle_pip_joint">
      <param name="initial_position">0.0</param>
      <param name="mimic">l_middle_mcp_joint</param>
      <param name="multiplier">1</param>
      <command_interface name="position"/>
      <state_interface name="position">
        <param name="initial_value">0.0</param>
      </state_interface>
      <state_interface name="velocity"/>
      <state_interface name="effort"/>
    </joint>
    <joint name="l_pinky_mcp_joint">
      <param name="initial_position">0.0</param>
      <command_interface name="position"/>
      <state_interface name="position">
        <param name="initial_value">0.0</param>
      </state_interface>
      <state_interface name="velocity"/>
      <state_interface name="effort"/>
    </joint>
    <transmission name="l_pinky_mcp_transmission">
      <plugin>transmission_interface/SimpleTransmission</plugin>
      <joint name="l_pinky_mcp_joint" role="joint1">
        <mechanical_reduction>1.0</mechanical_reduction>
        <offset>0</offset>
      </joint>
      <actuator name="l_pinky_mcp_actuator" role="actuator1">
        <mechanical_reduction>1.0</mechanical_reduction>
        <offset>0</offset>
      </actuator>
    </transmission>
    <joint name="l_pinky_pip_joint">
      <param name="initial_position">0.0</param>
      <param name="mimic">l_pinky_mcp_joint</param>
      <param name="multiplier">1</param>
      <command_interface name="position"/>
      <state_interface name="position">
        <param name="initial_value">0.0</param>
      </state_interface>
      <state_interface name="velocity"/>
      <state_interface name="effort"/>
    </joint>
    <joint name="l_ring_mcp_joint">
      <param name="initial_position">0.0</param>
      <command_interface name="position"/>
      <state_interface name="position">
        <param name="initial_value">0.0</param>
      </state_interface>
      <state_interface name="velocity"/>
      <state_interface name="effort"/>
    </joint>
    <transmission name="l_ring_mcp_transmission">
      <plugin>transmission_interface/SimpleTransmission</plugin>
      <joint name="l_ring_mcp_joint" role="joint1">
        <mechanical_reduction>1.0</mechanical_reduction>
        <offset>0</offset>
      </joint>
      <actuator name="l_ring_mcp_actuator" role="actuator1">
        <mechanical_reduction>1.0</mechanical_reduction>
        <offset>0</offset>
      </actuator>
    </transmission>
    <joint name="l_ring_pip_joint">
      <param name="initial_position">0.0</param>
      <param name="mimic">l_ring_mcp_joint</param>
      <param name="multiplier">1</param>
      <command_interface name="position"/>
      <state_interface name="position">
        <param name="initial_value">0.0</param>
      </state_interface>
      <state_interface name="velocity"/>
      <state_interface name="effort"/>
    </joint>
  </ros2_control>
  <link name="r_hand_palm_link">
    <visual name="r_hand_palm_link_vis">
      <origin rpy="0 0 0" xyz="0 0 0"/>
      <geometry>
        <sphere radius="0.005"/>
      </geometry>
      <material name="yellow">
        <color rgba="0.9 1.0 0.0 1.0"/>
      </material>
    </visual>
    <collision name="r_hand_palm_link_col">
      <origin rpy="0 0 0" xyz="0 0 0"/>
      <geometry>
        <sphere radius="0.005"/>
      </geometry>
    </collision>
    <inertial>
      <origin rpy="0. 0. 0." xyz="0. 0. 0."/>
      <mass value="1e-05"/>
      <inertia ixx="8.333333333333334e-11" ixy="0" ixz="0" iyy="8.333333333333334e-11" iyz="0" izz="1.25e-10"/>
    </inertial>
  </link>
  <gazebo reference="r_hand_palm_link">
    <mu1 value="0.85"/>
    <mu2 value="0.85"/>
    <maxContacts>10</maxContacts>
    <minDepth>0.0001</minDepth>
    <maxVel>0.01</maxVel>
    <selfCollide value="True"/>
  </gazebo>
  <joint name="r_hand_palm_fixed_joint" type="fixed">
    <parent link="r_arm7_wrist_p_link"/>
    <child link="r_hand_palm_link"/>
    <origin rpy="-3.1415926 0.0 1.5707963" xyz="0.0 -0.0099 -0.0525"/>
    <axis xyz="0 0 1"/>
  </joint>
  <link name="r_thumb_cmc_y_link">
    <visual name="r_thumb_cmc_y_link_vis">
      <origin rpy="0 0 0" xyz="0 0 0"/>
      <geometry>
        <mesh filename="package://human_description/meshes/robot_hands/m92c_hand/visual/r_thumb_cmc_y_link.stl" scale="1e-3 1e-3 1e-3"/>
      </geometry>
      <material name="metal">
        <color rgba="0.85 0.85 0.85 1"/>
      </material>
    </visual>
    <collision name="r_thumb_cmc_y_link_col">
      <origin rpy="0 0 0" xyz="0 0 0"/>
      <geometry>
        <mesh filename="package://human_description/meshes/robot_hands/m92c_hand/collision/r_thumb_cmc_y_link.stl" scale="1e-3 1e-3 1e-3"/>
      </geometry>
    </collision>
    <inertial>
      <origin rpy="0.0 0.0 0.0" xyz="0.0043445795 0.00073516028 0.00092114437"/>
      <mass value="4.5684539e-08"/>
      <inertia ixx="1.2807232e-07" ixy="2.6031726e-08" ixz="-9.2990531e-09" iyy="2.0994928e-07" iyz="2.3599758e-09" izz="1.8089779e-07"/>
    </inertial>
    <gazebo reference="r_thumb_cmc_y_link">
      <mu1 value="0.85"/>
      <mu2 value="0.85"/>
      <maxContacts>10</maxContacts>
      <minDepth>0.0001</minDepth>
      <maxVel>0.01</maxVel>
      <selfCollide value="True"/>
    </gazebo>
  </link>
  <joint name="r_thumb_cmc_y_joint" type="revolute">
    <parent link="r_hand_palm_link"/>
    <child link="r_thumb_cmc_y_link"/>
    <origin rpy="0.0 0.0 0.0" xyz="0.021 0.02025 0.03885"/>
    <axis xyz="0 0 1"/>
    <limit effort="1000.0" lower="0.19198621771937624" upper="1.5254177662430441" velocity="1.0"/>
    <dynamics damping="0.05" friction="0.2"/>
  </joint>
  <gazebo reference="r_thumb_cmc_y_joint">
    <!-- Needed for ODE to output external wrenches on joints -->
    <provideFeedback>true</provideFeedback>
    <preserveFixedJoint>true</preserveFixedJoint>
    <disableFixedJointLumping>true</disableFixedJointLumping>
  </gazebo>
  <link name="r_thumb_cmc_p_link">
    <visual name="r_thumb_cmc_p_link_vis">
      <origin rpy="0 0 0" xyz="0 0 0"/>
      <geometry>
        <mesh filename="package://human_description/meshes/robot_hands/m92c_hand/visual/r_thumb_cmc_p_link.stl" scale="1e-3 1e-3 1e-3"/>
      </geometry>
      <material name="metal">
        <color rgba="0.85 0.85 0.85 1"/>
      </material>
    </visual>
    <collision name="r_thumb_cmc_p_link_col">
      <origin rpy="0 0 0" xyz="0 0 0"/>
      <geometry>
        <mesh filename="package://human_description/meshes/robot_hands/m92c_hand/collision/r_thumb_cmc_p_link.stl" scale="1e-3 1e-3 1e-3"/>
      </geometry>
    </collision>
    <inertial>
      <origin rpy="0.0 0.0 0.0" xyz="0.0037146239 0.0 0.025714396"/>
      <mass value="4.8359764e-07"/>
      <inertia ixx="1.1564874e-05" ixy="0.0" ixz="9.8057604e-07" iyy="1.2950704e-05" iyz="0.0" izz="4.7469757e-06"/>
    </inertial>
    <gazebo reference="r_thumb_cmc_p_link">
      <mu1 value="0.85"/>
      <mu2 value="0.85"/>
      <maxContacts>10</maxContacts>
      <minDepth>0.0001</minDepth>
      <maxVel>0.01</maxVel>
      <selfCollide value="True"/>
    </gazebo>
  </link>
  <joint name="r_thumb_cmc_p_joint" type="revolute">
    <parent link="r_thumb_cmc_y_link"/>
    <child link="r_thumb_cmc_p_link"/>
    <origin rpy="0.0 0.0 0.0" xyz="0.011 0.0 0.0"/>
    <axis xyz="0 1 0"/>
    <limit effort="1000.0" lower="0.31590459461097364" upper="0.9581857593448869" velocity="1.0"/>
    <dynamics damping="0.05" friction="0.2"/>
  </joint>
  <gazebo reference="r_thumb_cmc_p_joint">
    <!-- Needed for ODE to output external wrenches on joints -->
    <provideFeedback>true</provideFeedback>
    <preserveFixedJoint>true</preserveFixedJoint>
    <disableFixedJointLumping>true</disableFixedJointLumping>
  </gazebo>
  <link name="r_thumb_mcp_link">
    <visual name="r_thumb_mcp_link_vis">
      <origin rpy="0 0 0" xyz="0 0 0"/>
      <geometry>
        <mesh filename="package://human_description/meshes/robot_hands/m92c_hand/visual/r_thumb_mcp_link.stl" scale="1e-3 1e-3 1e-3"/>
      </geometry>
      <material name="metal">
        <color rgba="0.85 0.85 0.85 1"/>
      </material>
    </visual>
    <collision name="r_thumb_mcp_link_col">
      <origin rpy="0 0 0" xyz="0 0 0"/>
      <geometry>
        <mesh filename="package://human_description/meshes/robot_hands/m92c_hand/collision/r_thumb_mcp_link.stl" scale="1e-3 1e-3 1e-3"/>
      </geometry>
    </collision>
    <inertial>
      <origin rpy="0.0 0.0 0.0" xyz="0.0034051517 0 0.010727105"/>
      <mass value="7.5745038e-08"/>
      <inertia ixx="6.6016669e-07" ixy="0.0" ixz="-1.9329706e-08" iyy="6.3533864e-07" iyz="0.0" izz="6.546447e-07"/>
    </inertial>
    <gazebo reference="r_thumb_mcp_link">
      <mu1 value="0.85"/>
      <mu2 value="0.85"/>
      <maxContacts>10</maxContacts>
      <minDepth>0.0001</minDepth>
      <maxVel>0.01</maxVel>
      <selfCollide value="True"/>
    </gazebo>
  </link>
  <joint name="r_thumb_mcp_joint" type="revolute">
    <parent link="r_thumb_cmc_p_link"/>
    <child link="r_thumb_mcp_link"/>
    <origin rpy="0.0 0.0 0.0" xyz="0.0 0.0 0.05572"/>
    <axis xyz="0 1 0"/>
    <limit effort="1000.0" lower="0.0" upper="1.0000736613927508" velocity="1.0"/>
    <dynamics damping="0.05" friction="0.2"/>
    <mimic joint="r_thumb_cmc_p_joint" multiplier="1.257" offset="-1.192"/>
  </joint>
  <gazebo reference="r_thumb_mcp_joint">
    <!-- Needed for ODE to output external wrenches on joints -->
    <provideFeedback>true</provideFeedback>
    <preserveFixedJoint>true</preserveFixedJoint>
    <disableFixedJointLumping>true</disableFixedJointLumping>
  </gazebo>
  <link name="r_thumb_ip_link">
    <visual name="r_thumb_ip_link_vis">
      <origin rpy="0 0 0" xyz="0 0 0"/>
      <geometry>
        <mesh filename="package://human_description/meshes/robot_hands/m92c_hand/visual/r_thumb_ip_link.stl" scale="1e-3 1e-3 1e-3"/>
      </geometry>
      <material name="metal">
        <color rgba="0.85 0.85 0.85 1"/>
      </material>
    </visual>
    <collision name="r_thumb_ip_link_col">
      <origin rpy="0 0 0" xyz="0 0 0"/>
      <geometry>
        <mesh filename="package://human_description/meshes/robot_hands/m92c_hand/collision/r_thumb_ip_link.stl" scale="1e-3 1e-3 1e-3"/>
      </geometry>
    </collision>
    <inertial>
      <origin rpy="0.0 0.0 0.0" xyz="0.00058212386 4.4266405e-06 0.014881067"/>
      <mass value="8.7566711e-07"/>
      <inertia ixx="1.0204087e-06" ixy="-8.9029655e-11" ixz="7.0098201e-08" iyy="9.9146034e-07" iyz="1.7085357e-10" izz="3.1951504e-07"/>
    </inertial>
    <gazebo reference="r_thumb_ip_link">
      <mu1 value="0.85"/>
      <mu2 value="0.85"/>
      <maxContacts>10</maxContacts>
      <minDepth>0.0001</minDepth>
      <maxVel>0.01</maxVel>
      <selfCollide value="True"/>
    </gazebo>
  </link>
  <joint name="r_thumb_ip_joint" type="revolute">
    <parent link="r_thumb_mcp_link"/>
    <child link="r_thumb_ip_link"/>
    <origin rpy="0.0 0.0 0.0" xyz="0.0 0.0 0.02305"/>
    <axis xyz="0 1 0"/>
    <limit effort="1000.0" lower="0.0" upper="1.0000736613927508" velocity="1.0"/>
    <dynamics damping="0.05" friction="0.2"/>
    <mimic joint="r_thumb_cmc_p_joint" multiplier="1.009" offset="-0.85"/>
  </joint>
  <gazebo reference="r_thumb_ip_joint">
    <!-- Needed for ODE to output external wrenches on joints -->
    <provideFeedback>true</provideFeedback>
    <preserveFixedJoint>true</preserveFixedJoint>
    <disableFixedJointLumping>true</disableFixedJointLumping>
  </gazebo>
  <link name="r_index_mcp_link">
    <visual name="r_index_mcp_link_vis">
      <origin rpy="0 0 0" xyz="0 0 0"/>
      <geometry>
        <mesh filename="package://human_description/meshes/robot_hands/m92c_hand/visual/r_index_mcp_link.stl" scale="1e-3 1e-3 1e-3"/>
      </geometry>
      <material name="metal">
        <color rgba="0.85 0.85 0.85 1"/>
      </material>
    </visual>
    <collision name="r_index_mcp_link_col">
      <origin rpy="0 0 0" xyz="0 0 0"/>
      <geometry>
        <mesh filename="package://human_description/meshes/robot_hands/m92c_hand/collision/r_index_mcp_link.stl" scale="1e-3 1e-3 1e-3"/>
      </geometry>
    </collision>
    <inertial>
      <origin rpy="0 0 0" xyz="-0.0024318988 3.328481e-07 0.010028137"/>
      <mass value="9.3522071e-09"/>
      <inertia ixx="1.1533308e-06" ixy="-1.327215e-11" ixz="2.5106055e-08" iyy="1.1732561e-06" iyz="2.2192538e-11" izz="5.6009882e-07"/>
    </inertial>
    <gazebo reference="r_index_mcp_link">
      <mu1 value="0.85"/>
      <mu2 value="0.85"/>
      <maxContacts>10</maxContacts>
      <minDepth>0.0001</minDepth>
      <maxVel>0.01</maxVel>
      <selfCollide value="True"/>
    </gazebo>
  </link>
  <joint name="r_index_mcp_joint" type="revolute">
    <parent link="r_hand_palm_link"/>
    <child link="r_index_mcp_link"/>
    <origin rpy="-0.05236 0.0 0.0" xyz="0.00227 0.02766 0.11556"/>
    <axis xyz="0 1 0"/>
    <limit effort="1000.0" lower="0.16406094968746698" upper="1.7662732030182617" velocity="1.0"/>
    <dynamics damping="0.05" friction="0.2"/>
  </joint>
  <gazebo reference="r_index_mcp_joint">
    <!-- Needed for ODE to output external wrenches on joints -->
    <provideFeedback>true</provideFeedback>
    <preserveFixedJoint>true</preserveFixedJoint>
    <disableFixedJointLumping>true</disableFixedJointLumping>
  </gazebo>
  <link name="r_index_pip_link">
    <visual name="r_index_pip_link_vis">
      <origin rpy="0 0 0" xyz="0 0 0"/>
      <geometry>
        <mesh filename="package://human_description/meshes/robot_hands/m92c_hand/visual/r_index_pip_link.stl" scale="1e-3 1e-3 1e-3"/>
      </geometry>
      <material name="metal">
        <color rgba="0.85 0.85 0.85 1"/>
      </material>
    </visual>
    <collision name="r_index_pip_link_col">
      <origin rpy="0 0 0" xyz="0 0 0"/>
      <geometry>
        <mesh filename="package://human_description/meshes/robot_hands/m92c_hand/collision/r_index_pip_link.stl" scale="1e-3 1e-3 1e-3"/>
      </geometry>
    </collision>
    <inertial>
      <origin rpy="0 0 0" xyz="-0.0021920592 2.81739e-06 0.023240314"/>
      <mass value="1.2033694e-10"/>
      <inertia ixx="2.8856205e-06" ixy="-5.3997072e-11" ixz="-2.4954332e-07" iyy="2.8726183e-06" iyz="-9.9600212e-11" izz="3.6244504e-07"/>
    </inertial>
    <gazebo reference="r_index_pip_link">
      <mu1 value="0.85"/>
      <mu2 value="0.85"/>
      <maxContacts>10</maxContacts>
      <minDepth>0.0001</minDepth>
      <maxVel>0.01</maxVel>
      <selfCollide value="True"/>
    </gazebo>
  </link>
  <joint name="r_index_pip_joint" type="revolute">
    <parent link="r_index_mcp_link"/>
    <child link="r_index_pip_link"/>
    <origin rpy="0.0 0.0 0.0" xyz="0.0 0.0 0.0325"/>
    <axis xyz="0 1 0"/>
    <limit effort="1000.0" lower="0.3385938748868999" upper="3.5831609543443586" velocity="1.0"/>
    <dynamics damping="0.05" friction="0.2"/>
    <mimic joint="r_index_mcp_joint" multiplier="0.9845" offset="-0.3017"/>
  </joint>
  <gazebo reference="r_index_pip_joint">
    <!-- Needed for ODE to output external wrenches on joints -->
    <provideFeedback>true</provideFeedback>
    <preserveFixedJoint>true</preserveFixedJoint>
    <disableFixedJointLumping>true</disableFixedJointLumping>
  </gazebo>
  <link name="r_middle_mcp_link">
    <visual name="r_middle_mcp_link_vis">
      <origin rpy="0 0 0" xyz="0 0 0"/>
      <geometry>
        <mesh filename="package://human_description/meshes/robot_hands/m92c_hand/visual/r_middle_mcp_link.stl" scale="1e-3 1e-3 1e-3"/>
      </geometry>
      <material name="metal">
        <color rgba="0.85 0.85 0.85 1"/>
      </material>
    </visual>
    <collision name="r_middle_mcp_link_col">
      <origin rpy="0 0 0" xyz="0 0 0"/>
      <geometry>
        <mesh filename="package://human_description/meshes/robot_hands/m92c_hand/collision/r_middle_mcp_link.stl" scale="1e-3 1e-3 1e-3"/>
      </geometry>
    </collision>
    <inertial>
      <origin rpy="0 0 0" xyz="-0.0024318988 3.328481e-07 0.010028137"/>
      <mass value="9.3522071e-09"/>
      <inertia ixx="1.1533308e-06" ixy="-1.327215e-11" ixz="2.5106055e-08" iyy="1.1732561e-06" iyz="2.2192538e-11" izz="5.6009882e-07"/>
    </inertial>
    <gazebo reference="r_middle_mcp_link">
      <mu1 value="0.85"/>
      <mu2 value="0.85"/>
      <maxContacts>10</maxContacts>
      <minDepth>0.0001</minDepth>
      <maxVel>0.01</maxVel>
      <selfCollide value="True"/>
    </gazebo>
  </link>
  <joint name="r_middle_mcp_joint" type="revolute">
    <parent link="r_hand_palm_link"/>
    <child link="r_middle_mcp_link"/>
    <origin rpy="0.0 0.0 0.0" xyz="0.00227 0.00675 0.1161"/>
    <axis xyz="0 1 0"/>
    <limit effort="1000.0" lower="0.16406094968746698" upper="1.7662732030182617" velocity="1.0"/>
    <dynamics damping="0.05" friction="0.2"/>
  </joint>
  <gazebo reference="r_middle_mcp_joint">
    <!-- Needed for ODE to output external wrenches on joints -->
    <provideFeedback>true</provideFeedback>
    <preserveFixedJoint>true</preserveFixedJoint>
    <disableFixedJointLumping>true</disableFixedJointLumping>
  </gazebo>
  <link name="r_middle_pip_link">
    <visual name="r_middle_pip_link_vis">
      <origin rpy="0 0 0" xyz="0 0 0"/>
      <geometry>
        <mesh filename="package://human_description/meshes/robot_hands/m92c_hand/visual/r_middle_pip_link.stl" scale="1e-3 1e-3 1e-3"/>
      </geometry>
      <material name="metal">
        <color rgba="0.85 0.85 0.85 1"/>
      </material>
    </visual>
    <collision name="r_middle_pip_link_col">
      <origin rpy="0 0 0" xyz="0 0 0"/>
      <geometry>
        <mesh filename="package://human_description/meshes/robot_hands/m92c_hand/collision/r_middle_pip_link.stl" scale="1e-3 1e-3 1e-3"/>
      </geometry>
    </collision>
    <inertial>
      <origin rpy="0 0 0" xyz="-0.0021920592 2.81739e-06 0.023240314"/>
      <mass value="1.2033694e-10"/>
      <inertia ixx="2.8856205e-06" ixy="-5.3997072e-11" ixz="-2.4954332e-07" iyy="2.8726183e-06" iyz="-9.9600212e-11" izz="3.6244504e-07"/>
    </inertial>
    <gazebo reference="r_middle_pip_link">
      <mu1 value="0.85"/>
      <mu2 value="0.85"/>
      <maxContacts>10</maxContacts>
      <minDepth>0.0001</minDepth>
      <maxVel>0.01</maxVel>
      <selfCollide value="True"/>
    </gazebo>
  </link>
  <joint name="r_middle_pip_joint" type="revolute">
    <parent link="r_middle_mcp_link"/>
    <child link="r_middle_pip_link"/>
    <origin rpy="0.0 0.0 0.0" xyz="0.0 0.0 0.0325"/>
    <axis xyz="0 1 0"/>
    <limit effort="1000.0" lower="0.3385938748868999" upper="3.5831609543443586" velocity="1.0"/>
    <dynamics damping="0.05" friction="0.2"/>
    <mimic joint="r_middle_mcp_joint" multiplier="0.9845" offset="-0.3017"/>
  </joint>
  <gazebo reference="r_middle_pip_joint">
    <!-- Needed for ODE to output external wrenches on joints -->
    <provideFeedback>true</provideFeedback>
    <preserveFixedJoint>true</preserveFixedJoint>
    <disableFixedJointLumping>true</disableFixedJointLumping>
  </gazebo>
  <link name="r_ring_mcp_link">
    <visual name="r_ring_mcp_link_vis">
      <origin rpy="0 0 0" xyz="0 0 0"/>
      <geometry>
        <mesh filename="package://human_description/meshes/robot_hands/m92c_hand/visual/r_ring_mcp_link.stl" scale="1e-3 1e-3 1e-3"/>
      </geometry>
      <material name="metal">
        <color rgba="0.85 0.85 0.85 1"/>
      </material>
    </visual>
    <collision name="r_ring_mcp_link_col">
      <origin rpy="0 0 0" xyz="0 0 0"/>
      <geometry>
        <mesh filename="package://human_description/meshes/robot_hands/m92c_hand/collision/r_ring_mcp_link.stl" scale="1e-3 1e-3 1e-3"/>
      </geometry>
    </collision>
    <inertial>
      <origin rpy="0 0 0" xyz="-0.0024318988 3.328481e-07 0.010028137"/>
      <mass value="9.3522071e-09"/>
      <inertia ixx="1.1533308e-06" ixy="-1.327215e-11" ixz="2.5106055e-08" iyy="1.1732561e-06" iyz="2.2192538e-11" izz="5.6009882e-07"/>
    </inertial>
    <gazebo reference="r_ring_mcp_link">
      <mu1 value="0.85"/>
      <mu2 value="0.85"/>
      <maxContacts>10</maxContacts>
      <minDepth>0.0001</minDepth>
      <maxVel>0.01</maxVel>
      <selfCollide value="True"/>
    </gazebo>
  </link>
  <joint name="r_ring_mcp_joint" type="revolute">
    <parent link="r_hand_palm_link"/>
    <child link="r_ring_mcp_link"/>
    <origin rpy="0.06108 0.0 0.0" xyz="0.00227 -0.01395 0.11541"/>
    <axis xyz="0 1 0"/>
    <limit effort="1000.0" lower="0.16406094968746698" upper="1.7662732030182617" velocity="1.0"/>
    <dynamics damping="0.05" friction="0.2"/>
  </joint>
  <gazebo reference="r_ring_mcp_joint">
    <!-- Needed for ODE to output external wrenches on joints -->
    <provideFeedback>true</provideFeedback>
    <preserveFixedJoint>true</preserveFixedJoint>
    <disableFixedJointLumping>true</disableFixedJointLumping>
  </gazebo>
  <link name="r_ring_pip_link">
    <visual name="r_ring_pip_link_vis">
      <origin rpy="0 0 0" xyz="0 0 0"/>
      <geometry>
        <mesh filename="package://human_description/meshes/robot_hands/m92c_hand/visual/r_ring_pip_link.stl" scale="1e-3 1e-3 1e-3"/>
      </geometry>
      <material name="metal">
        <color rgba="0.85 0.85 0.85 1"/>
      </material>
    </visual>
    <collision name="r_ring_pip_link_col">
      <origin rpy="0 0 0" xyz="0 0 0"/>
      <geometry>
        <mesh filename="package://human_description/meshes/robot_hands/m92c_hand/collision/r_ring_pip_link.stl" scale="1e-3 1e-3 1e-3"/>
      </geometry>
    </collision>
    <inertial>
      <origin rpy="0 0 0" xyz="-0.0021920592 2.81739e-06 0.023240314"/>
      <mass value="1.2033694e-10"/>
      <inertia ixx="2.8856205e-06" ixy="-5.3997072e-11" ixz="-2.4954332e-07" iyy="2.8726183e-06" iyz="-9.9600212e-11" izz="3.6244504e-07"/>
    </inertial>
    <gazebo reference="r_ring_pip_link">
      <mu1 value="0.85"/>
      <mu2 value="0.85"/>
      <maxContacts>10</maxContacts>
      <minDepth>0.0001</minDepth>
      <maxVel>0.01</maxVel>
      <selfCollide value="True"/>
    </gazebo>
  </link>
  <joint name="r_ring_pip_joint" type="revolute">
    <parent link="r_ring_mcp_link"/>
    <child link="r_ring_pip_link"/>
    <origin rpy="0.0 0.0 0.0" xyz="0.0 0.0 0.0325"/>
    <axis xyz="0 1 0"/>
    <limit effort="1000.0" lower="0.3385938748868999" upper="3.5831609543443586" velocity="1.0"/>
    <dynamics damping="0.05" friction="0.2"/>
    <mimic joint="r_ring_mcp_joint" multiplier="0.9845" offset="-0.3017"/>
  </joint>
  <gazebo reference="r_ring_pip_joint">
    <!-- Needed for ODE to output external wrenches on joints -->
    <provideFeedback>true</provideFeedback>
    <preserveFixedJoint>true</preserveFixedJoint>
    <disableFixedJointLumping>true</disableFixedJointLumping>
  </gazebo>
  <link name="r_pinky_mcp_link">
    <visual name="r_pinky_mcp_link_vis">
      <origin rpy="0 0 0" xyz="0 0 0"/>
      <geometry>
        <mesh filename="package://human_description/meshes/robot_hands/m92c_hand/visual/r_pinky_mcp_link.stl" scale="1e-3 1e-3 1e-3"/>
      </geometry>
      <material name="metal">
        <color rgba="0.85 0.85 0.85 1"/>
      </material>
    </visual>
    <collision name="r_pinky_mcp_link_col">
      <origin rpy="0 0 0" xyz="0 0 0"/>
      <geometry>
        <mesh filename="package://human_description/meshes/robot_hands/m92c_hand/collision/r_pinky_mcp_link.stl" scale="1e-3 1e-3 1e-3"/>
      </geometry>
    </collision>
    <inertial>
      <origin rpy="0 0 0" xyz="-0.0024318988 3.328481e-07 0.010028137"/>
      <mass value="9.3522071e-09"/>
      <inertia ixx="1.1533308e-06" ixy="-1.327215e-11" ixz="2.5106055e-08" iyy="1.1732561e-06" iyz="2.2192538e-11" izz="5.6009882e-07"/>
    </inertial>
    <gazebo reference="r_pinky_mcp_link">
      <mu1 value="0.85"/>
      <mu2 value="0.85"/>
      <maxContacts>10</maxContacts>
      <minDepth>0.0001</minDepth>
      <maxVel>0.01</maxVel>
      <selfCollide value="True"/>
    </gazebo>
  </link>
  <joint name="r_pinky_mcp_joint" type="revolute">
    <parent link="r_hand_palm_link"/>
    <child link="r_pinky_mcp_link"/>
    <origin rpy="0.12211 0.0 0.0" xyz="0.00227 -0.03431 0.11361"/>
    <axis xyz="0 1 0"/>
    <limit effort="1000.0" lower="0.16406094968746698" upper="1.7662732030182617" velocity="1.0"/>
    <dynamics damping="0.05" friction="0.2"/>
  </joint>
  <gazebo reference="r_pinky_mcp_joint">
    <!-- Needed for ODE to output external wrenches on joints -->
    <provideFeedback>true</provideFeedback>
    <preserveFixedJoint>true</preserveFixedJoint>
    <disableFixedJointLumping>true</disableFixedJointLumping>
  </gazebo>
  <link name="r_pinky_pip_link">
    <visual name="r_pinky_pip_link_vis">
      <origin rpy="0 0 0" xyz="0 0 0"/>
      <geometry>
        <mesh filename="package://human_description/meshes/robot_hands/m92c_hand/visual/r_pinky_pip_link.stl" scale="1e-3 1e-3 1e-3"/>
      </geometry>
      <material name="metal">
        <color rgba="0.85 0.85 0.85 1"/>
      </material>
    </visual>
    <collision name="r_pinky_pip_link_col">
      <origin rpy="0 0 0" xyz="0 0 0"/>
      <geometry>
        <mesh filename="package://human_description/meshes/robot_hands/m92c_hand/collision/r_pinky_pip_link.stl" scale="1e-3 1e-3 1e-3"/>
      </geometry>
    </collision>
    <inertial>
      <origin rpy="0 0 0" xyz="-0.0021920592 2.81739e-06 0.023240314"/>
      <mass value="1.2033694e-10"/>
      <inertia ixx="2.8856205e-06" ixy="-5.3997072e-11" ixz="-2.4954332e-07" iyy="2.8726183e-06" iyz="-9.9600212e-11" izz="3.6244504e-07"/>
    </inertial>
    <gazebo reference="r_pinky_pip_link">
      <mu1 value="0.85"/>
      <mu2 value="0.85"/>
      <maxContacts>10</maxContacts>
      <minDepth>0.0001</minDepth>
      <maxVel>0.01</maxVel>
      <selfCollide value="True"/>
    </gazebo>
  </link>
  <joint name="r_pinky_pip_joint" type="revolute">
    <parent link="r_pinky_mcp_link"/>
    <child link="r_pinky_pip_link"/>
    <origin rpy="0.0 0.0 0.0" xyz="0.0 0.0 0.0325"/>
    <axis xyz="0 1 0"/>
    <limit effort="1000.0" lower="0.3385938748868999" upper="3.5831609543443586" velocity="1.0"/>
    <dynamics damping="0.05" friction="0.2"/>
    <mimic joint="r_pinky_mcp_joint" multiplier="0.9845" offset="-0.3017"/>
  </joint>
  <gazebo reference="r_pinky_pip_joint">
    <!-- Needed for ODE to output external wrenches on joints -->
    <provideFeedback>true</provideFeedback>
    <preserveFixedJoint>true</preserveFixedJoint>
    <disableFixedJointLumping>true</disableFixedJointLumping>
  </gazebo>
  <ros2_control name="r_hand_system" type="system">
    <hardware>
      <plugin>ign_ros2_control/IgnitionSystem</plugin>
    </hardware>
    <joint name="r_thumb_cmc_y_joint">
      <param name="initial_position">0.0</param>
      <command_interface name="position"/>
      <state_interface name="position">
        <param name="initial_value">0.0</param>
      </state_interface>
      <state_interface name="velocity"/>
      <state_interface name="effort"/>
    </joint>
    <transmission name="r_thumb_cmc_y_transmission">
      <plugin>transmission_interface/SimpleTransmission</plugin>
      <joint name="r_thumb_cmc_y_joint" role="joint1">
        <mechanical_reduction>1.0</mechanical_reduction>
        <offset>0</offset>
      </joint>
      <actuator name="r_thumb_cmc_y_actuator" role="actuator1">
        <mechanical_reduction>1.0</mechanical_reduction>
        <offset>0</offset>
      </actuator>
    </transmission>
    <joint name="r_thumb_cmc_p_joint">
      <param name="initial_position">0.0</param>
      <command_interface name="position"/>
      <state_interface name="position">
        <param name="initial_value">0.0</param>
      </state_interface>
      <state_interface name="velocity"/>
      <state_interface name="effort"/>
    </joint>
    <transmission name="r_thumb_cmc_p_transmission">
      <plugin>transmission_interface/SimpleTransmission</plugin>
      <joint name="r_thumb_cmc_p_joint" role="joint1">
        <mechanical_reduction>1.0</mechanical_reduction>
        <offset>0</offset>
      </joint>
      <actuator name="r_thumb_cmc_p_actuator" role="actuator1">
        <mechanical_reduction>1.0</mechanical_reduction>
        <offset>0</offset>
      </actuator>
    </transmission>
    <joint name="r_thumb_mcp_joint">
      <param name="initial_position">0.0</param>
      <param name="mimic">r_thumb_cmc_p_joint</param>
      <param name="multiplier">1</param>
      <command_interface name="position"/>
      <state_interface name="position">
        <param name="initial_value">0.0</param>
      </state_interface>
      <state_interface name="velocity"/>
      <state_interface name="effort"/>
    </joint>
    <joint name="r_thumb_ip_joint">
      <param name="initial_position">0.0</param>
      <param name="mimic">r_thumb_cmc_p_joint</param>
      <param name="multiplier">1</param>
      <command_interface name="position"/>
      <state_interface name="position">
        <param name="initial_value">0.0</param>
      </state_interface>
      <state_interface name="velocity"/>
      <state_interface name="effort"/>
    </joint>
    <joint name="r_index_mcp_joint">
      <param name="initial_position">0.0</param>
      <command_interface name="position"/>
      <state_interface name="position">
        <param name="initial_value">0.0</param>
      </state_interface>
      <state_interface name="velocity"/>
      <state_interface name="effort"/>
    </joint>
    <transmission name="r_index_mcp_transmission">
      <plugin>transmission_interface/SimpleTransmission</plugin>
      <joint name="r_index_mcp_joint" role="joint1">
        <mechanical_reduction>1.0</mechanical_reduction>
        <offset>0</offset>
      </joint>
      <actuator name="r_index_mcp_actuator" role="actuator1">
        <mechanical_reduction>1.0</mechanical_reduction>
        <offset>0</offset>
      </actuator>
    </transmission>
    <joint name="r_index_pip_joint">
      <param name="initial_position">0.0</param>
      <param name="mimic">r_index_mcp_joint</param>
      <param name="multiplier">1</param>
      <command_interface name="position"/>
      <state_interface name="position">
        <param name="initial_value">0.0</param>
      </state_interface>
      <state_interface name="velocity"/>
      <state_interface name="effort"/>
    </joint>
    <joint name="r_middle_mcp_joint">
      <param name="initial_position">0.0</param>
      <command_interface name="position"/>
      <state_interface name="position">
        <param name="initial_value">0.0</param>
      </state_interface>
      <state_interface name="velocity"/>
      <state_interface name="effort"/>
    </joint>
    <transmission name="r_middle_mcp_transmission">
      <plugin>transmission_interface/SimpleTransmission</plugin>
      <joint name="r_middle_mcp_joint" role="joint1">
        <mechanical_reduction>1.0</mechanical_reduction>
        <offset>0</offset>
      </joint>
      <actuator name="r_middle_mcp_actuator" role="actuator1">
        <mechanical_reduction>1.0</mechanical_reduction>
        <offset>0</offset>
      </actuator>
    </transmission>
    <joint name="r_middle_pip_joint">
      <param name="initial_position">0.0</param>
      <param name="mimic">r_middle_mcp_joint</param>
      <param name="multiplier">1</param>
      <command_interface name="position"/>
      <state_interface name="position">
        <param name="initial_value">0.0</param>
      </state_interface>
      <state_interface name="velocity"/>
      <state_interface name="effort"/>
    </joint>
    <joint name="r_pinky_mcp_joint">
      <param name="initial_position">0.0</param>
      <command_interface name="position"/>
      <state_interface name="position">
        <param name="initial_value">0.0</param>
      </state_interface>
      <state_interface name="velocity"/>
      <state_interface name="effort"/>
    </joint>
    <transmission name="r_pinky_mcp_transmission">
      <plugin>transmission_interface/SimpleTransmission</plugin>
      <joint name="r_pinky_mcp_joint" role="joint1">
        <mechanical_reduction>1.0</mechanical_reduction>
        <offset>0</offset>
      </joint>
      <actuator name="r_pinky_mcp_actuator" role="actuator1">
        <mechanical_reduction>1.0</mechanical_reduction>
        <offset>0</offset>
      </actuator>
    </transmission>
    <joint name="r_pinky_pip_joint">
      <param name="initial_position">0.0</param>
      <param name="mimic">r_pinky_mcp_joint</param>
      <param name="multiplier">1</param>
      <command_interface name="position"/>
      <state_interface name="position">
        <param name="initial_value">0.0</param>
      </state_interface>
      <state_interface name="velocity"/>
      <state_interface name="effort"/>
    </joint>
    <joint name="r_ring_mcp_joint">
      <param name="initial_position">0.0</param>
      <command_interface name="position"/>
      <state_interface name="position">
        <param name="initial_value">0.0</param>
      </state_interface>
      <state_interface name="velocity"/>
      <state_interface name="effort"/>
    </joint>
    <transmission name="r_ring_mcp_transmission">
      <plugin>transmission_interface/SimpleTransmission</plugin>
      <joint name="r_ring_mcp_joint" role="joint1">
        <mechanical_reduction>1.0</mechanical_reduction>
        <offset>0</offset>
      </joint>
      <actuator name="r_ring_mcp_actuator" role="actuator1">
        <mechanical_reduction>1.0</mechanical_reduction>
        <offset>0</offset>
      </actuator>
    </transmission>
    <joint name="r_ring_pip_joint">
      <param name="initial_position">0.0</param>
      <param name="mimic">r_ring_mcp_joint</param>
      <param name="multiplier">1</param>
      <command_interface name="position"/>
      <state_interface name="position">
        <param name="initial_value">0.0</param>
      </state_interface>
      <state_interface name="velocity"/>
      <state_interface name="effort"/>
    </joint>
  </ros2_control>
  <!-- IMU -->
  <!-- <xacro:dummy-link name="pelvis_imu_frame" />
        <xacro:robot-joint joint_name="pelvis_imu"
            joint_type="fixed"
            parent="${connected_to}"
            child="pelvis_imu_frame"
            joint_limits="${joint_limits}"
            kinematics="${kinematics}"
            inertials="${inertials}"
            dynamics="${dynamics}" /> -->
  <link name="head_camera_color_optical_frame"/>
  <joint name="head_camera_color_optical_fixed_joint" type="fixed">
    <parent link="waist2_p_link"/>
    <child link="head_camera_color_optical_frame"/>
    <origin rpy="-2.3612687 -0.0018548 -1.5289507" xyz="0.051305717762167 0.03078826748102767 0.5296785230036899"/>
    <axis xyz="0 0 1"/>
  </joint>
  <link name="right_wrist_camera_color_optical_frame"/>
  <joint name="right_wrist_camera_color_optical_fixed_joint" type="fixed">
    <parent link="r_arm7_wrist_p_link"/>
    <child link="right_wrist_camera_color_optical_frame"/>
    <origin rpy="-3.0969094 -0.0446179 -2.6514574" xyz="-0.018756415998556566 0.06589653803939702 -0.059254465754087916"/>
    <axis xyz="0 0 1"/>
  </joint>
  <!-- <xacro:dummy-link name="middle_camera_link" />
        <xacro:robot-joint joint_name="middle_camera_link_fixed_joint"
            joint_type="fixed"
            parent="base_link"
            child="middle_camera_link"
            joint_limits="${joint_limits}"
            kinematics="${kinematics}"
            inertials="${inertials}"
            dynamics="${dynamics}" /> -->
  <ros2_control name="sensors_system" type="system">
    <hardware>
      <plugin>ign_ros2_control/IgnitionSystem</plugin>
    </hardware>
    <joint name="pelvis_imu"/>
    <sensor name="pelvis_imu">
      <state_interface name="orientation.x"/>
      <state_interface name="orientation.y"/>
      <state_interface name="orientation.z"/>
      <state_interface name="orientation.w"/>
      <state_interface name="angular_velocity.x"/>
      <state_interface name="angular_velocity.y"/>
      <state_interface name="angular_velocity.z"/>
      <state_interface name="linear_acceleration.x"/>
      <state_interface name="linear_acceleration.y"/>
      <state_interface name="linear_acceleration.z"/>
      <param name="frame_id">pelvis_imu_frame</param>
      <param name="gyro_sensor">pelvis_imu_gyro</param>
      <param name="accelerometer_sensor">pelvis_imu_accelerometer</param>
      <param name="quaternion_sensor">pelvis_imu_quaternion</param>
      <param name="sensor_type">imu</param>
    </sensor>
  </ros2_control>
  <gazebo>
    <plugin filename="ign_ros2_control-system" name="ign_ros2_control::IgnitionROS2ControlPlugin">
      <parameters>/home/neal/ws_humble/install/human_description/share/human_description/config/M92C/ros2_controllers.yaml</parameters>
    </plugin>
    <self_collide>false</self_collide>
  </gazebo>
</robot>
