<?xml version="1.0" ?>
<!-- =================================================================================== -->
<!-- |    This document was autogenerated by xacro from /home/neal/ws_humble/src/human_description/robots/GR1T2/GR1T2.urdf.xacro | -->
<!-- |    EDITING THIS FILE BY HAND IS NOT RECOMMENDED                                 | -->
<!-- =================================================================================== -->
<robot name="GR1T2">
  <!-- <link name="base_footprint">
            </link>
  <joint name="base_footprint_fixed_joint" type="fixed">
    <parent link="base_footprint"/>
    <child link="base_link"/>
    <origin rpy="0 0 0" xyz="0 0 0.95"/>
  </joint> -->
  <link name="base_link">
    <visual name="base_link_vis">
      <geometry>
        <mesh filename="package://human_description/meshes/GR1T2/visual/base_link.STL"/>
      </geometry>
      <material name="steel">
        <color rgba="0.7 0.65 0.55 1"/>
      </material>
    </visual>
    <collision name="base_link_col">
      <geometry>
        <mesh filename="package://human_description/meshes/GR1T2/collision/base_link.STL"/>
      </geometry>
    </collision>
    <inertial>
      <origin rpy="0 0 0" xyz="-0.06032 -9.9E-5 -0.008574"/>
      <mass value="3.96"/>
      <inertia ixx="0.04109" ixy="-6E-6" ixz="-0.001996" iyy="0.01336" iyz="-9E-6" izz="0.04269"/>
    </inertial>
  </link>
  <link name="waist_yaw_link">
    <visual name="waist_yaw_link_vis">
      <geometry>
        <mesh filename="package://human_description/meshes/GR1T2/visual/waist_yaw_link.STL"/>
      </geometry>
      <material name="metal">
        <color rgba="0.85 0.85 0.85 1"/>
      </material>
    </visual>
    <collision name="waist_yaw_link_col">
      <geometry>
        <mesh filename="package://human_description/meshes/GR1T2/collision/waist_yaw_link.STL"/>
      </geometry>
    </collision>
    <inertial>
      <origin rpy="0 0 0" xyz="-0.00152 -0.00691 0.05223"/>
      <mass value="1.66"/>
      <inertia ixx="0.003573" ixy="1.476E-05" ixz="5.805E-05" iyy="0.0031429" iyz="0.00039781" izz="0.0023119"/>
    </inertial>
  </link>
  <joint name="waist_yaw_joint" type="revolute">
    <parent link="base_link"/>
    <child link="waist_yaw_link"/>
    <origin rpy="0 0 0" xyz="0 0 0"/>
    <axis xyz="0 0 1"/>
    <limit effort="66.0" lower="-1.0471975511965976" upper="1.0471975511965976" velocity="16.76"/>
    <safety_controller k_position="121.0" k_velocity="540.0" soft_lower_limit="-0.9948376736367678" soft_upper_limit="0.9948376736367678"/>
    <dynamics damping="0.003" friction="0.2"/>
  </joint>
  <link name="waist_pitch_link">
    <visual name="waist_pitch_link_vis">
      <geometry>
        <mesh filename="package://human_description/meshes/GR1T2/visual/waist_pitch_link.STL"/>
      </geometry>
      <material name="metal">
        <color rgba="0.85 0.85 0.85 1"/>
      </material>
    </visual>
    <collision name="waist_pitch_link_col">
      <geometry>
        <mesh filename="package://human_description/meshes/GR1T2/collision/waist_pitch_link.STL"/>
      </geometry>
    </collision>
    <inertial>
      <origin rpy="0 0 0" xyz="0.004581 -0.004697 0.04034"/>
      <mass value="1.54"/>
      <inertia ixx="0.0046064" ixy="-2.297E-05" ixz="-0.00026084" iyy="0.0045722" iyz="-0.00024591" izz="0.0018747"/>
    </inertial>
  </link>
  <joint name="waist_pitch_joint" type="revolute">
    <parent link="waist_yaw_link"/>
    <child link="waist_pitch_link"/>
    <origin rpy="0 0 0" xyz="0 0 0.0869"/>
    <axis xyz="0 1 0"/>
    <limit effort="66.0" lower="-0.5235987755982988" upper="1.2217304763960306" velocity="16.76"/>
    <safety_controller k_position="121.0" k_velocity="540.0" soft_lower_limit="-0.47123889803846897" soft_upper_limit="1.1693705988362006"/>
    <dynamics damping="0.003" friction="0.2"/>
  </joint>
  <link name="waist_roll_link">
    <visual name="waist_roll_link_vis">
      <geometry>
        <mesh filename="package://human_description/meshes/GR1T2/visual/waist_roll_link.STL"/>
      </geometry>
      <material name="metal">
        <color rgba="0.85 0.85 0.85 1"/>
      </material>
    </visual>
    <collision name="waist_roll_link_col">
      <geometry>
        <mesh filename="package://human_description/meshes/GR1T2/collision/waist_roll_link.STL"/>
      </geometry>
    </collision>
    <inertial>
      <origin rpy="0 0 0" xyz="0.00823 0.00004 0.01227"/>
      <mass value="0.96"/>
      <inertia ixx="0.00100959" ixy="4.9E-7" ixz="9.99E-5" iyy="1.30981E-3" iyz="-5.3E-7" izz="1.16922E-3"/>
    </inertial>
  </link>
  <joint name="waist_roll_joint" type="revolute">
    <parent link="waist_pitch_link"/>
    <child link="waist_roll_link"/>
    <origin rpy="0 0 0" xyz="0.00525 -0.0005 0.081"/>
    <axis xyz="1 0 0"/>
    <limit effort="66.0" lower="-0.6981317007977318" upper="0.6981317007977318" velocity="16.76"/>
    <safety_controller k_position="121.0" k_velocity="540.0" soft_lower_limit="-0.6457718232379019" soft_upper_limit="0.6457718232379019"/>
    <dynamics damping="0.003" friction="0.2"/>
  </joint>
  <link name="torso_link">
    <visual name="torso_link_vis">
      <geometry>
        <mesh filename="package://human_description/meshes/GR1T2/visual/torso_link.STL"/>
      </geometry>
      <material name="metal">
        <color rgba="0.85 0.85 0.85 1"/>
      </material>
    </visual>
    <collision name="torso_link_col">
      <geometry>
        <mesh filename="package://human_description/meshes/GR1T2/collision/torso_link.STL"/>
      </geometry>
    </collision>
    <inertial>
      <origin rpy="0 0 0" xyz="-0.01325 0.000292 0.009517"/>
      <mass value="5.67"/>
      <inertia ixx="0.04082" ixy="-2e-6" ixz="-0.00047" iyy="0.03729" iyz="-1.4e-5" izz="0.03397"/>
    </inertial>
  </link>
  <joint name="torso_fixed_joint" type="fixed">
    <parent link="waist_roll_link"/>
    <child link="torso_link"/>
    <origin rpy="0 0 0" xyz="-0.00225 0.00057443 0.16035"/>
    <axis xyz="0 0 1"/>
  </joint>
  <ros2_control name="waist_system" type="system">
    <hardware>
      <plugin>mujoco_ros2_control/MujocoSystem</plugin>
    </hardware>
    <joint name="waist_roll_joint">
      <param name="initial_position">0.0</param>
      <command_interface name="position"/>
      <state_interface name="position">
        <param name="initial_value">0.0</param>
      </state_interface>
      <state_interface name="velocity"/>
      <state_interface name="effort"/>
    </joint>
    <transmission name="waist_roll_transmission">
      <plugin>transmission_interface/SimpleTransmission</plugin>
      <joint name="waist_roll_joint" role="joint1">
        <mechanical_reduction>1.0</mechanical_reduction>
        <offset>0</offset>
      </joint>
      <actuator name="waist_roll_actuator" role="actuator1">
        <mechanical_reduction>1.0</mechanical_reduction>
        <offset>0</offset>
      </actuator>
    </transmission>
    <joint name="waist_yaw_joint">
      <param name="initial_position">0.0</param>
      <command_interface name="position"/>
      <state_interface name="position">
        <param name="initial_value">0.0</param>
      </state_interface>
      <state_interface name="velocity"/>
      <state_interface name="effort"/>
    </joint>
    <transmission name="waist_yaw_transmission">
      <plugin>transmission_interface/SimpleTransmission</plugin>
      <joint name="waist_yaw_joint" role="joint1">
        <mechanical_reduction>1.0</mechanical_reduction>
        <offset>0</offset>
      </joint>
      <actuator name="waist_yaw_actuator" role="actuator1">
        <mechanical_reduction>1.0</mechanical_reduction>
        <offset>0</offset>
      </actuator>
    </transmission>
    <joint name="waist_pitch_joint">
      <param name="initial_position">0.656</param>
      <command_interface name="position"/>
      <state_interface name="position">
        <param name="initial_value">0.656</param>
      </state_interface>
      <state_interface name="velocity"/>
      <state_interface name="effort"/>
    </joint>
    <transmission name="waist_pitch_transmission">
      <plugin>transmission_interface/SimpleTransmission</plugin>
      <joint name="waist_pitch_joint" role="joint1">
        <mechanical_reduction>1.0</mechanical_reduction>
        <offset>0</offset>
      </joint>
      <actuator name="waist_pitch_actuator" role="actuator1">
        <mechanical_reduction>1.0</mechanical_reduction>
        <offset>0</offset>
      </actuator>
    </transmission>
  </ros2_control>
  <link name="neck_roll_link">
    <visual name="neck_roll_link_vis">
      <geometry>
        <mesh filename="package://human_description/meshes/GR1T2/visual/neck_roll_link.STL"/>
      </geometry>
      <material name="metal">
        <color rgba="0.85 0.85 0.85 1"/>
      </material>
    </visual>
    <collision name="neck_roll_link_col">
      <geometry>
        <mesh filename="package://human_description/meshes/GR1T2/collision/neck_roll_link.STL"/>
      </geometry>
    </collision>
    <inertial>
      <origin rpy="0 0 0" xyz="0.00425 0 0"/>
      <mass value="0.01"/>
      <inertia ixx="4.3E-7" ixy="0" ixz="0" iyy="4.4E-7" iyz="0" izz="7.2E-7"/>
    </inertial>
  </link>
  <joint name="neck_roll_joint" type="revolute">
    <parent link="torso_link"/>
    <child link="neck_roll_link"/>
    <origin rpy="0 0 0" xyz="0.002 0.0005184 0.14465"/>
    <axis xyz="1 0 0"/>
    <limit effort="3.95" lower="-0.3490658503988659" upper="0.3490658503988659" velocity="27.96"/>
    <safety_controller k_position="121.0" k_velocity="540.0" soft_lower_limit="-0.29670597283903605" soft_upper_limit="0.29670597283903605"/>
    <dynamics damping="0.003" friction="0.2"/>
  </joint>
  <link name="neck_pitch_link">
    <visual name="neck_pitch_link_vis">
      <geometry>
        <mesh filename="package://human_description/meshes/GR1T2/visual/neck_pitch_link.STL"/>
      </geometry>
      <material name="metal">
        <color rgba="0.85 0.85 0.85 1"/>
      </material>
    </visual>
    <collision name="neck_pitch_link_col">
      <geometry>
        <mesh filename="package://human_description/meshes/GR1T2/collision/neck_pitch_link.STL"/>
      </geometry>
    </collision>
    <inertial>
      <origin rpy="0 0 0" xyz="-0.0021765 -4.1784E-07 0.017509"/>
      <mass value="0.06"/>
      <inertia ixx="2.509E-05" ixy="0" ixz="-1.3E-06" iyy="1.707E-05" iyz="0" izz="2.462E-05"/>
    </inertial>
  </link>
  <joint name="neck_pitch_joint" type="revolute">
    <parent link="neck_roll_link"/>
    <child link="neck_pitch_link"/>
    <origin rpy="0 0 0" xyz="0 0 0"/>
    <axis xyz="0 1 0"/>
    <limit effort="3.95" lower="-0.8726646259971648" upper="0.8726646259971648" velocity="27.96"/>
    <safety_controller k_position="121.0" k_velocity="540.0" soft_lower_limit="-0.8203047484373349" soft_upper_limit="0.8203047484373349"/>
    <dynamics damping="0.003" friction="0.2"/>
  </joint>
  <link name="neck_yaw_link">
    <visual name="neck_yaw_link_vis">
      <geometry>
        <mesh filename="package://human_description/meshes/GR1T2/visual/neck_yaw_link.STL"/>
      </geometry>
      <material name="metal">
        <color rgba="0.85 0.85 0.85 1"/>
      </material>
    </visual>
    <collision name="neck_yaw_link_col">
      <geometry>
        <mesh filename="package://human_description/meshes/GR1T2/collision/neck_yaw_link.STL"/>
      </geometry>
    </collision>
    <inertial>
      <origin rpy="0 0 0" xyz="0.02710 -0.00206 0.09577"/>
      <mass value="1.58"/>
      <inertia ixx="7.54439E-3" ixy="7.210E-5" ixz="9.5183E-4" iyy="0.01013433" iyz="5.051E-5" izz="5.65975E-3"/>
    </inertial>
  </link>
  <joint name="neck_yaw_joint" type="revolute">
    <parent link="neck_pitch_link"/>
    <child link="neck_yaw_link"/>
    <origin rpy="0 0 0" xyz="0 0 0.0513"/>
    <axis xyz="0 0 1"/>
    <limit effort="3.95" lower="-2.705260340591211" upper="2.705260340591211" velocity="27.96"/>
    <safety_controller k_position="121.0" k_velocity="540.0" soft_lower_limit="-2.6529004630313806" soft_upper_limit="2.6529004630313806"/>
    <dynamics damping="0.003" friction="0.2"/>
  </joint>
  <ros2_control name="head_system" type="system">
    <hardware>
      <plugin>mujoco_ros2_control/MujocoSystem</plugin>
    </hardware>
    <joint name="neck_yaw_joint">
      <param name="initial_position">0.0</param>
      <command_interface name="position"/>
      <state_interface name="position">
        <param name="initial_value">0.0</param>
      </state_interface>
      <state_interface name="velocity"/>
      <state_interface name="effort"/>
    </joint>
    <transmission name="neck_yaw_transmission">
      <plugin>transmission_interface/SimpleTransmission</plugin>
      <joint name="neck_yaw_joint" role="joint1">
        <mechanical_reduction>1.0</mechanical_reduction>
        <offset>0</offset>
      </joint>
      <actuator name="neck_yaw_actuator" role="actuator1">
        <mechanical_reduction>1.0</mechanical_reduction>
        <offset>0</offset>
      </actuator>
    </transmission>
    <joint name="neck_pitch_joint">
      <param name="initial_position">0.343</param>
      <command_interface name="position"/>
      <state_interface name="position">
        <param name="initial_value">0.343</param>
      </state_interface>
      <state_interface name="velocity"/>
      <state_interface name="effort"/>
    </joint>
    <transmission name="neck_pitch_transmission">
      <plugin>transmission_interface/SimpleTransmission</plugin>
      <joint name="neck_pitch_joint" role="joint1">
        <mechanical_reduction>1.0</mechanical_reduction>
        <offset>0</offset>
      </joint>
      <actuator name="neck_pitch_actuator" role="actuator1">
        <mechanical_reduction>1.0</mechanical_reduction>
        <offset>0</offset>
      </actuator>
    </transmission>
    <joint name="neck_roll_joint">
      <param name="initial_position">0.0</param>
      <command_interface name="position"/>
      <state_interface name="position">
        <param name="initial_value">0.0</param>
      </state_interface>
      <state_interface name="velocity"/>
      <state_interface name="effort"/>
    </joint>
    <transmission name="neck_roll_transmission">
      <plugin>transmission_interface/SimpleTransmission</plugin>
      <joint name="neck_roll_joint" role="joint1">
        <mechanical_reduction>1.0</mechanical_reduction>
        <offset>0</offset>
      </joint>
      <actuator name="neck_roll_actuator" role="actuator1">
        <mechanical_reduction>1.0</mechanical_reduction>
        <offset>0</offset>
      </actuator>
    </transmission>
  </ros2_control>
  <link name="l_shoulder_pitch_link">
    <visual name="l_shoulder_pitch_link_vis">
      <geometry>
        <mesh filename="package://human_description/meshes/GR1T2/visual/l_shoulder_pitch_link.STL"/>
      </geometry>
      <material name="metal">
        <color rgba="0.85 0.85 0.85 1"/>
      </material>
    </visual>
    <collision name="l_shoulder_pitch_link_col">
      <geometry>
        <mesh filename="package://human_description/meshes/GR1T2/collision/l_shoulder_pitch_link.STL"/>
      </geometry>
    </collision>
    <inertial>
      <origin rpy="0 0 0" xyz="0.0033 0.05361 -0.00011"/>
      <mass value="0.82"/>
      <inertia ixx="2.04209E-3" ixy="-1.0845E-4" ixz="-5.7E-6" iyy="5.02E-4" iyz="-2.88E-6" izz="1.98176E-3"/>
    </inertial>
  </link>
  <joint name="l_shoulder_pitch_joint" type="revolute">
    <parent link="torso_link"/>
    <child link="l_shoulder_pitch_link"/>
    <origin rpy="0.43275 0 0" xyz="0 0.10128 0.046651"/>
    <axis xyz="0 1 0"/>
    <limit effort="38" lower="-2.792526803190927" upper="1.9198621771937625" velocity="9.11"/>
    <safety_controller k_position="121.0" k_velocity="540.0" soft_lower_limit="-2.740166925631097" soft_upper_limit="1.8675022996339325"/>
    <dynamics damping="0.003" friction="0.2"/>
  </joint>
  <link name="l_shoulder_roll_link">
    <visual name="l_shoulder_roll_link_vis">
      <geometry>
        <mesh filename="package://human_description/meshes/GR1T2/visual/l_shoulder_roll_link.STL"/>
      </geometry>
      <material name="metal">
        <color rgba="0.85 0.85 0.85 1"/>
      </material>
    </visual>
    <collision name="l_shoulder_roll_link_col">
      <geometry>
        <mesh filename="package://human_description/meshes/GR1T2/collision/l_shoulder_roll_link.STL"/>
      </geometry>
    </collision>
    <inertial>
      <origin rpy="0 0 0" xyz="0.005026 0.01740 -0.02398"/>
      <mass value="0.61"/>
      <inertia ixx="0.0010175" ixy="8.5E-07" ixz="-2.686E-05" iyy="0.00080346" iyz="0.00031013" izz="0.00056524"/>
    </inertial>
  </link>
  <joint name="l_shoulder_roll_joint" type="revolute">
    <parent link="l_shoulder_pitch_link"/>
    <child link="l_shoulder_roll_link"/>
    <origin rpy="-0.43275 0 0" xyz="0 0.0951 0"/>
    <axis xyz="1 0 0"/>
    <limit effort="38" lower="-0.5759586531581288" upper="3.2637657012293966" velocity="9.11"/>
    <safety_controller k_position="121.0" k_velocity="540.0" soft_lower_limit="-0.5235987755982988" soft_upper_limit="3.211405823669566"/>
    <dynamics damping="0.003" friction="0.2"/>
  </joint>
  <link name="l_elbow_yaw_link">
    <visual name="l_elbow_yaw_link_vis">
      <geometry>
        <mesh filename="package://human_description/meshes/GR1T2/visual/l_elbow_yaw_link.STL"/>
      </geometry>
      <material name="metal">
        <color rgba="0.85 0.85 0.85 1"/>
      </material>
    </visual>
    <collision name="l_elbow_yaw_link_col">
      <geometry>
        <mesh filename="package://human_description/meshes/GR1T2/collision/l_elbow_yaw_link.STL"/>
      </geometry>
    </collision>
    <inertial>
      <origin rpy="0 0 0" xyz="-1.7E-5 -0.0002 -0.08761"/>
      <mass value="0.54"/>
      <inertia ixx="0.0035571" ixy="-1.6E-07" ixz="-7.1E-07" iyy="0.003544" iyz="4.560E-05" izz="0.00026034"/>
    </inertial>
  </link>
  <joint name="l_elbow_yaw_joint" type="revolute">
    <parent link="l_shoulder_roll_link"/>
    <child link="l_elbow_yaw_link"/>
    <origin rpy="0 0 0" xyz="0 0.04 -0.0709"/>
    <axis xyz="0 0 1"/>
    <limit effort="30" lower="-2.9670597283903604" upper="2.9670597283903604" velocity="7.33"/>
    <safety_controller k_position="121.0" k_velocity="540.0" soft_lower_limit="-2.9146998508305306" soft_upper_limit="2.9146998508305306"/>
    <dynamics damping="0.003" friction="0.2"/>
  </joint>
  <link name="l_elbow_pitch_link">
    <visual name="l_elbow_pitch_link_vis">
      <geometry>
        <mesh filename="package://human_description/meshes/GR1T2/visual/l_elbow_pitch_link.STL"/>
      </geometry>
      <material name="metal">
        <color rgba="0.85 0.85 0.85 1"/>
      </material>
    </visual>
    <collision name="l_elbow_pitch_link_col">
      <geometry>
        <mesh filename="package://human_description/meshes/GR1T2/collision/l_elbow_pitch_link.STL"/>
      </geometry>
    </collision>
    <inertial>
      <origin rpy="0 0 0" xyz="0 0.008102 -0.02528"/>
      <mass value="0.33"/>
      <inertia ixx="0.00029558" ixy="2E-08" ixz="7E-08" iyy="0.000287" iyz="-5.014E-05" izz="0.00011171"/>
    </inertial>
  </link>
  <joint name="l_elbow_pitch_joint" type="revolute">
    <parent link="l_elbow_yaw_link"/>
    <child link="l_elbow_pitch_link"/>
    <origin rpy="0 0 0" xyz="0 0.0010503 -0.1786"/>
    <axis xyz="0 1 0"/>
    <limit effort="30" lower="-2.2689280275926285" upper="2.2689280275926285" velocity="7.33"/>
    <safety_controller k_position="121.0" k_velocity="540.0" soft_lower_limit="-2.2165681500327987" soft_upper_limit="2.2165681500327987"/>
    <dynamics damping="0.003" friction="0.2"/>
  </joint>
  <link name="l_wrist_yaw_link">
    <visual name="l_wrist_yaw_link_vis">
      <geometry>
        <mesh filename="package://human_description/meshes/GR1T2/visual/l_wrist_yaw_link.STL"/>
      </geometry>
      <material name="metal">
        <color rgba="0.85 0.85 0.85 1"/>
      </material>
    </visual>
    <collision name="l_wrist_yaw_link_col">
      <geometry>
        <mesh filename="package://human_description/meshes/GR1T2/collision/l_wrist_yaw_link.STL"/>
      </geometry>
    </collision>
    <inertial>
      <origin rpy="0 0 0" xyz="0.00044 0.00196 -0.07313"/>
      <mass value="0.99"/>
      <inertia ixx="0.0026215" ixy="1.29E-06" ixz="6.12E-06" iyy="0.0025491" iyz="-1.585E-05" izz="0.00049784"/>
    </inertial>
  </link>
  <joint name="l_wrist_yaw_joint" type="revolute">
    <parent link="l_elbow_pitch_link"/>
    <child link="l_wrist_yaw_link"/>
    <origin rpy="0 0 0" xyz="0 0 -0.05945"/>
    <axis xyz="0 0 1"/>
    <limit effort="10.2" lower="-2.9670597283903604" upper="2.9670597283903604" velocity="24.4"/>
    <safety_controller k_position="121.0" k_velocity="540.0" soft_lower_limit="-2.9146998508305306" soft_upper_limit="2.9146998508305306"/>
    <dynamics damping="0.003" friction="0.2"/>
  </joint>
  <link name="l_wrist_roll_link">
    <visual name="l_wrist_roll_link_vis">
      <geometry>
        <mesh filename="package://human_description/meshes/GR1T2/visual/l_wrist_roll_link.STL"/>
      </geometry>
      <material name="metal">
        <color rgba="0.85 0.85 0.85 1"/>
      </material>
    </visual>
    <collision name="l_wrist_roll_link_col">
      <geometry>
        <mesh filename="package://human_description/meshes/GR1T2/collision/l_wrist_roll_link.STL"/>
      </geometry>
    </collision>
    <inertial>
      <origin rpy="0 0 0" xyz="0 0.005104 -0.008485"/>
      <mass value="0.055"/>
      <inertia ixx="1.1E-5" ixy="0" ixz="0" iyy="2E-5" iyz="-1E-6" izz="2.1E-5"/>
    </inertial>
  </link>
  <joint name="l_wrist_roll_joint" type="revolute">
    <parent link="l_wrist_yaw_link"/>
    <child link="l_wrist_roll_link"/>
    <origin rpy="0 0 0" xyz="0 0 -0.19115"/>
    <axis xyz="1 0 0"/>
    <limit effort="3.95" lower="-0.6108652381980153" upper="0.6108652381980153" velocity="27.96"/>
    <safety_controller k_position="121.0" k_velocity="540.0" soft_lower_limit="-0.5585053606381855" soft_upper_limit="0.5585053606381855"/>
    <dynamics damping="0.003" friction="0.2"/>
  </joint>
  <link name="l_wrist_pitch_link">
    <visual name="l_wrist_pitch_link_vis">
      <geometry>
        <mesh filename="package://human_description/meshes/GR1T2/visual/l_wrist_pitch_link.STL"/>
      </geometry>
      <material name="metal">
        <color rgba="0.85 0.85 0.85 1"/>
      </material>
    </visual>
    <collision name="l_wrist_pitch_link_col">
      <geometry>
        <mesh filename="package://human_description/meshes/GR1T2/collision/l_wrist_pitch_link.STL"/>
      </geometry>
    </collision>
    <inertial>
      <origin rpy="0 0 0" xyz="0 0.005104 -0.008485"/>
      <mass value="0.055"/>
      <inertia ixx="1.1E-5" ixy="0" ixz="0" iyy="2E-5" iyz="-1E-6" izz="2.1E-5"/>
    </inertial>
  </link>
  <joint name="l_wrist_pitch_joint" type="revolute">
    <parent link="l_wrist_roll_link"/>
    <child link="l_wrist_pitch_link"/>
    <origin rpy="0 0 0" xyz="0 0 0"/>
    <axis xyz="0 1 0"/>
    <limit effort="3.95" lower="-0.9599310885968813" upper="0.8726646259971648" velocity="27.96"/>
    <safety_controller k_position="121.0" k_velocity="540.0" soft_lower_limit="-0.9075712110370514" soft_upper_limit="0.8203047484373349"/>
    <dynamics damping="0.003" friction="0.2"/>
  </joint>
  <link name="l_end_effector_link">
    <inertial>
      <origin rpy="0. 0. 0." xyz="0. 0. 0."/>
      <mass value="1e-05"/>
      <inertia ixx="3.333333333333333e-12" ixy="0" ixz="0" iyy="3.333333333333333e-12" iyz="0" izz="5.0000000000000005e-12"/>
    </inertial>
  </link>
  <joint name="l_end_effector_fixed_joint" type="fixed">
    <parent link="l_wrist_pitch_link"/>
    <child link="l_end_effector_link"/>
    <origin rpy="0 0 0" xyz="0 0 0"/>
    <axis xyz="0 0 1"/>
  </joint>
  <ros2_control name="l_arm_system" type="system">
    <hardware>
      <plugin>mujoco_ros2_control/MujocoSystem</plugin>
    </hardware>
    <joint name="l_shoulder_pitch_joint">
      <param name="initial_position">-0.211</param>
      <command_interface name="position"/>
      <state_interface name="position">
        <param name="initial_value">-0.211</param>
      </state_interface>
      <state_interface name="velocity"/>
      <state_interface name="effort"/>
    </joint>
    <transmission name="l_shoulder_pitch_transmission">
      <plugin>transmission_interface/SimpleTransmission</plugin>
      <joint name="l_shoulder_pitch_joint" role="joint1">
        <mechanical_reduction>1.0</mechanical_reduction>
        <offset>0</offset>
      </joint>
      <actuator name="l_shoulder_pitch_actuator" role="actuator1">
        <mechanical_reduction>1.0</mechanical_reduction>
        <offset>0</offset>
      </actuator>
    </transmission>
    <joint name="l_shoulder_roll_joint">
      <param name="initial_position">0.0</param>
      <command_interface name="position"/>
      <state_interface name="position">
        <param name="initial_value">0.0</param>
      </state_interface>
      <state_interface name="velocity"/>
      <state_interface name="effort"/>
    </joint>
    <transmission name="l_shoulder_roll_transmission">
      <plugin>transmission_interface/SimpleTransmission</plugin>
      <joint name="l_shoulder_roll_joint" role="joint1">
        <mechanical_reduction>1.0</mechanical_reduction>
        <offset>0</offset>
      </joint>
      <actuator name="l_shoulder_roll_actuator" role="actuator1">
        <mechanical_reduction>1.0</mechanical_reduction>
        <offset>0</offset>
      </actuator>
    </transmission>
    <joint name="l_elbow_yaw_joint">
      <param name="initial_position">0.0</param>
      <command_interface name="position"/>
      <state_interface name="position">
        <param name="initial_value">0.0</param>
      </state_interface>
      <state_interface name="velocity"/>
      <state_interface name="effort"/>
    </joint>
    <transmission name="l_elbow_yaw_transmission">
      <plugin>transmission_interface/SimpleTransmission</plugin>
      <joint name="l_elbow_yaw_joint" role="joint1">
        <mechanical_reduction>1.0</mechanical_reduction>
        <offset>0</offset>
      </joint>
      <actuator name="l_elbow_yaw_actuator" role="actuator1">
        <mechanical_reduction>1.0</mechanical_reduction>
        <offset>0</offset>
      </actuator>
    </transmission>
    <joint name="l_elbow_pitch_joint">
      <param name="initial_position">0.0</param>
      <command_interface name="position"/>
      <state_interface name="position">
        <param name="initial_value">0.0</param>
      </state_interface>
      <state_interface name="velocity"/>
      <state_interface name="effort"/>
    </joint>
    <transmission name="l_elbow_pitch_transmission">
      <plugin>transmission_interface/SimpleTransmission</plugin>
      <joint name="l_elbow_pitch_joint" role="joint1">
        <mechanical_reduction>1.0</mechanical_reduction>
        <offset>0</offset>
      </joint>
      <actuator name="l_elbow_pitch_actuator" role="actuator1">
        <mechanical_reduction>1.0</mechanical_reduction>
        <offset>0</offset>
      </actuator>
    </transmission>
    <joint name="l_wrist_yaw_joint">
      <param name="initial_position">0.0</param>
      <command_interface name="position"/>
      <state_interface name="position">
        <param name="initial_value">0.0</param>
      </state_interface>
      <state_interface name="velocity"/>
      <state_interface name="effort"/>
    </joint>
    <transmission name="l_wrist_yaw_transmission">
      <plugin>transmission_interface/SimpleTransmission</plugin>
      <joint name="l_wrist_yaw_joint" role="joint1">
        <mechanical_reduction>1.0</mechanical_reduction>
        <offset>0</offset>
      </joint>
      <actuator name="l_wrist_yaw_actuator" role="actuator1">
        <mechanical_reduction>1.0</mechanical_reduction>
        <offset>0</offset>
      </actuator>
    </transmission>
    <joint name="l_wrist_pitch_joint">
      <param name="initial_position">0.0</param>
      <command_interface name="position"/>
      <state_interface name="position">
        <param name="initial_value">0.0</param>
      </state_interface>
      <state_interface name="velocity"/>
      <state_interface name="effort"/>
    </joint>
    <transmission name="l_wrist_pitch_transmission">
      <plugin>transmission_interface/SimpleTransmission</plugin>
      <joint name="l_wrist_pitch_joint" role="joint1">
        <mechanical_reduction>1.0</mechanical_reduction>
        <offset>0</offset>
      </joint>
      <actuator name="l_wrist_pitch_actuator" role="actuator1">
        <mechanical_reduction>1.0</mechanical_reduction>
        <offset>0</offset>
      </actuator>
    </transmission>
    <joint name="l_wrist_roll_joint">
      <param name="initial_position">0.0</param>
      <command_interface name="position"/>
      <state_interface name="position">
        <param name="initial_value">0.0</param>
      </state_interface>
      <state_interface name="velocity"/>
      <state_interface name="effort"/>
    </joint>
    <transmission name="l_wrist_roll_transmission">
      <plugin>transmission_interface/SimpleTransmission</plugin>
      <joint name="l_wrist_roll_joint" role="joint1">
        <mechanical_reduction>1.0</mechanical_reduction>
        <offset>0</offset>
      </joint>
      <actuator name="l_wrist_roll_actuator" role="actuator1">
        <mechanical_reduction>1.0</mechanical_reduction>
        <offset>0</offset>
      </actuator>
    </transmission>
  </ros2_control>
  <link name="r_shoulder_pitch_link">
    <visual name="r_shoulder_pitch_link_vis">
      <geometry>
        <mesh filename="package://human_description/meshes/GR1T2/visual/r_shoulder_pitch_link.STL"/>
      </geometry>
      <material name="metal">
        <color rgba="0.85 0.85 0.85 1"/>
      </material>
    </visual>
    <collision name="r_shoulder_pitch_link_col">
      <geometry>
        <mesh filename="package://human_description/meshes/GR1T2/collision/r_shoulder_pitch_link.STL"/>
      </geometry>
    </collision>
    <inertial>
      <origin rpy="0 0 0" xyz="0.00338 -0.05364 0.00021"/>
      <mass value="0.82"/>
      <inertia ixx="0.0020452" ixy="0.00011066" ixz="-3.5E-07" iyy="0.00050607" iyz="-3.27E-06" izz="0.0019775"/>
    </inertial>
  </link>
  <joint name="r_shoulder_pitch_joint" type="revolute">
    <parent link="torso_link"/>
    <child link="r_shoulder_pitch_link"/>
    <origin rpy="-0.43275 0 0" xyz="0 -0.10128 0.046651"/>
    <axis xyz="0 1 0"/>
    <limit effort="38" lower="-2.792526803190927" upper="1.9198621771937625" velocity="9.11"/>
    <safety_controller k_position="121.0" k_velocity="540.0" soft_lower_limit="-2.740166925631097" soft_upper_limit="1.8675022996339325"/>
    <dynamics damping="0.003" friction="0.2"/>
  </joint>
  <link name="r_shoulder_roll_link">
    <visual name="r_shoulder_roll_link_vis">
      <geometry>
        <mesh filename="package://human_description/meshes/GR1T2/visual/r_shoulder_roll_link.STL"/>
      </geometry>
      <material name="metal">
        <color rgba="0.85 0.85 0.85 1"/>
      </material>
    </visual>
    <collision name="r_shoulder_roll_link_col">
      <geometry>
        <mesh filename="package://human_description/meshes/GR1T2/collision/r_shoulder_roll_link.STL"/>
      </geometry>
    </collision>
    <inertial>
      <origin rpy="0 0 0" xyz="0.004503 -0.0174 -0.02398"/>
      <mass value="0.61"/>
      <inertia ixx="0.0010174" ixy="-8.4E-07" ixz="-2.687E-05" iyy="0.0008033" iyz="-0.00031043" izz="0.00056542"/>
    </inertial>
  </link>
  <joint name="r_shoulder_roll_joint" type="revolute">
    <parent link="r_shoulder_pitch_link"/>
    <child link="r_shoulder_roll_link"/>
    <origin rpy="0.43275 0 0" xyz="0 -0.09515 0"/>
    <axis xyz="1 0 0"/>
    <limit effort="38" lower="-3.2637657012293966" upper="0.5759586531581288" velocity="9.11"/>
    <safety_controller k_position="121.0" k_velocity="540.0" soft_lower_limit="-3.211405823669566" soft_upper_limit="0.5235987755982988"/>
    <dynamics damping="0.003" friction="0.2"/>
  </joint>
  <link name="r_elbow_yaw_link">
    <visual name="r_elbow_yaw_link_vis">
      <geometry>
        <mesh filename="package://human_description/meshes/GR1T2/visual/r_elbow_yaw_link.STL"/>
      </geometry>
      <material name="metal">
        <color rgba="0.85 0.85 0.85 1"/>
      </material>
    </visual>
    <collision name="r_elbow_yaw_link_col">
      <geometry>
        <mesh filename="package://human_description/meshes/GR1T2/collision/r_elbow_yaw_link.STL"/>
      </geometry>
    </collision>
    <inertial>
      <origin rpy="0 0 0" xyz="-1E-5 0.0002 -0.08761"/>
      <mass value="0.54"/>
      <inertia ixx="0.0035706" ixy="3E-08" ixz="7E-08" iyy="0.0035441" iyz="-4.555E-05" izz="0.00026029"/>
    </inertial>
  </link>
  <joint name="r_elbow_yaw_joint" type="revolute">
    <parent link="r_shoulder_roll_link"/>
    <child link="r_elbow_yaw_link"/>
    <origin rpy="0 0 0" xyz="0 -0.04 -0.0709"/>
    <axis xyz="0 0 1"/>
    <limit effort="30" lower="-2.9670597283903604" upper="2.9670597283903604" velocity="7.33"/>
    <safety_controller k_position="121.0" k_velocity="540.0" soft_lower_limit="-2.9146998508305306" soft_upper_limit="2.9146998508305306"/>
    <dynamics damping="0.003" friction="0.2"/>
  </joint>
  <link name="r_elbow_pitch_link">
    <visual name="r_elbow_pitch_link_vis">
      <geometry>
        <mesh filename="package://human_description/meshes/GR1T2/visual/r_elbow_pitch_link.STL"/>
      </geometry>
      <material name="metal">
        <color rgba="0.85 0.85 0.85 1"/>
      </material>
    </visual>
    <collision name="r_elbow_pitch_link_col">
      <geometry>
        <mesh filename="package://human_description/meshes/GR1T2/collision/r_elbow_pitch_link.STL"/>
      </geometry>
    </collision>
    <inertial>
      <origin rpy="0 0 0" xyz="0 -0.008102 -0.02528"/>
      <mass value="0.33"/>
      <inertia ixx="0.00029558" ixy="2E-08" ixz="-7E-08" iyy="0.000287" iyz="5.014E-05" izz="0.000112"/>
    </inertial>
  </link>
  <joint name="r_elbow_pitch_joint" type="revolute">
    <parent link="r_elbow_yaw_link"/>
    <child link="r_elbow_pitch_link"/>
    <origin rpy="0 0 0" xyz="0 -0.0010503 -0.1786"/>
    <axis xyz="0 1 0"/>
    <limit effort="30" lower="-2.2689280275926285" upper="2.2689280275926285" velocity="7.33"/>
    <safety_controller k_position="121.0" k_velocity="540.0" soft_lower_limit="-2.2165681500327987" soft_upper_limit="2.2165681500327987"/>
    <dynamics damping="0.003" friction="0.2"/>
  </joint>
  <link name="r_wrist_yaw_link">
    <visual name="r_wrist_yaw_link_vis">
      <geometry>
        <mesh filename="package://human_description/meshes/GR1T2/visual/r_wrist_yaw_link.STL"/>
      </geometry>
      <material name="metal">
        <color rgba="0.85 0.85 0.85 1"/>
      </material>
    </visual>
    <collision name="r_wrist_yaw_link_col">
      <geometry>
        <mesh filename="package://human_description/meshes/GR1T2/collision/r_wrist_yaw_link.STL"/>
      </geometry>
    </collision>
    <inertial>
      <origin rpy="0 0 0" xyz="0.00047 -0.00196 -0.07239"/>
      <mass value="0.99"/>
      <inertia ixx="0.0025979" ixy="3.47E-06" ixz="2.86E-06" iyy="0.0025255" iyz="1.62E-05" izz="0.00049776"/>
    </inertial>
  </link>
  <joint name="r_wrist_yaw_joint" type="revolute">
    <parent link="r_elbow_pitch_link"/>
    <child link="r_wrist_yaw_link"/>
    <origin rpy="0 0 0" xyz="0 0 -0.05945"/>
    <axis xyz="0 0 1"/>
    <limit effort="10.2" lower="-2.9670597283903604" upper="2.9670597283903604" velocity="24.4"/>
    <safety_controller k_position="121.0" k_velocity="540.0" soft_lower_limit="-2.9146998508305306" soft_upper_limit="2.9146998508305306"/>
    <dynamics damping="0.003" friction="0.2"/>
  </joint>
  <link name="r_wrist_roll_link">
    <visual name="r_wrist_roll_link_vis">
      <geometry>
        <mesh filename="package://human_description/meshes/GR1T2/visual/r_wrist_roll_link.STL"/>
      </geometry>
      <material name="metal">
        <color rgba="0.85 0.85 0.85 1"/>
      </material>
    </visual>
    <collision name="r_wrist_roll_link_col">
      <geometry>
        <mesh filename="package://human_description/meshes/GR1T2/collision/r_wrist_roll_link.STL"/>
      </geometry>
    </collision>
    <inertial>
      <origin rpy="0 0 0" xyz="0 0.005104 -0.008485"/>
      <mass value="0.055"/>
      <inertia ixx="1.1E-5" ixy="0" ixz="0" iyy="2E-5" iyz="-1E-6" izz="2.1E-5"/>
    </inertial>
  </link>
  <joint name="r_wrist_roll_joint" type="revolute">
    <parent link="r_wrist_yaw_link"/>
    <child link="r_wrist_roll_link"/>
    <origin rpy="0 0 0" xyz="0 0 -0.19115"/>
    <axis xyz="1 0 0"/>
    <limit effort="3.95" lower="-0.6108652381980153" upper="0.6108652381980153" velocity="27.96"/>
    <safety_controller k_position="121.0" k_velocity="540.0" soft_lower_limit="-0.5585053606381855" soft_upper_limit="0.5585053606381855"/>
    <dynamics damping="0.003" friction="0.2"/>
  </joint>
  <link name="r_wrist_pitch_link">
    <visual name="r_wrist_pitch_link_vis">
      <geometry>
        <mesh filename="package://human_description/meshes/GR1T2/visual/r_wrist_pitch_link.STL"/>
      </geometry>
      <material name="metal">
        <color rgba="0.85 0.85 0.85 1"/>
      </material>
    </visual>
    <collision name="r_wrist_pitch_link_col">
      <geometry>
        <mesh filename="package://human_description/meshes/GR1T2/collision/r_wrist_pitch_link.STL"/>
      </geometry>
    </collision>
    <inertial>
      <origin rpy="0 0 0" xyz="0 0.005104 -0.008485"/>
      <mass value="0.055"/>
      <inertia ixx="1.1E-5" ixy="0" ixz="0" iyy="2E-5" iyz="-1E-6" izz="2.1E-5"/>
    </inertial>
  </link>
  <joint name="r_wrist_pitch_joint" type="revolute">
    <parent link="r_wrist_roll_link"/>
    <child link="r_wrist_pitch_link"/>
    <origin rpy="0 0 0" xyz="0 0 0"/>
    <axis xyz="0 1 0"/>
    <limit effort="3.95" lower="-0.9599310885968813" upper="0.8726646259971648" velocity="27.96"/>
    <safety_controller k_position="121.0" k_velocity="540.0" soft_lower_limit="-0.9075712110370514" soft_upper_limit="0.8203047484373349"/>
    <dynamics damping="0.003" friction="0.2"/>
  </joint>
  <link name="r_end_effector_link">
    <inertial>
      <origin rpy="0. 0. 0." xyz="0. 0. 0."/>
      <mass value="1e-05"/>
      <inertia ixx="3.333333333333333e-12" ixy="0" ixz="0" iyy="3.333333333333333e-12" iyz="0" izz="5.0000000000000005e-12"/>
    </inertial>
  </link>
  <joint name="r_end_effector_fixed_joint" type="fixed">
    <parent link="r_wrist_pitch_link"/>
    <child link="r_end_effector_link"/>
    <origin rpy="0 0 0" xyz="0 0 0"/>
    <axis xyz="0 0 1"/>
  </joint>
  <ros2_control name="r_arm_system" type="system">
    <hardware>
      <plugin>mujoco_ros2_control/MujocoSystem</plugin>
    </hardware>
    <joint name="r_shoulder_pitch_joint">
      <param name="initial_position">-0.211</param>
      <command_interface name="position"/>
      <state_interface name="position">
        <param name="initial_value">-0.211</param>
      </state_interface>
      <state_interface name="velocity"/>
      <state_interface name="effort"/>
    </joint>
    <transmission name="r_shoulder_pitch_transmission">
      <plugin>transmission_interface/SimpleTransmission</plugin>
      <joint name="r_shoulder_pitch_joint" role="joint1">
        <mechanical_reduction>1.0</mechanical_reduction>
        <offset>0</offset>
      </joint>
      <actuator name="r_shoulder_pitch_actuator" role="actuator1">
        <mechanical_reduction>1.0</mechanical_reduction>
        <offset>0</offset>
      </actuator>
    </transmission>
    <joint name="r_shoulder_roll_joint">
      <param name="initial_position">0.0</param>
      <command_interface name="position"/>
      <state_interface name="position">
        <param name="initial_value">0.0</param>
      </state_interface>
      <state_interface name="velocity"/>
      <state_interface name="effort"/>
    </joint>
    <transmission name="r_shoulder_roll_transmission">
      <plugin>transmission_interface/SimpleTransmission</plugin>
      <joint name="r_shoulder_roll_joint" role="joint1">
        <mechanical_reduction>1.0</mechanical_reduction>
        <offset>0</offset>
      </joint>
      <actuator name="r_shoulder_roll_actuator" role="actuator1">
        <mechanical_reduction>1.0</mechanical_reduction>
        <offset>0</offset>
      </actuator>
    </transmission>
    <joint name="r_elbow_yaw_joint">
      <param name="initial_position">0.0</param>
      <command_interface name="position"/>
      <state_interface name="position">
        <param name="initial_value">0.0</param>
      </state_interface>
      <state_interface name="velocity"/>
      <state_interface name="effort"/>
    </joint>
    <transmission name="r_elbow_yaw_transmission">
      <plugin>transmission_interface/SimpleTransmission</plugin>
      <joint name="r_elbow_yaw_joint" role="joint1">
        <mechanical_reduction>1.0</mechanical_reduction>
        <offset>0</offset>
      </joint>
      <actuator name="r_elbow_yaw_actuator" role="actuator1">
        <mechanical_reduction>1.0</mechanical_reduction>
        <offset>0</offset>
      </actuator>
    </transmission>
    <joint name="r_elbow_pitch_joint">
      <param name="initial_position">0.0</param>
      <command_interface name="position"/>
      <state_interface name="position">
        <param name="initial_value">0.0</param>
      </state_interface>
      <state_interface name="velocity"/>
      <state_interface name="effort"/>
    </joint>
    <transmission name="r_elbow_pitch_transmission">
      <plugin>transmission_interface/SimpleTransmission</plugin>
      <joint name="r_elbow_pitch_joint" role="joint1">
        <mechanical_reduction>1.0</mechanical_reduction>
        <offset>0</offset>
      </joint>
      <actuator name="r_elbow_pitch_actuator" role="actuator1">
        <mechanical_reduction>1.0</mechanical_reduction>
        <offset>0</offset>
      </actuator>
    </transmission>
    <joint name="r_wrist_yaw_joint">
      <param name="initial_position">0.0</param>
      <command_interface name="position"/>
      <state_interface name="position">
        <param name="initial_value">0.0</param>
      </state_interface>
      <state_interface name="velocity"/>
      <state_interface name="effort"/>
    </joint>
    <transmission name="r_wrist_yaw_transmission">
      <plugin>transmission_interface/SimpleTransmission</plugin>
      <joint name="r_wrist_yaw_joint" role="joint1">
        <mechanical_reduction>1.0</mechanical_reduction>
        <offset>0</offset>
      </joint>
      <actuator name="r_wrist_yaw_actuator" role="actuator1">
        <mechanical_reduction>1.0</mechanical_reduction>
        <offset>0</offset>
      </actuator>
    </transmission>
    <joint name="r_wrist_pitch_joint">
      <param name="initial_position">0.0</param>
      <command_interface name="position"/>
      <state_interface name="position">
        <param name="initial_value">0.0</param>
      </state_interface>
      <state_interface name="velocity"/>
      <state_interface name="effort"/>
    </joint>
    <transmission name="r_wrist_pitch_transmission">
      <plugin>transmission_interface/SimpleTransmission</plugin>
      <joint name="r_wrist_pitch_joint" role="joint1">
        <mechanical_reduction>1.0</mechanical_reduction>
        <offset>0</offset>
      </joint>
      <actuator name="r_wrist_pitch_actuator" role="actuator1">
        <mechanical_reduction>1.0</mechanical_reduction>
        <offset>0</offset>
      </actuator>
    </transmission>
    <joint name="r_wrist_roll_joint">
      <param name="initial_position">0.0</param>
      <command_interface name="position"/>
      <state_interface name="position">
        <param name="initial_value">0.0</param>
      </state_interface>
      <state_interface name="velocity"/>
      <state_interface name="effort"/>
    </joint>
    <transmission name="r_wrist_roll_transmission">
      <plugin>transmission_interface/SimpleTransmission</plugin>
      <joint name="r_wrist_roll_joint" role="joint1">
        <mechanical_reduction>1.0</mechanical_reduction>
        <offset>0</offset>
      </joint>
      <actuator name="r_wrist_roll_actuator" role="actuator1">
        <mechanical_reduction>1.0</mechanical_reduction>
        <offset>0</offset>
      </actuator>
    </transmission>
  </ros2_control>
  <link name="l_hand_palm_link">
    <visual name="l_hand_palm_link_vis">
      <origin rpy="0 0 0" xyz="0 0 0"/>
      <geometry>
        <mesh filename="package://human_description/meshes/robot_hands/fourier_hand/visual/l_hand_palm_link.STL"/>
      </geometry>
      <material name="metal">
        <color rgba="0.85 0.85 0.85 1"/>
      </material>
    </visual>
    <collision name="l_hand_palm_link_col">
      <origin rpy="0 0 0" xyz="0 0 0"/>
      <geometry>
        <mesh filename="package://human_description/meshes/robot_hands/fourier_hand/collision/l_hand_palm_link.STL"/>
      </geometry>
    </collision>
    <inertial>
      <origin rpy="0 0 0" xyz="-0.000341219118062869 -0.00502824269426091 -0.0449280446308069"/>
      <mass value="0.099947"/>
      <inertia ixx="0.00030651" ixy="-2.324E-05" ixz="-3.2E-07" iyy="0.0004015" iyz="3.1E-07" izz="0.00019218"/>
    </inertial>
  </link>
  <joint name="l_hand_palm_fixed_joint" type="fixed">
    <parent link="l_end_effector_link"/>
    <child link="l_hand_palm_link"/>
    <origin rpy="0 0 0" xyz="-0.00143750472419189 -5.94019892983799e-05 -0.0210000216633744"/>
    <axis xyz="0 0 1"/>
  </joint>
  <link name="l_thumb_mcp_yaw_link">
    <visual name="l_thumb_mcp_yaw_link_vis">
      <origin rpy="0 0 0" xyz="0 0 0"/>
      <geometry>
        <mesh filename="package://human_description/meshes/robot_hands/fourier_hand/visual/l_thumb_mcp_yaw_link.STL"/>
      </geometry>
      <material name="metal">
        <color rgba="0.85 0.85 0.85 1"/>
      </material>
    </visual>
    <collision name="l_thumb_mcp_yaw_link_col">
      <origin rpy="0 0 0" xyz="0 0 0"/>
      <geometry>
        <mesh filename="package://human_description/meshes/robot_hands/fourier_hand/collision/l_thumb_mcp_yaw_link.STL"/>
      </geometry>
    </collision>
    <inertial>
      <origin rpy="0 0 0" xyz="0.0110171865188146 -2.47672281110389E-05 0.000776047913919345"/>
      <mass value="0.0094853"/>
      <inertia ixx="3.2E-07" ixy="1.3E-07" ixz="-4E-08" iyy="9.2E-07" iyz="0" izz="9.7E-07"/>
    </inertial>
  </link>
  <joint name="l_thumb_mcp_yaw_joint" type="revolute">
    <parent link="l_hand_palm_link"/>
    <child link="l_thumb_mcp_yaw_link"/>
    <origin rpy="0 -1.22105233317497e-05 0" xyz="0.0220003063830263 -0.0154982849769962 -0.0250926444440346"/>
    <axis xyz="0 0 1"/>
    <limit effort="10" lower="-1.7453292519943295" upper="0.05235987755982988" velocity="0.8"/>
    <safety_controller k_position="121.0" k_velocity="540.0" soft_lower_limit="-1.6929693744344996" soft_upper_limit="0.0"/>
    <dynamics damping="0.003" friction="0.2"/>
  </joint>
  <link name="l_thumb_mcp_pitch_link">
    <visual name="l_thumb_mcp_pitch_link_vis">
      <origin rpy="0 0 0" xyz="0 0 0"/>
      <geometry>
        <mesh filename="package://human_description/meshes/robot_hands/fourier_hand/visual/l_thumb_mcp_pitch_link.STL"/>
      </geometry>
      <material name="metal">
        <color rgba="0.85 0.85 0.85 1"/>
      </material>
    </visual>
    <collision name="l_thumb_mcp_pitch_link_col">
      <origin rpy="0 0 0" xyz="0 0 0"/>
      <geometry>
        <mesh filename="package://human_description/meshes/robot_hands/fourier_hand/collision/l_thumb_mcp_pitch_link.STL"/>
      </geometry>
    </collision>
    <inertial>
      <origin rpy="0 0 0" xyz="0.0312833670370602 0.000740495699468297 -2.32089545953995E-05"/>
      <mass value="0.033247"/>
      <inertia ixx="1.214E-05" ixy="4.25E-06" ixz="-1E-07" iyy="3.292E-05" iyz="3E-08" izz="3.183E-05"/>
    </inertial>
  </link>
  <joint name="l_thumb_mcp_pitch_joint" type="revolute">
    <parent link="l_thumb_mcp_yaw_link"/>
    <child link="l_thumb_mcp_pitch_link"/>
    <origin rpy="-1.57072797771317 0 0" xyz="0.02175 0 0"/>
    <axis xyz="0 0 1"/>
    <limit effort="10" lower="-0.05235987755982988" upper="1.2217304763960306" velocity="0.8"/>
    <safety_controller k_position="121.0" k_velocity="540.0" soft_lower_limit="0.0" soft_upper_limit="1.1693705988362006"/>
    <dynamics damping="0.003" friction="0.2"/>
  </joint>
  <link name="l_thumb_dip_link">
    <visual name="l_thumb_dip_link_vis">
      <origin rpy="0 0 0" xyz="0 0 0"/>
      <geometry>
        <mesh filename="package://human_description/meshes/robot_hands/fourier_hand/visual/l_thumb_dip_link.STL"/>
      </geometry>
      <material name="metal">
        <color rgba="0.85 0.85 0.85 1"/>
      </material>
    </visual>
    <collision name="l_thumb_dip_link_col">
      <origin rpy="0 0 0" xyz="0 0 0"/>
      <geometry>
        <mesh filename="package://human_description/meshes/robot_hands/fourier_hand/collision/l_thumb_dip_link.STL"/>
      </geometry>
    </collision>
    <inertial>
      <origin rpy="0 0 0" xyz="0.0132168665788391 -0.00326175003895993 -5.06101471370313E-07"/>
      <mass value="0.020321"/>
      <inertia ixx="9.7E-07" ixy="2.7E-07" ixz="9E-08" iyy="2.29E-06" iyz="-2E-08" izz="2.48E-06"/>
    </inertial>
  </link>
  <joint name="l_thumb_dip_joint" type="revolute">
    <parent link="l_thumb_mcp_pitch_link"/>
    <child link="l_thumb_dip_link"/>
    <origin rpy="0 0 1.22106056547031e-05" xyz="0.0615493701717829 0.00746157030770586 0"/>
    <axis xyz="0 0 1"/>
    <limit effort="10" lower="-0.05235987755982988" upper="1.2217304763960306" velocity="0.8"/>
    <safety_controller k_position="121.0" k_velocity="540.0" soft_lower_limit="0.0" soft_upper_limit="1.1693705988362006"/>
    <dynamics damping="0.003" friction="0.2"/>
    <mimic joint="l_thumb_mcp_pitch_joint" multiplier="0.974" offset="0"/>
  </joint>
  <link name="l_thumb_tip_link">
    <visual name="l_thumb_tip_link_vis">
      <origin rpy="0 0 0" xyz="0 0 0"/>
      <geometry>
        <sphere radius="0.005"/>
      </geometry>
      <material name="yellow">
        <color rgba="0.9 1.0 0.0 1.0"/>
      </material>
    </visual>
    <collision name="l_thumb_tip_link_col">
      <origin rpy="0 0 0" xyz="0 0 0"/>
      <geometry>
        <sphere radius="0.005"/>
      </geometry>
    </collision>
    <inertial>
      <origin rpy="0. 0. 0." xyz="0. 0. 0."/>
      <mass value="1e-05"/>
      <inertia ixx="8.333333333333334e-11" ixy="0" ixz="0" iyy="8.333333333333334e-11" iyz="0" izz="1.25e-10"/>
    </inertial>
  </link>
  <joint name="l_thumb_tip_joint" type="fixed">
    <parent link="l_thumb_dip_link"/>
    <child link="l_thumb_tip_link"/>
    <origin rpy="0 0 0" xyz="0.031 0 0"/>
    <axis xyz="0 0 1"/>
  </joint>
  <link name="l_index_mcp_link">
    <visual name="l_index_mcp_link_vis">
      <origin rpy="0 0 0" xyz="0 0 0"/>
      <geometry>
        <mesh filename="package://human_description/meshes/robot_hands/fourier_hand/visual/l_index_mcp_link.STL"/>
      </geometry>
      <material name="metal">
        <color rgba="0.85 0.85 0.85 1"/>
      </material>
    </visual>
    <collision name="l_index_mcp_link_col">
      <origin rpy="0 0 0" xyz="0 0 0"/>
      <geometry>
        <mesh filename="package://human_description/meshes/robot_hands/fourier_hand/collision/l_index_mcp_link.STL"/>
      </geometry>
    </collision>
    <inertial>
      <origin rpy="0 0 0" xyz="0.00960018118915809 0.00044353185078605 2.958628109756E-06"/>
      <mass value="0.019118"/>
      <inertia ixx="3.83E-06" ixy="3E-08" ixz="1.8E-07" iyy="3.72E-06" iyz="-8E-08" izz="8.7E-07"/>
    </inertial>
  </link>
  <joint name="l_index_mcp_joint" type="revolute">
    <parent link="l_hand_palm_link"/>
    <child link="l_index_mcp_link"/>
    <origin rpy="0.00130566300740641 1.51842419415245 0.00130387280614764" xyz="0.026869067504082 -0.0122934392405636 -0.0959894118552304"/>
    <axis xyz="0 0 1"/>
    <limit effort="10" lower="-1.5707963267948966" upper="0.05235987755982988" velocity="0.8"/>
    <safety_controller k_position="121.0" k_velocity="540.0" soft_lower_limit="-1.5184364492350666" soft_upper_limit="0.0"/>
    <dynamics damping="0.003" friction="0.2"/>
  </joint>
  <link name="l_index_dip_link">
    <visual name="l_index_dip_link_vis">
      <origin rpy="0 0 0" xyz="0 0 0"/>
      <geometry>
        <mesh filename="package://human_description/meshes/robot_hands/fourier_hand/visual/l_index_dip_link.STL"/>
      </geometry>
      <material name="metal">
        <color rgba="0.85 0.85 0.85 1"/>
      </material>
    </visual>
    <collision name="l_index_dip_link_col">
      <origin rpy="0 0 0" xyz="0 0 0"/>
      <geometry>
        <mesh filename="package://human_description/meshes/robot_hands/fourier_hand/collision/l_index_dip_link.STL"/>
      </geometry>
    </collision>
    <inertial>
      <origin rpy="0 0 0" xyz="0.0180093666798108 0.00300055705134525 -8.82089827167198E-06"/>
      <mass value="0.012927"/>
      <inertia ixx="2.03E-06" ixy="2E-08" ixz="1.4E-07" iyy="2.01E-06" iyz="-2.3E-07" izz="3.8E-07"/>
    </inertial>
  </link>
  <joint name="l_index_dip_joint" type="revolute">
    <parent link="l_index_mcp_link"/>
    <child link="l_index_dip_link"/>
    <origin rpy="0 0 -6.82553680074393e-05" xyz="0.0315316061985493 -0.00545507200132231 0"/>
    <axis xyz="0 0 1"/>
    <limit effort="10" lower="-1.5707963267948966" upper="0.05235987755982988" velocity="0.8"/>
    <safety_controller k_position="121.0" k_velocity="540.0" soft_lower_limit="-1.5184364492350666" soft_upper_limit="0.0"/>
    <dynamics damping="0.003" friction="0.2"/>
    <mimic joint="l_index_mcp_joint" multiplier="1.128" offset="0"/>
  </joint>
  <link name="l_index_tip_link">
    <visual name="l_index_tip_link_vis">
      <origin rpy="0 0 0" xyz="0 0 0"/>
      <geometry>
        <sphere radius="0.005"/>
      </geometry>
      <material name="yellow">
        <color rgba="0.9 1.0 0.0 1.0"/>
      </material>
    </visual>
    <collision name="l_index_tip_link_col">
      <origin rpy="0 0 0" xyz="0 0 0"/>
      <geometry>
        <sphere radius="0.005"/>
      </geometry>
    </collision>
    <inertial>
      <origin rpy="0. 0. 0." xyz="0. 0. 0."/>
      <mass value="1e-05"/>
      <inertia ixx="8.333333333333334e-11" ixy="0" ixz="0" iyy="8.333333333333334e-11" iyz="0" izz="1.25e-10"/>
    </inertial>
  </link>
  <joint name="l_index_tip_joint" type="fixed">
    <parent link="l_index_dip_link"/>
    <child link="l_index_tip_link"/>
    <origin rpy="0 0 0" xyz="0.038 -0.0038 0"/>
    <axis xyz="0 0 1"/>
  </joint>
  <link name="l_middle_mcp_link">
    <visual name="l_middle_mcp_link_vis">
      <origin rpy="0 0 0" xyz="0 0 0"/>
      <geometry>
        <mesh filename="package://human_description/meshes/robot_hands/fourier_hand/visual/l_middle_mcp_link.STL"/>
      </geometry>
      <material name="metal">
        <color rgba="0.85 0.85 0.85 1"/>
      </material>
    </visual>
    <collision name="l_middle_mcp_link_col">
      <origin rpy="0 0 0" xyz="0 0 0"/>
      <geometry>
        <mesh filename="package://human_description/meshes/robot_hands/fourier_hand/collision/l_middle_mcp_link.STL"/>
      </geometry>
    </collision>
    <inertial>
      <origin rpy="0 0 0" xyz="0.00955705245388191 0.00071918425895251 3.00382438536695E-06"/>
      <mass value="0.019118"/>
      <inertia ixx="3.84E-06" ixy="3E-08" ixz="1E-08" iyy="3.73E-06" iyz="-6E-08" izz="8.6E-07"/>
    </inertial>
  </link>
  <joint name="l_middle_mcp_joint" type="revolute">
    <parent link="l_hand_palm_link"/>
    <child link="l_middle_mcp_link"/>
    <origin rpy="1.39401189702948 1.57072689557984 1.3940118966122" xyz="0.00850119653118567 -0.0122933023251572 -0.0979925903933238"/>
    <axis xyz="0 0 1"/>
    <limit effort="10" lower="-1.5707963267948966" upper="0.05235987755982988" velocity="0.8"/>
    <safety_controller k_position="121.0" k_velocity="540.0" soft_lower_limit="-1.5184364492350666" soft_upper_limit="0.0"/>
    <dynamics damping="0.003" friction="0.2"/>
  </joint>
  <link name="l_middle_dip_link">
    <visual name="l_middle_dip_link_vis">
      <origin rpy="0 0 0" xyz="0 0 0"/>
      <geometry>
        <mesh filename="package://human_description/meshes/robot_hands/fourier_hand/visual/l_middle_dip_link.STL"/>
      </geometry>
      <material name="metal">
        <color rgba="0.85 0.85 0.85 1"/>
      </material>
    </visual>
    <collision name="l_middle_dip_link_col">
      <origin rpy="0 0 0" xyz="0 0 0"/>
      <geometry>
        <mesh filename="package://human_description/meshes/robot_hands/fourier_hand/collision/l_middle_dip_link.STL"/>
      </geometry>
    </collision>
    <inertial>
      <origin rpy="0 0 0" xyz="0.0212893549719316 0.00408289770373668 -9.13198765574441E-06"/>
      <mass value="0.015352"/>
      <inertia ixx="3.29E-06" ixy="0" ixz="5E-08" iyy="3.28E-06" iyz="-2.2E-07" izz="4.1E-07"/>
    </inertial>
  </link>
  <joint name="l_middle_dip_joint" type="revolute">
    <parent link="l_middle_mcp_link"/>
    <child link="l_middle_dip_link"/>
    <origin rpy="0 0 -6.83490817261459e-05" xyz="0.0316616941629316 -0.00464081056852417 0"/>
    <axis xyz="0 0 1"/>
    <limit effort="10" lower="-1.5707963267948966" upper="0.05235987755982988" velocity="0.8"/>
    <safety_controller k_position="121.0" k_velocity="540.0" soft_lower_limit="-1.5184364492350666" soft_upper_limit="0.0"/>
    <dynamics damping="0.003" friction="0.2"/>
    <mimic joint="l_middle_mcp_joint" multiplier="1.128" offset="0"/>
  </joint>
  <link name="l_middle_tip_link">
    <visual name="l_middle_tip_link_vis">
      <origin rpy="0 0 0" xyz="0 0 0"/>
      <geometry>
        <sphere radius="0.005"/>
      </geometry>
      <material name="yellow">
        <color rgba="0.9 1.0 0.0 1.0"/>
      </material>
    </visual>
    <collision name="l_middle_tip_link_col">
      <origin rpy="0 0 0" xyz="0 0 0"/>
      <geometry>
        <sphere radius="0.005"/>
      </geometry>
    </collision>
    <inertial>
      <origin rpy="0. 0. 0." xyz="0. 0. 0."/>
      <mass value="1e-05"/>
      <inertia ixx="8.333333333333334e-11" ixy="0" ixz="0" iyy="8.333333333333334e-11" iyz="0" izz="1.25e-10"/>
    </inertial>
  </link>
  <joint name="l_middle_tip_joint" type="fixed">
    <parent link="l_middle_dip_link"/>
    <child link="l_middle_tip_link"/>
    <origin rpy="0 0 0" xyz="0.045 -0.0032 0"/>
    <axis xyz="0 0 1"/>
  </joint>
  <link name="l_ring_mcp_link">
    <visual name="l_ring_mcp_link_vis">
      <origin rpy="0 0 0" xyz="0 0 0"/>
      <geometry>
        <mesh filename="package://human_description/meshes/robot_hands/fourier_hand/visual/l_ring_mcp_link.STL"/>
      </geometry>
      <material name="metal">
        <color rgba="0.85 0.85 0.85 1"/>
      </material>
    </visual>
    <collision name="l_ring_mcp_link_col">
      <origin rpy="0 0 0" xyz="0 0 0"/>
      <geometry>
        <mesh filename="package://human_description/meshes/robot_hands/fourier_hand/collision/l_ring_mcp_link.STL"/>
      </geometry>
    </collision>
    <inertial>
      <origin rpy="0 0 0" xyz="0.00960002708086655 0.000443602585259689 3.01251546439701E-06"/>
      <mass value="0.019117"/>
      <inertia ixx="3.84E-06" ixy="2E-08" ixz="-1.2E-07" iyy="3.72E-06" iyz="-1.5E-07" izz="8.7E-07"/>
    </inertial>
  </link>
  <joint name="l_ring_mcp_joint" type="revolute">
    <parent link="l_hand_palm_link"/>
    <child link="l_ring_mcp_link"/>
    <origin rpy="3.14028638202668 1.51844861517835 3.14028817139281" xyz="-0.0099599699075906 -0.012293306060256 -0.0979379429013024"/>
    <axis xyz="0 0 1"/>
    <limit effort="10" lower="-1.5707963267948966" upper="0.05235987755982988" velocity="0.8"/>
    <safety_controller k_position="121.0" k_velocity="540.0" soft_lower_limit="-1.5184364492350666" soft_upper_limit="0.0"/>
    <dynamics damping="0.003" friction="0.2"/>
  </joint>
  <link name="l_ring_dip_link">
    <visual name="l_ring_dip_link_vis">
      <origin rpy="0 0 0" xyz="0 0 0"/>
      <geometry>
        <mesh filename="package://human_description/meshes/robot_hands/fourier_hand/visual/l_ring_dip_link.STL"/>
      </geometry>
      <material name="metal">
        <color rgba="0.85 0.85 0.85 1"/>
      </material>
    </visual>
    <collision name="l_ring_dip_link_col">
      <origin rpy="0 0 0" xyz="0 0 0"/>
      <geometry>
        <mesh filename="package://human_description/meshes/robot_hands/fourier_hand/collision/l_ring_dip_link.STL"/>
      </geometry>
    </collision>
    <inertial>
      <origin rpy="0 0 0" xyz="0.0180097013870772 0.00300008137097776 -8.39742864479354E-06"/>
      <mass value="0.012926"/>
      <inertia ixx="2.04E-06" ixy="0" ixz="-3E-08" iyy="2E-06" iyz="-2.6E-07" izz="3.8E-07"/>
    </inertial>
  </link>
  <joint name="l_ring_dip_joint" type="revolute">
    <parent link="l_ring_mcp_link"/>
    <child link="l_ring_dip_link"/>
    <origin rpy="0 0 -6.82554553643455e-05" xyz="0.0315316061985493 -0.00545507200132236 0"/>
    <axis xyz="0 0 1"/>
    <limit effort="10" lower="-1.5707963267948966" upper="0.05235987755982988" velocity="0.8"/>
    <safety_controller k_position="121.0" k_velocity="540.0" soft_lower_limit="-1.5184364492350666" soft_upper_limit="0.0"/>
    <dynamics damping="0.003" friction="0.2"/>
    <mimic joint="l_ring_mcp_joint" multiplier="1.128" offset="0"/>
  </joint>
  <link name="l_ring_tip_link">
    <visual name="l_ring_tip_link_vis">
      <origin rpy="0 0 0" xyz="0 0 0"/>
      <geometry>
        <sphere radius="0.005"/>
      </geometry>
      <material name="yellow">
        <color rgba="0.9 1.0 0.0 1.0"/>
      </material>
    </visual>
    <collision name="l_ring_tip_link_col">
      <origin rpy="0 0 0" xyz="0 0 0"/>
      <geometry>
        <sphere radius="0.005"/>
      </geometry>
    </collision>
    <inertial>
      <origin rpy="0. 0. 0." xyz="0. 0. 0."/>
      <mass value="1e-05"/>
      <inertia ixx="8.333333333333334e-11" ixy="0" ixz="0" iyy="8.333333333333334e-11" iyz="0" izz="1.25e-10"/>
    </inertial>
  </link>
  <joint name="l_ring_tip_joint" type="fixed">
    <parent link="l_ring_dip_link"/>
    <child link="l_ring_tip_link"/>
    <origin rpy="0 0 0" xyz="0.038 -0.0038 0"/>
    <axis xyz="0 0 1"/>
  </joint>
  <link name="l_pinky_mcp_link">
    <visual name="l_pinky_mcp_link_vis">
      <origin rpy="0 0 0" xyz="0 0 0"/>
      <geometry>
        <mesh filename="package://human_description/meshes/robot_hands/fourier_hand/visual/l_pinky_mcp_link.STL"/>
      </geometry>
      <material name="metal">
        <color rgba="0.85 0.85 0.85 1"/>
      </material>
    </visual>
    <collision name="l_pinky_mcp_link_col">
      <origin rpy="0 0 0" xyz="0 0 0"/>
      <geometry>
        <mesh filename="package://human_description/meshes/robot_hands/fourier_hand/collision/l_pinky_mcp_link.STL"/>
      </geometry>
    </collision>
    <inertial>
      <origin rpy="0 0 0" xyz="0.00964509278679124 9.44866526330912E-05 3.06424748800632E-06"/>
      <mass value="0.019118"/>
      <inertia ixx="3.82E-06" ixy="0" ixz="-2.6E-07" iyy="3.7E-06" iyz="-2.6E-07" izz="9.1E-07"/>
    </inertial>
  </link>
  <joint name="l_pinky_mcp_joint" type="revolute">
    <parent link="l_hand_palm_link"/>
    <child link="l_pinky_mcp_link"/>
    <origin rpy="3.14093869761107 1.46608875997235 3.14094227921624" xyz="-0.0282266675554703 -0.012293437629494 -0.0960129830601813"/>
    <axis xyz="0 0 1"/>
    <limit effort="10" lower="-1.5707963267948966" upper="0.05235987755982988" velocity="0.8"/>
    <safety_controller k_position="121.0" k_velocity="540.0" soft_lower_limit="-1.5184364492350666" soft_upper_limit="0.0"/>
    <dynamics damping="0.003" friction="0.2"/>
  </joint>
  <link name="l_pinky_dip_link">
    <visual name="l_pinky_dip_link_vis">
      <origin rpy="0 0 0" xyz="0 0 0"/>
      <geometry>
        <mesh filename="package://human_description/meshes/robot_hands/fourier_hand/visual/l_pinky_dip_link.STL"/>
      </geometry>
      <material name="metal">
        <color rgba="0.85 0.85 0.85 1"/>
      </material>
    </visual>
    <collision name="l_pinky_dip_link_col">
      <origin rpy="0 0 0" xyz="0 0 0"/>
      <geometry>
        <mesh filename="package://human_description/meshes/robot_hands/fourier_hand/collision/l_pinky_dip_link.STL"/>
      </geometry>
    </collision>
    <inertial>
      <origin rpy="0 0 0" xyz="0.0160981065679005 0.00118818281307698 -9.37496349673328E-06"/>
      <mass value="0.0056868"/>
      <inertia ixx="6.6E-07" ixy="0" ixz="-2E-08" iyy="6.2E-07" iyz="-1.4E-07" izz="1.8E-07"/>
    </inertial>
  </link>
  <joint name="l_pinky_dip_joint" type="revolute">
    <parent link="l_pinky_mcp_link"/>
    <child link="l_pinky_dip_link"/>
    <origin rpy="0 0 -6.79747455421694e-05" xyz="0.0313378020543266 -0.00647627689369765 0"/>
    <axis xyz="0 0 1"/>
    <limit effort="10" lower="-1.5707963267948966" upper="0.05235987755982988" velocity="0.8"/>
    <safety_controller k_position="121.0" k_velocity="540.0" soft_lower_limit="-1.5184364492350666" soft_upper_limit="0.0"/>
    <dynamics damping="0.003" friction="0.2"/>
    <mimic joint="l_pinky_mcp_joint" multiplier="1.128" offset="0"/>
  </joint>
  <link name="l_pinky_tip_link">
    <visual name="l_pinky_tip_link_vis">
      <origin rpy="0 0 0" xyz="0 0 0"/>
      <geometry>
        <sphere radius="0.005"/>
      </geometry>
      <material name="yellow">
        <color rgba="0.9 1.0 0.0 1.0"/>
      </material>
    </visual>
    <collision name="l_pinky_tip_link_col">
      <origin rpy="0 0 0" xyz="0 0 0"/>
      <geometry>
        <sphere radius="0.005"/>
      </geometry>
    </collision>
    <inertial>
      <origin rpy="0. 0. 0." xyz="0. 0. 0."/>
      <mass value="1e-05"/>
      <inertia ixx="8.333333333333334e-11" ixy="0" ixz="0" iyy="8.333333333333334e-11" iyz="0" izz="1.25e-10"/>
    </inertial>
  </link>
  <joint name="l_pinky_tip_joint" type="fixed">
    <parent link="l_pinky_dip_link"/>
    <child link="l_pinky_tip_link"/>
    <origin rpy="0 0 0" xyz="0.031 -0.007 0"/>
    <axis xyz="0 0 1"/>
  </joint>
  <ros2_control name="l_hand_system" type="system">
    <hardware>
      <plugin>mujoco_ros2_control/MujocoSystem</plugin>
    </hardware>
    <joint name="l_thumb_mcp_yaw_joint">
      <param name="initial_position">0.0</param>
      <command_interface name="position"/>
      <state_interface name="position">
        <param name="initial_value">0.0</param>
      </state_interface>
      <state_interface name="velocity"/>
      <state_interface name="effort"/>
    </joint>
    <transmission name="l_thumb_mcp_yaw_transmission">
      <plugin>transmission_interface/SimpleTransmission</plugin>
      <joint name="l_thumb_mcp_yaw_joint" role="joint1">
        <mechanical_reduction>1.0</mechanical_reduction>
        <offset>0</offset>
      </joint>
      <actuator name="l_thumb_mcp_yaw_actuator" role="actuator1">
        <mechanical_reduction>1.0</mechanical_reduction>
        <offset>0</offset>
      </actuator>
    </transmission>
    <joint name="l_thumb_mcp_pitch_joint">
      <param name="initial_position">0.0</param>
      <command_interface name="position"/>
      <state_interface name="position">
        <param name="initial_value">0.0</param>
      </state_interface>
      <state_interface name="velocity"/>
      <state_interface name="effort"/>
    </joint>
    <transmission name="l_thumb_mcp_pitch_transmission">
      <plugin>transmission_interface/SimpleTransmission</plugin>
      <joint name="l_thumb_mcp_pitch_joint" role="joint1">
        <mechanical_reduction>1.0</mechanical_reduction>
        <offset>0</offset>
      </joint>
      <actuator name="l_thumb_mcp_pitch_actuator" role="actuator1">
        <mechanical_reduction>1.0</mechanical_reduction>
        <offset>0</offset>
      </actuator>
    </transmission>
    <joint name="l_thumb_dip_joint">
      <param name="initial_position">0.0</param>
      <param name="mimic">l_thumb_mcp_pitch_joint</param>
      <param name="multiplier">1</param>
      <command_interface name="position"/>
      <state_interface name="position">
        <param name="initial_value">0.0</param>
      </state_interface>
      <state_interface name="velocity"/>
      <state_interface name="effort"/>
    </joint>
    <joint name="l_index_mcp_joint">
      <param name="initial_position">0.0</param>
      <command_interface name="position"/>
      <state_interface name="position">
        <param name="initial_value">0.0</param>
      </state_interface>
      <state_interface name="velocity"/>
      <state_interface name="effort"/>
    </joint>
    <transmission name="l_index_mcp_transmission">
      <plugin>transmission_interface/SimpleTransmission</plugin>
      <joint name="l_index_mcp_joint" role="joint1">
        <mechanical_reduction>1.0</mechanical_reduction>
        <offset>0</offset>
      </joint>
      <actuator name="l_index_mcp_actuator" role="actuator1">
        <mechanical_reduction>1.0</mechanical_reduction>
        <offset>0</offset>
      </actuator>
    </transmission>
    <joint name="l_index_dip_joint">
      <param name="initial_position">0.0</param>
      <param name="mimic">l_index_mcp_joint</param>
      <param name="multiplier">1</param>
      <command_interface name="position"/>
      <state_interface name="position">
        <param name="initial_value">0.0</param>
      </state_interface>
      <state_interface name="velocity"/>
      <state_interface name="effort"/>
    </joint>
    <joint name="l_middle_mcp_joint">
      <param name="initial_position">0.0</param>
      <command_interface name="position"/>
      <state_interface name="position">
        <param name="initial_value">0.0</param>
      </state_interface>
      <state_interface name="velocity"/>
      <state_interface name="effort"/>
    </joint>
    <transmission name="l_middle_mcp_transmission">
      <plugin>transmission_interface/SimpleTransmission</plugin>
      <joint name="l_middle_mcp_joint" role="joint1">
        <mechanical_reduction>1.0</mechanical_reduction>
        <offset>0</offset>
      </joint>
      <actuator name="l_middle_mcp_actuator" role="actuator1">
        <mechanical_reduction>1.0</mechanical_reduction>
        <offset>0</offset>
      </actuator>
    </transmission>
    <joint name="l_middle_dip_joint">
      <param name="initial_position">0.0</param>
      <param name="mimic">l_middle_mcp_joint</param>
      <param name="multiplier">1</param>
      <command_interface name="position"/>
      <state_interface name="position">
        <param name="initial_value">0.0</param>
      </state_interface>
      <state_interface name="velocity"/>
      <state_interface name="effort"/>
    </joint>
    <joint name="l_pinky_mcp_joint">
      <param name="initial_position">0.0</param>
      <command_interface name="position"/>
      <state_interface name="position">
        <param name="initial_value">0.0</param>
      </state_interface>
      <state_interface name="velocity"/>
      <state_interface name="effort"/>
    </joint>
    <transmission name="l_pinky_mcp_transmission">
      <plugin>transmission_interface/SimpleTransmission</plugin>
      <joint name="l_pinky_mcp_joint" role="joint1">
        <mechanical_reduction>1.0</mechanical_reduction>
        <offset>0</offset>
      </joint>
      <actuator name="l_pinky_mcp_actuator" role="actuator1">
        <mechanical_reduction>1.0</mechanical_reduction>
        <offset>0</offset>
      </actuator>
    </transmission>
    <joint name="l_pinky_dip_joint">
      <param name="initial_position">0.0</param>
      <param name="mimic">l_pinky_mcp_joint</param>
      <param name="multiplier">1</param>
      <command_interface name="position"/>
      <state_interface name="position">
        <param name="initial_value">0.0</param>
      </state_interface>
      <state_interface name="velocity"/>
      <state_interface name="effort"/>
    </joint>
    <joint name="l_ring_mcp_joint">
      <param name="initial_position">0.0</param>
      <command_interface name="position"/>
      <state_interface name="position">
        <param name="initial_value">0.0</param>
      </state_interface>
      <state_interface name="velocity"/>
      <state_interface name="effort"/>
    </joint>
    <transmission name="l_ring_mcp_transmission">
      <plugin>transmission_interface/SimpleTransmission</plugin>
      <joint name="l_ring_mcp_joint" role="joint1">
        <mechanical_reduction>1.0</mechanical_reduction>
        <offset>0</offset>
      </joint>
      <actuator name="l_ring_mcp_actuator" role="actuator1">
        <mechanical_reduction>1.0</mechanical_reduction>
        <offset>0</offset>
      </actuator>
    </transmission>
    <joint name="l_ring_dip_joint">
      <param name="initial_position">0.0</param>
      <param name="mimic">l_ring_mcp_joint</param>
      <param name="multiplier">1</param>
      <command_interface name="position"/>
      <state_interface name="position">
        <param name="initial_value">0.0</param>
      </state_interface>
      <state_interface name="velocity"/>
      <state_interface name="effort"/>
    </joint>
  </ros2_control>
  <link name="r_hand_palm_link">
    <visual name="r_hand_palm_link_vis">
      <origin rpy="0 0 0" xyz="0 0 0"/>
      <geometry>
        <mesh filename="package://human_description/meshes/robot_hands/fourier_hand/visual/r_hand_palm_link.STL"/>
      </geometry>
      <material name="metal">
        <color rgba="0.85 0.85 0.85 1"/>
      </material>
    </visual>
    <collision name="r_hand_palm_link_col">
      <origin rpy="0 0 0" xyz="0 0 0"/>
      <geometry>
        <mesh filename="package://human_description/meshes/robot_hands/fourier_hand/collision/r_hand_palm_link.STL"/>
      </geometry>
    </collision>
    <inertial>
      <origin rpy="0 0 0" xyz="-0.000386127877570155 0.00503962174027214 -0.0449101271034299"/>
      <mass value="0.09995"/>
      <inertia ixx="0.00030106" ixy="6E-08" ixz="-3.7E-07" iyy="0.0004068" iyz="-3.2E-07" izz="0.00019218"/>
    </inertial>
  </link>
  <joint name="r_hand_palm_fixed_joint" type="fixed">
    <parent link="r_end_effector_link"/>
    <child link="r_hand_palm_link"/>
    <origin rpy="0 0 0" xyz="-0.00141711624232485 0 -0.0210000172555634"/>
    <axis xyz="0 0 1"/>
  </joint>
  <link name="r_thumb_mcp_yaw_link">
    <visual name="r_thumb_mcp_yaw_link_vis">
      <origin rpy="0 0 0" xyz="0 0 0"/>
      <geometry>
        <mesh filename="package://human_description/meshes/robot_hands/fourier_hand/visual/r_thumb_mcp_yaw_link.STL"/>
      </geometry>
      <material name="metal">
        <color rgba="0.85 0.85 0.85 1"/>
      </material>
    </visual>
    <collision name="r_thumb_mcp_yaw_link_col">
      <origin rpy="0 0 0" xyz="0 0 0"/>
      <geometry>
        <mesh filename="package://human_description/meshes/robot_hands/fourier_hand/collision/r_thumb_mcp_yaw_link.STL"/>
      </geometry>
    </collision>
    <inertial>
      <origin rpy="0 0 0" xyz="0.0110212287050384 -3.32698098642614E-05 -0.000776780774953884"/>
      <mass value="0.0094822"/>
      <inertia ixx="3E-07" ixy="0" ixz="-4E-08" iyy="9.5E-07" iyz="0" izz="9.7E-07"/>
    </inertial>
  </link>
  <joint name="r_thumb_mcp_yaw_joint" type="revolute">
    <parent link="r_hand_palm_link"/>
    <child link="r_thumb_mcp_yaw_link"/>
    <origin rpy="3.14159265358979 0 0" xyz="0.0219570995851234 0.0155628599102215 -0.0250905219673082"/>
    <axis xyz="0 0 1"/>
    <limit effort="10" lower="-1.7453292519943295" upper="0.05235987755982988" velocity="0.8"/>
    <safety_controller k_position="121.0" k_velocity="540.0" soft_lower_limit="-1.6929693744344996" soft_upper_limit="0.0"/>
    <dynamics damping="0.003" friction="0.2"/>
  </joint>
  <link name="r_thumb_mcp_pitch_link">
    <visual name="r_thumb_mcp_pitch_link_vis">
      <origin rpy="0 0 0" xyz="0 0 0"/>
      <geometry>
        <mesh filename="package://human_description/meshes/robot_hands/fourier_hand/visual/r_thumb_mcp_pitch_link.STL"/>
      </geometry>
      <material name="metal">
        <color rgba="0.85 0.85 0.85 1"/>
      </material>
    </visual>
    <collision name="r_thumb_mcp_pitch_link_col">
      <origin rpy="0 0 0" xyz="0 0 0"/>
      <geometry>
        <mesh filename="package://human_description/meshes/robot_hands/fourier_hand/collision/r_thumb_mcp_pitch_link.STL"/>
      </geometry>
    </collision>
    <inertial>
      <origin rpy="0 0 0" xyz="0.0317791766093077 0.00114667119068899 -2.28155954604681E-05"/>
      <mass value="0.033824"/>
      <inertia ixx="1.132E-05" ixy="3E-08" ixz="1.7E-07" iyy="3.419E-05" iyz="1E-08" izz="3.228E-05"/>
    </inertial>
  </link>
  <joint name="r_thumb_mcp_pitch_joint" type="revolute">
    <parent link="r_thumb_mcp_yaw_link"/>
    <child link="r_thumb_mcp_pitch_link"/>
    <origin rpy="1.57086466715046 1.22641020904056e-05 -0.000791532745143911" xyz="0.0217499931849152 -1.72158354079244e-05 0"/>
    <axis xyz="0 0 1"/>
    <limit effort="10" lower="-0.05235987755982988" upper="1.2217304763960306" velocity="0.8"/>
    <safety_controller k_position="121.0" k_velocity="540.0" soft_lower_limit="0.0" soft_upper_limit="1.1693705988362006"/>
    <dynamics damping="0.003" friction="0.2"/>
  </joint>
  <link name="r_thumb_dip_link">
    <visual name="r_thumb_dip_link_vis">
      <origin rpy="0 0 0" xyz="0 0 0"/>
      <geometry>
        <mesh filename="package://human_description/meshes/robot_hands/fourier_hand/visual/r_thumb_dip_link.STL"/>
      </geometry>
      <material name="metal">
        <color rgba="0.85 0.85 0.85 1"/>
      </material>
    </visual>
    <collision name="r_thumb_dip_link_col">
      <origin rpy="0 0 0" xyz="0 0 0"/>
      <geometry>
        <mesh filename="package://human_description/meshes/robot_hands/fourier_hand/collision/r_thumb_dip_link.STL"/>
      </geometry>
    </collision>
    <inertial>
      <origin rpy="0 0 0" xyz="0.0137334892415782 -0.00277453154609453 -4.9718691799705E-07"/>
      <mass value="0.019744"/>
      <inertia ixx="9E-07" ixy="0" ixz="9E-08" iyy="2.19E-06" iyz="0" izz="2.33E-06"/>
    </inertial>
  </link>
  <joint name="r_thumb_dip_joint" type="revolute">
    <parent link="r_thumb_mcp_pitch_link"/>
    <child link="r_thumb_dip_link"/>
    <origin rpy="0 0 1.22100084212751e-05" xyz="0.0614443264755605 0.00828219439307844 0"/>
    <axis xyz="0 0 1"/>
    <limit effort="10" lower="-0.05235987755982988" upper="1.2217304763960306" velocity="0.8"/>
    <safety_controller k_position="121.0" k_velocity="540.0" soft_lower_limit="0.0" soft_upper_limit="1.1693705988362006"/>
    <dynamics damping="0.003" friction="0.2"/>
    <mimic joint="r_thumb_mcp_pitch_joint" multiplier="0.974" offset="0"/>
  </joint>
  <link name="r_thumb_tip_link">
    <visual name="r_thumb_tip_link_vis">
      <origin rpy="0 0 0" xyz="0 0 0"/>
      <geometry>
        <sphere radius="0.005"/>
      </geometry>
      <material name="yellow">
        <color rgba="0.9 1.0 0.0 1.0"/>
      </material>
    </visual>
    <collision name="r_thumb_tip_link_col">
      <origin rpy="0 0 0" xyz="0 0 0"/>
      <geometry>
        <sphere radius="0.005"/>
      </geometry>
    </collision>
    <inertial>
      <origin rpy="0. 0. 0." xyz="0. 0. 0."/>
      <mass value="1e-05"/>
      <inertia ixx="8.333333333333334e-11" ixy="0" ixz="0" iyy="8.333333333333334e-11" iyz="0" izz="1.25e-10"/>
    </inertial>
  </link>
  <joint name="r_thumb_tip_joint" type="fixed">
    <parent link="r_thumb_dip_link"/>
    <child link="r_thumb_tip_link"/>
    <origin rpy="0 0 0" xyz="0.031 0 0"/>
    <axis xyz="0 0 1"/>
  </joint>
  <link name="r_index_mcp_link">
    <visual name="r_index_mcp_link_vis">
      <origin rpy="0 0 0" xyz="0 0 0"/>
      <geometry>
        <mesh filename="package://human_description/meshes/robot_hands/fourier_hand/visual/r_index_mcp_link.STL"/>
      </geometry>
      <material name="metal">
        <color rgba="0.85 0.85 0.85 1"/>
      </material>
    </visual>
    <collision name="r_index_mcp_link_col">
      <origin rpy="0 0 0" xyz="0 0 0"/>
      <geometry>
        <mesh filename="package://human_description/meshes/robot_hands/fourier_hand/collision/r_index_mcp_link.STL"/>
      </geometry>
    </collision>
    <inertial>
      <origin rpy="0 0 0" xyz="0.00960002721978334 0.000443602715936658 3.01276850581123E-06"/>
      <mass value="0.019118"/>
      <inertia ixx="3.84E-06" ixy="0" ixz="1.5E-07" iyy="3.71E-06" iyz="1.2E-07" izz="8.7E-07"/>
    </inertial>
  </link>
  <joint name="r_index_mcp_joint" type="revolute">
    <parent link="r_hand_palm_link"/>
    <child link="r_index_mcp_link"/>
    <origin rpy="-3.14028763091841 1.5184240046093 0.00408527869771669" xyz="0.0268347443648602 0.01238126080166 -0.0959877257832576"/>
    <axis xyz="0 0 1"/>
    <limit effort="10" lower="-1.5707963267948966" upper="0.05235987755982988" velocity="0.8"/>
    <safety_controller k_position="121.0" k_velocity="540.0" soft_lower_limit="-1.5184364492350666" soft_upper_limit="0.0"/>
    <dynamics damping="0.003" friction="0.2"/>
  </joint>
  <link name="r_index_dip_link">
    <visual name="r_index_dip_link_vis">
      <origin rpy="0 0 0" xyz="0 0 0"/>
      <geometry>
        <mesh filename="package://human_description/meshes/robot_hands/fourier_hand/visual/r_index_dip_link.STL"/>
      </geometry>
      <material name="metal">
        <color rgba="0.85 0.85 0.85 1"/>
      </material>
    </visual>
    <collision name="r_index_dip_link_col">
      <origin rpy="0 0 0" xyz="0 0 0"/>
      <geometry>
        <mesh filename="package://human_description/meshes/robot_hands/fourier_hand/collision/r_index_dip_link.STL"/>
      </geometry>
    </collision>
    <inertial>
      <origin rpy="0 0 0" xyz="0.0180099074306208 0.00299885189981389 -8.39749152652114E-06"/>
      <mass value="0.012927"/>
      <inertia ixx="2.03E-06" ixy="-1E-08" ixz="9E-08" iyy="2.01E-06" iyz="2.5E-07" izz="3.8E-07"/>
    </inertial>
  </link>
  <joint name="r_index_dip_joint" type="revolute">
    <parent link="r_index_mcp_link"/>
    <child link="r_index_dip_link"/>
    <origin rpy="0 0 -6.82553680074393e-05" xyz="0.0315316061985493 -0.00545507200132231 0"/>
    <axis xyz="0 0 1"/>
    <limit effort="10" lower="-1.5707963267948966" upper="0.05235987755982988" velocity="0.8"/>
    <safety_controller k_position="121.0" k_velocity="540.0" soft_lower_limit="-1.5184364492350666" soft_upper_limit="0.0"/>
    <dynamics damping="0.003" friction="0.2"/>
    <mimic joint="r_index_mcp_joint" multiplier="1.128" offset="0"/>
  </joint>
  <link name="r_index_tip_link">
    <visual name="r_index_tip_link_vis">
      <origin rpy="0 0 0" xyz="0 0 0"/>
      <geometry>
        <sphere radius="0.005"/>
      </geometry>
      <material name="yellow">
        <color rgba="0.9 1.0 0.0 1.0"/>
      </material>
    </visual>
    <collision name="r_index_tip_link_col">
      <origin rpy="0 0 0" xyz="0 0 0"/>
      <geometry>
        <sphere radius="0.005"/>
      </geometry>
    </collision>
    <inertial>
      <origin rpy="0. 0. 0." xyz="0. 0. 0."/>
      <mass value="1e-05"/>
      <inertia ixx="8.333333333333334e-11" ixy="0" ixz="0" iyy="8.333333333333334e-11" iyz="0" izz="1.25e-10"/>
    </inertial>
  </link>
  <joint name="r_index_tip_joint" type="fixed">
    <parent link="r_index_dip_link"/>
    <child link="r_index_tip_link"/>
    <origin rpy="0 0 0" xyz="0.038 -0.0038 0"/>
    <axis xyz="0 0 1"/>
  </joint>
  <link name="r_middle_mcp_link">
    <visual name="r_middle_mcp_link_vis">
      <origin rpy="0 0 0" xyz="0 0 0"/>
      <geometry>
        <mesh filename="package://human_description/meshes/robot_hands/fourier_hand/visual/r_middle_mcp_link.STL"/>
      </geometry>
      <material name="metal">
        <color rgba="0.85 0.85 0.85 1"/>
      </material>
    </visual>
    <collision name="r_middle_mcp_link_col">
      <origin rpy="0 0 0" xyz="0 0 0"/>
      <geometry>
        <mesh filename="package://human_description/meshes/robot_hands/fourier_hand/collision/r_middle_mcp_link.STL"/>
      </geometry>
    </collision>
    <inertial>
      <origin rpy="0 0 0" xyz="0.00955705255659736 0.000719184503009201 3.00388766753812E-06"/>
      <mass value="0.019118"/>
      <inertia ixx="3.85E-06" ixy="0" ixz="0" iyy="3.72E-06" iyz="6E-08" izz="8.6E-07"/>
    </inertial>
  </link>
  <joint name="r_middle_mcp_joint" type="revolute">
    <parent link="r_hand_palm_link"/>
    <child link="r_middle_mcp_link"/>
    <origin rpy="-1.75035301585144 1.57072689472437 1.39402168267738" xyz="0.00846694447258024 0.0123302974668429 -0.0979909078036594"/>
    <axis xyz="0 0 1"/>
    <limit effort="10" lower="-1.5707963267948966" upper="0.05235987755982988" velocity="0.8"/>
    <safety_controller k_position="121.0" k_velocity="540.0" soft_lower_limit="-1.5184364492350666" soft_upper_limit="0.0"/>
    <dynamics damping="0.003" friction="0.2"/>
  </joint>
  <link name="r_middle_dip_link">
    <visual name="r_middle_dip_link_vis">
      <origin rpy="0 0 0" xyz="0 0 0"/>
      <geometry>
        <mesh filename="package://human_description/meshes/robot_hands/fourier_hand/visual/r_middle_dip_link.STL"/>
      </geometry>
      <material name="metal">
        <color rgba="0.85 0.85 0.85 1"/>
      </material>
    </visual>
    <collision name="r_middle_dip_link_col">
      <origin rpy="0 0 0" xyz="0 0 0"/>
      <geometry>
        <mesh filename="package://human_description/meshes/robot_hands/fourier_hand/collision/r_middle_dip_link.STL"/>
      </geometry>
    </collision>
    <inertial>
      <origin rpy="0 0 0" xyz="0.0212896407543054 0.00408143996126112 -9.13148789218055E-06"/>
      <mass value="0.015352"/>
      <inertia ixx="3.29E-06" ixy="0" ixz="0" iyy="3.28E-06" iyz="2.2E-07" izz="4.1E-07"/>
    </inertial>
  </link>
  <joint name="r_middle_dip_joint" type="revolute">
    <parent link="r_middle_mcp_link"/>
    <child link="r_middle_dip_link"/>
    <origin rpy="0 0 0" xyz="0.0316616941629307 -0.00464081056853635 0"/>
    <axis xyz="0 0 1"/>
    <limit effort="10" lower="-1.5707963267948966" upper="0.05235987755982988" velocity="0.8"/>
    <safety_controller k_position="121.0" k_velocity="540.0" soft_lower_limit="-1.5184364492350666" soft_upper_limit="0.0"/>
    <dynamics damping="0.003" friction="0.2"/>
    <mimic joint="r_middle_mcp_joint" multiplier="1.128" offset="0"/>
  </joint>
  <link name="r_middle_tip_link">
    <visual name="r_middle_tip_link_vis">
      <origin rpy="0 0 0" xyz="0 0 0"/>
      <geometry>
        <sphere radius="0.005"/>
      </geometry>
      <material name="yellow">
        <color rgba="0.9 1.0 0.0 1.0"/>
      </material>
    </visual>
    <collision name="r_middle_tip_link_col">
      <origin rpy="0 0 0" xyz="0 0 0"/>
      <geometry>
        <sphere radius="0.005"/>
      </geometry>
    </collision>
    <inertial>
      <origin rpy="0. 0. 0." xyz="0. 0. 0."/>
      <mass value="1e-05"/>
      <inertia ixx="8.333333333333334e-11" ixy="0" ixz="0" iyy="8.333333333333334e-11" iyz="0" izz="1.25e-10"/>
    </inertial>
  </link>
  <joint name="r_middle_tip_joint" type="fixed">
    <parent link="r_middle_dip_link"/>
    <child link="r_middle_tip_link"/>
    <origin rpy="0 0 0" xyz="0.045 -0.0032 0"/>
    <axis xyz="0 0 1"/>
  </joint>
  <link name="r_ring_mcp_link">
    <visual name="r_ring_mcp_link_vis">
      <origin rpy="0 0 0" xyz="0 0 0"/>
      <geometry>
        <mesh filename="package://human_description/meshes/robot_hands/fourier_hand/visual/r_ring_mcp_link.STL"/>
      </geometry>
      <material name="metal">
        <color rgba="0.85 0.85 0.85 1"/>
      </material>
    </visual>
    <collision name="r_ring_mcp_link_col">
      <origin rpy="0 0 0" xyz="0 0 0"/>
      <geometry>
        <mesh filename="package://human_description/meshes/robot_hands/fourier_hand/collision/r_ring_mcp_link.STL"/>
      </geometry>
    </collision>
    <inertial>
      <origin rpy="0 0 0" xyz="0.0096001470731025 0.00044427472300787 2.95897501418479E-06"/>
      <mass value="0.019117"/>
      <inertia ixx="3.84E-06" ixy="0" ixz="-1.6E-07" iyy="3.71E-06" iyz="1.2E-07" izz="8.7E-07"/>
    </inertial>
  </link>
  <joint name="r_ring_mcp_joint" type="revolute">
    <parent link="r_hand_palm_link"/>
    <child link="r_ring_mcp_link"/>
    <origin rpy="-0.00278180898871791 1.51844864673705 3.14159265358979" xyz="-0.00999415052356634 0.0122789339975533 -0.0979362638116289"/>
    <axis xyz="0 0 1"/>
    <limit effort="10" lower="-1.5707963267948966" upper="0.05235987755982988" velocity="0.8"/>
    <safety_controller k_position="121.0" k_velocity="540.0" soft_lower_limit="-1.5184364492350666" soft_upper_limit="0.0"/>
    <dynamics damping="0.003" friction="0.2"/>
  </joint>
  <link name="r_ring_dip_link">
    <visual name="r_ring_dip_link_vis">
      <origin rpy="0 0 0" xyz="0 0 0"/>
      <geometry>
        <mesh filename="package://human_description/meshes/robot_hands/fourier_hand/visual/r_ring_dip_link.STL"/>
      </geometry>
      <material name="metal">
        <color rgba="0.85 0.85 0.85 1"/>
      </material>
    </visual>
    <collision name="r_ring_dip_link_col">
      <origin rpy="0 0 0" xyz="0 0 0"/>
      <geometry>
        <mesh filename="package://human_description/meshes/robot_hands/fourier_hand/collision/r_ring_dip_link.STL"/>
      </geometry>
    </collision>
    <inertial>
      <origin rpy="0 0 0" xyz="0.0180093387957889 0.00300072092575132 -8.8209720389143E-06"/>
      <mass value="0.012925"/>
      <inertia ixx="2.03E-06" ixy="1E-08" ixz="-9E-08" iyy="2.01E-06" iyz="2.5E-07" izz="3.8E-07"/>
    </inertial>
  </link>
  <joint name="r_ring_dip_joint" type="revolute">
    <parent link="r_ring_mcp_link"/>
    <child link="r_ring_dip_link"/>
    <origin rpy="0 0 0" xyz="0.0315320280251494 -0.00545263318234326 0"/>
    <axis xyz="0 0 1"/>
    <limit effort="10" lower="-1.5707963267948966" upper="0.05235987755982988" velocity="0.8"/>
    <safety_controller k_position="121.0" k_velocity="540.0" soft_lower_limit="-1.5184364492350666" soft_upper_limit="0.0"/>
    <dynamics damping="0.003" friction="0.2"/>
    <mimic joint="r_ring_mcp_joint" multiplier="1.128" offset="0"/>
  </joint>
  <link name="r_ring_tip_link">
    <visual name="r_ring_tip_link_vis">
      <origin rpy="0 0 0" xyz="0 0 0"/>
      <geometry>
        <sphere radius="0.005"/>
      </geometry>
      <material name="yellow">
        <color rgba="0.9 1.0 0.0 1.0"/>
      </material>
    </visual>
    <collision name="r_ring_tip_link_col">
      <origin rpy="0 0 0" xyz="0 0 0"/>
      <geometry>
        <sphere radius="0.005"/>
      </geometry>
    </collision>
    <inertial>
      <origin rpy="0. 0. 0." xyz="0. 0. 0."/>
      <mass value="1e-05"/>
      <inertia ixx="8.333333333333334e-11" ixy="0" ixz="0" iyy="8.333333333333334e-11" iyz="0" izz="1.25e-10"/>
    </inertial>
  </link>
  <joint name="r_ring_tip_joint" type="fixed">
    <parent link="r_ring_dip_link"/>
    <child link="r_ring_tip_link"/>
    <origin rpy="0 0 0" xyz="0.038 -0.0038 0"/>
    <axis xyz="0 0 1"/>
  </joint>
  <link name="r_pinky_mcp_link">
    <visual name="r_pinky_mcp_link_vis">
      <origin rpy="0 0 0" xyz="0 0 0"/>
      <geometry>
        <mesh filename="package://human_description/meshes/robot_hands/fourier_hand/visual/r_pinky_mcp_link.STL"/>
      </geometry>
      <material name="metal">
        <color rgba="0.85 0.85 0.85 1"/>
      </material>
    </visual>
    <collision name="r_pinky_mcp_link_col">
      <origin rpy="0 0 0" xyz="0 0 0"/>
      <geometry>
        <mesh filename="package://human_description/meshes/robot_hands/fourier_hand/collision/r_pinky_mcp_link.STL"/>
      </geometry>
    </collision>
    <inertial>
      <origin rpy="0 0 0" xyz="0.0096385794510781 0.000350820790422174 2.97431465753201E-06"/>
      <mass value="0.019117"/>
      <inertia ixx="3.82E-06" ixy="2E-08" ixz="-3.1E-07" iyy="3.7E-06" iyz="2E-07" izz="9.1E-07"/>
    </inertial>
  </link>
  <joint name="r_pinky_mcp_joint" type="revolute">
    <parent link="r_hand_palm_link"/>
    <child link="r_pinky_mcp_link"/>
    <origin rpy="-0.248599525552003 1.46275517858851 2.89438415643823" xyz="-0.0282607774805067 0.012227983776169 -0.0960113074336258"/>
    <axis xyz="0 0 1"/>
    <limit effort="10" lower="-1.5707963267948966" upper="0.05235987755982988" velocity="0.8"/>
    <safety_controller k_position="121.0" k_velocity="540.0" soft_lower_limit="-1.5184364492350666" soft_upper_limit="0.0"/>
    <dynamics damping="0.003" friction="0.2"/>
  </joint>
  <link name="r_pinky_dip_link">
    <visual name="r_pinky_dip_link_vis">
      <origin rpy="0 0 0" xyz="0 0 0"/>
      <geometry>
        <mesh filename="package://human_description/meshes/robot_hands/fourier_hand/visual/r_pinky_dip_link.STL"/>
      </geometry>
      <material name="metal">
        <color rgba="0.85 0.85 0.85 1"/>
      </material>
    </visual>
    <collision name="r_pinky_dip_link_col">
      <origin rpy="0 0 0" xyz="0 0 0"/>
      <geometry>
        <mesh filename="package://human_description/meshes/robot_hands/fourier_hand/collision/r_pinky_dip_link.STL"/>
      </geometry>
    </collision>
    <inertial>
      <origin rpy="0 0 0" xyz="0.0160982593015231 0.00119063979850093 -9.07695338753234E-06"/>
      <mass value="0.0056869"/>
      <inertia ixx="6.6E-07" ixy="1E-08" ixz="-5E-08" iyy="6.2E-07" iyz="1.3E-07" izz="1.8E-07"/>
    </inertial>
  </link>
  <joint name="r_pinky_dip_joint" type="revolute">
    <parent link="r_pinky_mcp_link"/>
    <child link="r_pinky_dip_link"/>
    <origin rpy="0 0 0.0263892434774018" xyz="0.0314990327566104 -0.00564011838510353 0"/>
    <axis xyz="0 0 1"/>
    <limit effort="10" lower="-1.5707963267948966" upper="0.05235987755982988" velocity="0.8"/>
    <safety_controller k_position="121.0" k_velocity="540.0" soft_lower_limit="-1.5184364492350666" soft_upper_limit="0.0"/>
    <dynamics damping="0.003" friction="0.2"/>
    <mimic joint="r_pinky_mcp_joint" multiplier="1.128" offset="0"/>
  </joint>
  <link name="r_pinky_tip_link">
    <visual name="r_pinky_tip_link_vis">
      <origin rpy="0 0 0" xyz="0 0 0"/>
      <geometry>
        <sphere radius="0.005"/>
      </geometry>
      <material name="yellow">
        <color rgba="0.9 1.0 0.0 1.0"/>
      </material>
    </visual>
    <collision name="r_pinky_tip_link_col">
      <origin rpy="0 0 0" xyz="0 0 0"/>
      <geometry>
        <sphere radius="0.005"/>
      </geometry>
    </collision>
    <inertial>
      <origin rpy="0. 0. 0." xyz="0. 0. 0."/>
      <mass value="1e-05"/>
      <inertia ixx="8.333333333333334e-11" ixy="0" ixz="0" iyy="8.333333333333334e-11" iyz="0" izz="1.25e-10"/>
    </inertial>
  </link>
  <joint name="r_pinky_tip_joint" type="fixed">
    <parent link="r_pinky_dip_link"/>
    <child link="r_pinky_tip_link"/>
    <origin rpy="0 0 0" xyz="0.031 -0.007 0"/>
    <axis xyz="0 0 1"/>
  </joint>
  <ros2_control name="r_hand_system" type="system">
    <hardware>
      <plugin>mujoco_ros2_control/MujocoSystem</plugin>
    </hardware>
    <joint name="r_thumb_mcp_yaw_joint">
      <param name="initial_position">0.0</param>
      <command_interface name="position"/>
      <state_interface name="position">
        <param name="initial_value">0.0</param>
      </state_interface>
      <state_interface name="velocity"/>
      <state_interface name="effort"/>
    </joint>
    <transmission name="r_thumb_mcp_yaw_transmission">
      <plugin>transmission_interface/SimpleTransmission</plugin>
      <joint name="r_thumb_mcp_yaw_joint" role="joint1">
        <mechanical_reduction>1.0</mechanical_reduction>
        <offset>0</offset>
      </joint>
      <actuator name="r_thumb_mcp_yaw_actuator" role="actuator1">
        <mechanical_reduction>1.0</mechanical_reduction>
        <offset>0</offset>
      </actuator>
    </transmission>
    <joint name="r_thumb_mcp_pitch_joint">
      <param name="initial_position">0.0</param>
      <command_interface name="position"/>
      <state_interface name="position">
        <param name="initial_value">0.0</param>
      </state_interface>
      <state_interface name="velocity"/>
      <state_interface name="effort"/>
    </joint>
    <transmission name="r_thumb_mcp_pitch_transmission">
      <plugin>transmission_interface/SimpleTransmission</plugin>
      <joint name="r_thumb_mcp_pitch_joint" role="joint1">
        <mechanical_reduction>1.0</mechanical_reduction>
        <offset>0</offset>
      </joint>
      <actuator name="r_thumb_mcp_pitch_actuator" role="actuator1">
        <mechanical_reduction>1.0</mechanical_reduction>
        <offset>0</offset>
      </actuator>
    </transmission>
    <joint name="r_thumb_dip_joint">
      <param name="initial_position">0.0</param>
      <param name="mimic">r_thumb_mcp_pitch_joint</param>
      <param name="multiplier">1</param>
      <command_interface name="position"/>
      <state_interface name="position">
        <param name="initial_value">0.0</param>
      </state_interface>
      <state_interface name="velocity"/>
      <state_interface name="effort"/>
    </joint>
    <joint name="r_index_mcp_joint">
      <param name="initial_position">0.0</param>
      <command_interface name="position"/>
      <state_interface name="position">
        <param name="initial_value">0.0</param>
      </state_interface>
      <state_interface name="velocity"/>
      <state_interface name="effort"/>
    </joint>
    <transmission name="r_index_mcp_transmission">
      <plugin>transmission_interface/SimpleTransmission</plugin>
      <joint name="r_index_mcp_joint" role="joint1">
        <mechanical_reduction>1.0</mechanical_reduction>
        <offset>0</offset>
      </joint>
      <actuator name="r_index_mcp_actuator" role="actuator1">
        <mechanical_reduction>1.0</mechanical_reduction>
        <offset>0</offset>
      </actuator>
    </transmission>
    <joint name="r_index_dip_joint">
      <param name="initial_position">0.0</param>
      <param name="mimic">r_index_mcp_joint</param>
      <param name="multiplier">1</param>
      <command_interface name="position"/>
      <state_interface name="position">
        <param name="initial_value">0.0</param>
      </state_interface>
      <state_interface name="velocity"/>
      <state_interface name="effort"/>
    </joint>
    <joint name="r_middle_mcp_joint">
      <param name="initial_position">0.0</param>
      <command_interface name="position"/>
      <state_interface name="position">
        <param name="initial_value">0.0</param>
      </state_interface>
      <state_interface name="velocity"/>
      <state_interface name="effort"/>
    </joint>
    <transmission name="r_middle_mcp_transmission">
      <plugin>transmission_interface/SimpleTransmission</plugin>
      <joint name="r_middle_mcp_joint" role="joint1">
        <mechanical_reduction>1.0</mechanical_reduction>
        <offset>0</offset>
      </joint>
      <actuator name="r_middle_mcp_actuator" role="actuator1">
        <mechanical_reduction>1.0</mechanical_reduction>
        <offset>0</offset>
      </actuator>
    </transmission>
    <joint name="r_middle_dip_joint">
      <param name="initial_position">0.0</param>
      <param name="mimic">r_middle_mcp_joint</param>
      <param name="multiplier">1</param>
      <command_interface name="position"/>
      <state_interface name="position">
        <param name="initial_value">0.0</param>
      </state_interface>
      <state_interface name="velocity"/>
      <state_interface name="effort"/>
    </joint>
    <joint name="r_pinky_mcp_joint">
      <param name="initial_position">0.0</param>
      <command_interface name="position"/>
      <state_interface name="position">
        <param name="initial_value">0.0</param>
      </state_interface>
      <state_interface name="velocity"/>
      <state_interface name="effort"/>
    </joint>
    <transmission name="r_pinky_mcp_transmission">
      <plugin>transmission_interface/SimpleTransmission</plugin>
      <joint name="r_pinky_mcp_joint" role="joint1">
        <mechanical_reduction>1.0</mechanical_reduction>
        <offset>0</offset>
      </joint>
      <actuator name="r_pinky_mcp_actuator" role="actuator1">
        <mechanical_reduction>1.0</mechanical_reduction>
        <offset>0</offset>
      </actuator>
    </transmission>
    <joint name="r_pinky_dip_joint">
      <param name="initial_position">0.0</param>
      <param name="mimic">r_pinky_mcp_joint</param>
      <param name="multiplier">1</param>
      <command_interface name="position"/>
      <state_interface name="position">
        <param name="initial_value">0.0</param>
      </state_interface>
      <state_interface name="velocity"/>
      <state_interface name="effort"/>
    </joint>
    <joint name="r_ring_mcp_joint">
      <param name="initial_position">0.0</param>
      <command_interface name="position"/>
      <state_interface name="position">
        <param name="initial_value">0.0</param>
      </state_interface>
      <state_interface name="velocity"/>
      <state_interface name="effort"/>
    </joint>
    <transmission name="r_ring_mcp_transmission">
      <plugin>transmission_interface/SimpleTransmission</plugin>
      <joint name="r_ring_mcp_joint" role="joint1">
        <mechanical_reduction>1.0</mechanical_reduction>
        <offset>0</offset>
      </joint>
      <actuator name="r_ring_mcp_actuator" role="actuator1">
        <mechanical_reduction>1.0</mechanical_reduction>
        <offset>0</offset>
      </actuator>
    </transmission>
    <joint name="r_ring_dip_joint">
      <param name="initial_position">0.0</param>
      <param name="mimic">r_ring_mcp_joint</param>
      <param name="multiplier">1</param>
      <command_interface name="position"/>
      <state_interface name="position">
        <param name="initial_value">0.0</param>
      </state_interface>
      <state_interface name="velocity"/>
      <state_interface name="effort"/>
    </joint>
  </ros2_control>
  <link name="pelvis_imu_frame">
    <visual name="pelvis_imu_frame_vis">
      <geometry>
        <mesh filename="package://human_description/meshes/GR1T2/visual/pelvis_imu_frame.STL"/>
      </geometry>
      <material name="steel">
        <color rgba="0.7 0.65 0.55 1"/>
      </material>
    </visual>
    <collision name="pelvis_imu_frame_col">
      <geometry>
        <mesh filename="package://human_description/meshes/GR1T2/collision/pelvis_imu_frame.STL"/>
      </geometry>
    </collision>
    <inertial>
      <origin rpy="0 0 0" xyz="-0.062133 -1.5129E-06 -0.003126"/>
      <mass value="0.05"/>
      <inertia ixx="1.125E-05" ixy="0" ixz="8.8E-07" iyy="1.67E-05" iyz="0" izz="1.983E-05"/>
    </inertial>
  </link>
  <joint name="pelvis_imu" type="fixed">
    <parent link="base_link"/>
    <child link="pelvis_imu_frame"/>
    <origin rpy="0 0 0" xyz="0 0 -0.0595999999999995"/>
    <axis xyz="0 0 1"/>
  </joint>
  <ros2_control name="sensors_system" type="system">
    <hardware>
      <plugin>mujoco_ros2_control/MujocoSystem</plugin>
    </hardware>
    <joint name="pelvis_imu"/>
    <sensor name="pelvis_imu">
      <state_interface name="orientation.x"/>
      <state_interface name="orientation.y"/>
      <state_interface name="orientation.z"/>
      <state_interface name="orientation.w"/>
      <state_interface name="angular_velocity.x"/>
      <state_interface name="angular_velocity.y"/>
      <state_interface name="angular_velocity.z"/>
      <state_interface name="linear_acceleration.x"/>
      <state_interface name="linear_acceleration.y"/>
      <state_interface name="linear_acceleration.z"/>
      <param name="frame_id">pelvis_imu_frame</param>
      <param name="gyro_sensor">pelvis_imu_gyro</param>
      <param name="accelerometer_sensor">pelvis_imu_accelerometer</param>
      <param name="quaternion_sensor">pelvis_imu_quaternion</param>
      <param name="sensor_type">imu</param>
    </sensor>
  </ros2_control>
  <mujoco>
    <compiler angle="degree" balanceinertia="true" convexhull="false" discardvisual="true" eulerseq="xyz" fusestatic="false" meshdir="../../meshes/GR1T2/visual" strippath="true" texturedir="../../textures/"/>
    <option collision="all" timestep="0.001"/>
  </mujoco>
</robot>
