<?xml version="1.0" ?>
<!-- =================================================================================== -->
<!-- |    This document was autogenerated by xacro from /home/neal/ws_humble/src/tendon_description/xacro/finger/finger.urdf.xacro | -->
<!-- |    EDITING THIS FILE BY HAND IS NOT RECOMMENDED                                 | -->
<!-- =================================================================================== -->
<robot name="tendon">
  <link name="base_link">
            </link>
  <link name="base_site1_link">
    <visual name="base_site1_link_vis">
      <origin rpy="0 0 0" xyz="0 0 0"/>
      <geometry>
        <sphere radius="0.005"/>
      </geometry>
      <material name="white">
        <color rgba="1.0 1.0 1.0 1.0"/>
      </material>
    </visual>
    <collision name="base_site1_link_col">
      <origin rpy="0 0 0" xyz="0 0 0"/>
      <geometry>
        <sphere radius="0.005"/>
      </geometry>
    </collision>
    <inertial>
      <origin rpy="0 0 0" xyz="0 0 0"/>
      <mass value="1e-05"/>
      <inertia ixx="8.333333333333334e-11" ixy="0" ixz="0" iyy="8.333333333333334e-11" iyz="0" izz="1.25e-10"/>
    </inertial>
  </link>
  <joint name="base_site1_joint" type="fixed">
    <parent link="base_link"/>
    <child link="base_site1_link"/>
    <origin rpy="0 0 0" xyz="-0.03 0 0.43"/>
    <axis xyz="1 0 0"/>
  </joint>
  <link name="tendon_link">
    <visual name="tendon_link_vis">
      <origin rpy="0. 1.5707963 0." xyz="-0.025 0. 0. "/>
      <geometry>
        <cylinder length="0.05" radius="0.03"/>
      </geometry>
      <material name="purple">
        <color rgba="0.2 0.2 0.5 1.0"/>
      </material>
    </visual>
    <collision name="tendon_link_col">
      <origin rpy="0. 1.5707963 0." xyz="-0.025 0. 0. "/>
      <geometry>
        <cylinder length="0.05" radius="0.03"/>
      </geometry>
    </collision>
    <inertial>
      <origin rpy="0. 1.5707963 0." xyz="-0.025 0. 0. "/>
      <mass value="0.5"/>
      <inertia ixx="0.00021666666666666668" ixy="0" ixz="0" iyy="0.00021666666666666668" iyz="0" izz="0.000225"/>
    </inertial>
  </link>
  <joint name="tendon_joint" type="prismatic">
    <parent link="base_link"/>
    <child link="tendon_link"/>
    <origin rpy="0 -1.5707963 0" xyz="-0.03 0.0 0.3"/>
    <axis xyz="1 0 0"/>
    <limit effort="100" lower="-0.01" upper="0.10471976" velocity="0.8"/>
    <safety_controller k_position="121.0" k_velocity="540.0" soft_lower_limit="0.0" soft_upper_limit="0.09471976"/>
    <dynamics damping="0.003" friction="0.2"/>
  </joint>
  <link name="tendon_site1_link">
    <visual name="tendon_site1_link_vis">
      <origin rpy="0 0 0" xyz="0 0 0"/>
      <geometry>
        <sphere radius="0.005"/>
      </geometry>
      <material name="white">
        <color rgba="1.0 1.0 1.0 1.0"/>
      </material>
    </visual>
    <collision name="tendon_site1_link_col">
      <origin rpy="0 0 0" xyz="0 0 0"/>
      <geometry>
        <sphere radius="0.005"/>
      </geometry>
    </collision>
    <inertial>
      <origin rpy="0 0 0" xyz="0 0 0"/>
      <mass value="1e-05"/>
      <inertia ixx="8.333333333333334e-11" ixy="0" ixz="0" iyy="8.333333333333334e-11" iyz="0" izz="1.25e-10"/>
    </inertial>
  </link>
  <joint name="tendon_site1_joint" type="fixed">
    <parent link="tendon_link"/>
    <child link="tendon_site1_link"/>
    <origin rpy="0 0 0" xyz="0 0 0"/>
    <axis xyz="1 0 0"/>
  </joint>
  <link name="mcp_link">
    <visual name="mcp_link_vis">
      <origin rpy="0 1.5707964 0" xyz="0 0 0 "/>
      <geometry>
        <cylinder length="0.03" radius="0.02"/>
      </geometry>
      <material name="green">
        <color rgba="0.0 0.8 0.0 0.7"/>
      </material>
    </visual>
    <collision name="mcp_link_col">
      <origin rpy="0 1.5707964 0" xyz="0 0 0 "/>
      <geometry>
        <cylinder length="0.03" radius="0.02"/>
      </geometry>
    </collision>
    <inertial>
      <origin rpy="0 1.5707964 0" xyz="0 0 0 "/>
      <mass value="0.1"/>
      <inertia ixx="1.7500000000000002e-05" ixy="0" ixz="0" iyy="1.7500000000000002e-05" iyz="0" izz="2e-05"/>
    </inertial>
  </link>
  <joint name="mcp_joint" type="revolute">
    <parent link="base_link"/>
    <child link="mcp_link"/>
    <origin rpy="0 0 1.5707964" xyz="0.0 0.0 0.4"/>
    <axis xyz="1 0 0"/>
    <limit effort="10" lower="-0.17453292519943295" upper="1.1344640137963142" velocity="0.8"/>
    <safety_controller k_position="121.0" k_velocity="540.0" soft_lower_limit="-0.12217304763960307" soft_upper_limit="1.0821041362364843"/>
    <dynamics damping="0.003" friction="0.2"/>
  </joint>
  <link name="mcp_bar_linkage_link">
    <visual name="mcp_bar_linkage_link_part1_vis">
      <origin rpy="0 0 0" xyz="0 0 0.05"/>
      <geometry>
        <cylinder length="0.1" radius="0.01"/>
      </geometry>
      <material name="yellow">
        <color rgba="0.9 1.0 0.0 0.7"/>
      </material>
    </visual>
    <visual name="mcp_bar_linkage_link_part2_vis">
      <origin xyz="0 0 0.1"/>
      <geometry>
        <sphere radius="0.01"/>
      </geometry>
      <material name="yellow">
        <color rgba="0.9 1.0 0.0 0.7"/>
      </material>
    </visual>
    <visual name="mcp_bar_linkage_link_part3_vis">
      <origin xyz="0 0 0.0"/>
      <geometry>
        <sphere radius="0.01"/>
      </geometry>
      <material name="yellow">
        <color rgba="0.9 1.0 0.0 0.7"/>
      </material>
    </visual>
    <collision name="mcp_bar_linkage_link_part1_col">
      <origin rpy="0 0 0" xyz="0 0 0.05"/>
      <geometry>
        <cylinder length="0.1" radius="0.01"/>
      </geometry>
    </collision>
    <collision name="mcp_bar_linkage_link_part2_col">
      <origin xyz="0 0 0.1"/>
      <geometry>
        <sphere radius="0.01"/>
      </geometry>
    </collision>
    <collision name="mcp_bar_linkage_link_part3_col">
      <origin xyz="0 0 0.0"/>
      <geometry>
        <sphere radius="0.01"/>
      </geometry>
    </collision>
    <inertial>
      <origin rpy="0 0 0" xyz="0 0 0.05"/>
      <mass value="0.1"/>
      <inertia ixx="8.583333333333335e-05" ixy="0" ixz="0" iyy="8.583333333333335e-05" iyz="0" izz="5e-06"/>
    </inertial>
  </link>
  <joint name="mcp_bar_linkage_fixed_joint" type="fixed">
    <parent link="mcp_link"/>
    <child link="mcp_bar_linkage_link"/>
    <origin rpy="1.5707964 0 0" xyz="0.0 0.0 0.0"/>
    <axis xyz="1 0 0"/>
  </joint>
  <link name="mcp_site1_link">
    <visual name="mcp_site1_link_vis">
      <origin rpy="0 0 0" xyz="0 0 0"/>
      <geometry>
        <sphere radius="0.005"/>
      </geometry>
      <material name="white">
        <color rgba="1.0 1.0 1.0 1.0"/>
      </material>
    </visual>
    <collision name="mcp_site1_link_col">
      <origin rpy="0 0 0" xyz="0 0 0"/>
      <geometry>
        <sphere radius="0.005"/>
      </geometry>
    </collision>
    <inertial>
      <origin rpy="0 0 0" xyz="0 0 0"/>
      <mass value="1e-05"/>
      <inertia ixx="8.333333333333334e-11" ixy="0" ixz="0" iyy="8.333333333333334e-11" iyz="0" izz="1.25e-10"/>
    </inertial>
  </link>
  <joint name="mcp_site1_joint" type="fixed">
    <parent link="mcp_link"/>
    <child link="mcp_site1_link"/>
    <origin rpy="0 0 -1.5707964" xyz="0 -0.02 0.03"/>
    <axis xyz="1 0 0"/>
  </joint>
  <link name="pip_link">
    <visual name="pip_link_vis">
      <origin rpy="0 1.5707964 0" xyz="0 0 0 "/>
      <geometry>
        <cylinder length="0.03" radius="0.02"/>
      </geometry>
      <material name="green">
        <color rgba="0.0 0.8 0.0 0.7"/>
      </material>
    </visual>
    <collision name="pip_link_col">
      <origin rpy="0 1.5707964 0" xyz="0 0 0 "/>
      <geometry>
        <cylinder length="0.03" radius="0.02"/>
      </geometry>
    </collision>
    <inertial>
      <origin rpy="0 1.5707964 0" xyz="0 0 0 "/>
      <mass value="0.1"/>
      <inertia ixx="1.7500000000000002e-05" ixy="0" ixz="0" iyy="1.7500000000000002e-05" iyz="0" izz="2e-05"/>
    </inertial>
  </link>
  <joint name="pip_joint" type="revolute">
    <parent link="mcp_link"/>
    <child link="pip_link"/>
    <origin rpy="0 0 0" xyz="0 -0.1 0"/>
    <axis xyz="1 0 0"/>
    <limit effort="10" lower="-0.17453292519943295" upper="1.1344640137963142" velocity="0.8"/>
    <safety_controller k_position="121.0" k_velocity="540.0" soft_lower_limit="-0.12217304763960307" soft_upper_limit="1.0821041362364843"/>
    <dynamics damping="0.003" friction="0.2"/>
  </joint>
  <link name="pip_bar_linkage_link">
    <visual name="pip_bar_linkage_link_part1_vis">
      <origin rpy="0 0 0" xyz="0 0 0.05"/>
      <geometry>
        <cylinder length="0.1" radius="0.01"/>
      </geometry>
      <material name="yellow">
        <color rgba="0.9 1.0 0.0 0.7"/>
      </material>
    </visual>
    <visual name="pip_bar_linkage_link_part2_vis">
      <origin xyz="0 0 0.1"/>
      <geometry>
        <sphere radius="0.01"/>
      </geometry>
      <material name="yellow">
        <color rgba="0.9 1.0 0.0 0.7"/>
      </material>
    </visual>
    <visual name="pip_bar_linkage_link_part3_vis">
      <origin xyz="0 0 0.0"/>
      <geometry>
        <sphere radius="0.01"/>
      </geometry>
      <material name="yellow">
        <color rgba="0.9 1.0 0.0 0.7"/>
      </material>
    </visual>
    <collision name="pip_bar_linkage_link_part1_col">
      <origin rpy="0 0 0" xyz="0 0 0.05"/>
      <geometry>
        <cylinder length="0.1" radius="0.01"/>
      </geometry>
    </collision>
    <collision name="pip_bar_linkage_link_part2_col">
      <origin xyz="0 0 0.1"/>
      <geometry>
        <sphere radius="0.01"/>
      </geometry>
    </collision>
    <collision name="pip_bar_linkage_link_part3_col">
      <origin xyz="0 0 0.0"/>
      <geometry>
        <sphere radius="0.01"/>
      </geometry>
    </collision>
    <inertial>
      <origin rpy="0 0 0" xyz="0 0 0.05"/>
      <mass value="0.1"/>
      <inertia ixx="8.583333333333335e-05" ixy="0" ixz="0" iyy="8.583333333333335e-05" iyz="0" izz="5e-06"/>
    </inertial>
  </link>
  <joint name="pip_bar_linkage_fixed_joint" type="fixed">
    <parent link="pip_link"/>
    <child link="pip_bar_linkage_link"/>
    <origin rpy="1.5707964 0 0" xyz="0.0 0.0 0.0"/>
    <axis xyz="1 0 0"/>
  </joint>
  <link name="pip_site1_link">
    <visual name="pip_site1_link_vis">
      <origin rpy="0 0 0" xyz="0 0 0"/>
      <geometry>
        <sphere radius="0.005"/>
      </geometry>
      <material name="white">
        <color rgba="1.0 1.0 1.0 1.0"/>
      </material>
    </visual>
    <collision name="pip_site1_link_col">
      <origin rpy="0 0 0" xyz="0 0 0"/>
      <geometry>
        <sphere radius="0.005"/>
      </geometry>
    </collision>
    <inertial>
      <origin rpy="0 0 0" xyz="0 0 0"/>
      <mass value="1e-05"/>
      <inertia ixx="8.333333333333334e-11" ixy="0" ixz="0" iyy="8.333333333333334e-11" iyz="0" izz="1.25e-10"/>
    </inertial>
  </link>
  <joint name="pip_site1_joint" type="fixed">
    <parent link="pip_link"/>
    <child link="pip_site1_link"/>
    <origin rpy="0 0 -1.5707964" xyz="0 -0.03 0.01"/>
    <axis xyz="1 0 0"/>
  </joint>
  <link name="pip_site2_link">
    <visual name="pip_site2_link_vis">
      <origin rpy="0 0 0" xyz="0 0 0"/>
      <geometry>
        <sphere radius="0.005"/>
      </geometry>
      <material name="white">
        <color rgba="1.0 1.0 1.0 1.0"/>
      </material>
    </visual>
    <collision name="pip_site2_link_col">
      <origin rpy="0 0 0" xyz="0 0 0"/>
      <geometry>
        <sphere radius="0.005"/>
      </geometry>
    </collision>
    <inertial>
      <origin rpy="0 0 0" xyz="0 0 0"/>
      <mass value="1e-05"/>
      <inertia ixx="8.333333333333334e-11" ixy="0" ixz="0" iyy="8.333333333333334e-11" iyz="0" izz="1.25e-10"/>
    </inertial>
  </link>
  <joint name="pip_site2_joint" type="fixed">
    <parent link="pip_link"/>
    <child link="pip_site2_link"/>
    <origin rpy="0 0 -1.5707964" xyz="0 -0.05 0.02"/>
    <axis xyz="1 0 0"/>
  </joint>
  <link name="pip_site3_link">
    <visual name="pip_site3_link_vis">
      <origin rpy="0 0 0" xyz="0 0 0"/>
      <geometry>
        <sphere radius="0.005"/>
      </geometry>
      <material name="white">
        <color rgba="1.0 1.0 1.0 1.0"/>
      </material>
    </visual>
    <collision name="pip_site3_link_col">
      <origin rpy="0 0 0" xyz="0 0 0"/>
      <geometry>
        <sphere radius="0.005"/>
      </geometry>
    </collision>
    <inertial>
      <origin rpy="0 0 0" xyz="0 0 0"/>
      <mass value="1e-05"/>
      <inertia ixx="8.333333333333334e-11" ixy="0" ixz="0" iyy="8.333333333333334e-11" iyz="0" izz="1.25e-10"/>
    </inertial>
  </link>
  <joint name="pip_site3_joint" type="fixed">
    <parent link="pip_link"/>
    <child link="pip_site3_link"/>
    <origin rpy="0 0 -1.5707964" xyz="0 0 0.03"/>
    <axis xyz="1 0 0"/>
  </joint>
  <link name="dip_link">
    <visual name="dip_link_vis">
      <origin rpy="0 1.5707964 0" xyz="0 0 0"/>
      <geometry>
        <cylinder length="0.03" radius="0.02"/>
      </geometry>
      <material name="green">
        <color rgba="0.0 0.8 0.0 0.7"/>
      </material>
    </visual>
    <collision name="dip_link_col">
      <origin rpy="0 1.5707964 0" xyz="0 0 0"/>
      <geometry>
        <cylinder length="0.03" radius="0.02"/>
      </geometry>
    </collision>
    <inertial>
      <origin rpy="0 1.5707964 0" xyz="0 0 0"/>
      <mass value="0.1"/>
      <inertia ixx="1.7500000000000002e-05" ixy="0" ixz="0" iyy="1.7500000000000002e-05" iyz="0" izz="2e-05"/>
    </inertial>
  </link>
  <joint name="dip_joint" type="revolute">
    <parent link="pip_link"/>
    <child link="dip_link"/>
    <origin rpy="0 0 0" xyz="0 -0.1 0"/>
    <axis xyz="1 0 0"/>
    <limit effort="10" lower="-0.17453292519943295" upper="1.1344640137963142" velocity="0.8"/>
    <safety_controller k_position="121.0" k_velocity="540.0" soft_lower_limit="-0.12217304763960307" soft_upper_limit="1.0821041362364843"/>
    <dynamics damping="0.003" friction="0.2"/>
  </joint>
  <link name="dip_bar_linkage_link">
    <visual name="dip_bar_linkage_link_part1_vis">
      <origin rpy="0 0 0" xyz="0 0 0.05"/>
      <geometry>
        <cylinder length="0.1" radius="0.01"/>
      </geometry>
      <material name="yellow">
        <color rgba="0.9 1.0 0.0 0.7"/>
      </material>
    </visual>
    <visual name="dip_bar_linkage_link_part2_vis">
      <origin xyz="0 0 0.1"/>
      <geometry>
        <sphere radius="0.01"/>
      </geometry>
      <material name="yellow">
        <color rgba="0.9 1.0 0.0 0.7"/>
      </material>
    </visual>
    <visual name="dip_bar_linkage_link_part3_vis">
      <origin xyz="0 0 0.0"/>
      <geometry>
        <sphere radius="0.01"/>
      </geometry>
      <material name="yellow">
        <color rgba="0.9 1.0 0.0 0.7"/>
      </material>
    </visual>
    <collision name="dip_bar_linkage_link_part1_col">
      <origin rpy="0 0 0" xyz="0 0 0.05"/>
      <geometry>
        <cylinder length="0.1" radius="0.01"/>
      </geometry>
    </collision>
    <collision name="dip_bar_linkage_link_part2_col">
      <origin xyz="0 0 0.1"/>
      <geometry>
        <sphere radius="0.01"/>
      </geometry>
    </collision>
    <collision name="dip_bar_linkage_link_part3_col">
      <origin xyz="0 0 0.0"/>
      <geometry>
        <sphere radius="0.01"/>
      </geometry>
    </collision>
    <inertial>
      <origin rpy="0 0 0" xyz="0 0 0.05"/>
      <mass value="0.1"/>
      <inertia ixx="8.583333333333335e-05" ixy="0" ixz="0" iyy="8.583333333333335e-05" iyz="0" izz="5e-06"/>
    </inertial>
  </link>
  <joint name="dip_bar_linkage_fixed_joint" type="fixed">
    <parent link="dip_link"/>
    <child link="dip_bar_linkage_link"/>
    <origin rpy="1.5707964 0 0" xyz="0.0 0.0 0.0"/>
    <axis xyz="1 0 0"/>
  </joint>
  <link name="dip_site1_link">
    <visual name="dip_site1_link_vis">
      <origin rpy="0 0 0" xyz="0 0 0"/>
      <geometry>
        <sphere radius="0.005"/>
      </geometry>
      <material name="white">
        <color rgba="1.0 1.0 1.0 1.0"/>
      </material>
    </visual>
    <collision name="dip_site1_link_col">
      <origin rpy="0 0 0" xyz="0 0 0"/>
      <geometry>
        <sphere radius="0.005"/>
      </geometry>
    </collision>
    <inertial>
      <origin rpy="0 0 0" xyz="0 0 0"/>
      <mass value="1e-05"/>
      <inertia ixx="8.333333333333334e-11" ixy="0" ixz="0" iyy="8.333333333333334e-11" iyz="0" izz="1.25e-10"/>
    </inertial>
  </link>
  <joint name="dip_site1_joint" type="fixed">
    <parent link="dip_link"/>
    <child link="dip_site1_link"/>
    <origin rpy="0 0 -1.5707964" xyz="0 -0.03 0.01"/>
    <axis xyz="1 0 0"/>
  </joint>
  <link name="dip_site2_link">
    <visual name="dip_site2_link_vis">
      <origin rpy="0 0 0" xyz="0 0 0"/>
      <geometry>
        <sphere radius="0.005"/>
      </geometry>
      <material name="white">
        <color rgba="1.0 1.0 1.0 1.0"/>
      </material>
    </visual>
    <collision name="dip_site2_link_col">
      <origin rpy="0 0 0" xyz="0 0 0"/>
      <geometry>
        <sphere radius="0.005"/>
      </geometry>
    </collision>
    <inertial>
      <origin rpy="0 0 0" xyz="0 0 0"/>
      <mass value="1e-05"/>
      <inertia ixx="8.333333333333334e-11" ixy="0" ixz="0" iyy="8.333333333333334e-11" iyz="0" izz="1.25e-10"/>
    </inertial>
  </link>
  <joint name="dip_site2_joint" type="fixed">
    <parent link="dip_link"/>
    <child link="dip_site2_link"/>
    <origin rpy="0 0 -1.5707964" xyz="0 0 0.03"/>
    <axis xyz="1 0 0"/>
  </joint>
  <ros2_control name="finger_system" type="system">
    <hardware>
      <plugin>mujoco_ros2_control/MujocoSystem</plugin>
    </hardware>
    <joint name="tendon_joint">
      <param name="initial_position">0.0</param>
      <command_interface name="position"/>
      <command_interface name="velocity"/>
      <state_interface name="position">
        <param name="initial_value">0.0</param>
      </state_interface>
      <state_interface name="velocity"/>
      <state_interface name="effort"/>
    </joint>
    <transmission name="tendon_transmission">
      <plugin>transmission_interface/SimpleTransmission</plugin>
      <joint name="tendon_joint" role="joint1">
        <mechanical_reduction>1.0</mechanical_reduction>
        <offset>0</offset>
      </joint>
      <actuator name="tendon_actuator" role="actuator1">
        <mechanical_reduction>1.0</mechanical_reduction>
        <offset>0</offset>
      </actuator>
    </transmission>
    <joint name="mcp_joint">
      <param name="initial_position">0.0</param>
      <command_interface name="position"/>
      <command_interface name="velocity"/>
      <state_interface name="position">
        <param name="initial_value">0.0</param>
      </state_interface>
      <state_interface name="velocity"/>
      <state_interface name="effort"/>
    </joint>
    <transmission name="mcp_transmission">
      <plugin>transmission_interface/SimpleTransmission</plugin>
      <joint name="mcp_joint" role="joint1">
        <mechanical_reduction>1.0</mechanical_reduction>
        <offset>0</offset>
      </joint>
      <actuator name="mcp_actuator" role="actuator1">
        <mechanical_reduction>1.0</mechanical_reduction>
        <offset>0</offset>
      </actuator>
    </transmission>
    <joint name="pip_joint">
      <param name="initial_position">0.0</param>
      <command_interface name="position"/>
      <command_interface name="velocity"/>
      <state_interface name="position">
        <param name="initial_value">0.0</param>
      </state_interface>
      <state_interface name="velocity"/>
      <state_interface name="effort"/>
    </joint>
    <transmission name="pip_transmission">
      <plugin>transmission_interface/SimpleTransmission</plugin>
      <joint name="pip_joint" role="joint1">
        <mechanical_reduction>1.0</mechanical_reduction>
        <offset>0</offset>
      </joint>
      <actuator name="pip_actuator" role="actuator1">
        <mechanical_reduction>1.0</mechanical_reduction>
        <offset>0</offset>
      </actuator>
    </transmission>
    <joint name="dip_joint">
      <param name="initial_position">0.0</param>
      <command_interface name="position"/>
      <command_interface name="velocity"/>
      <state_interface name="position">
        <param name="initial_value">0.0</param>
      </state_interface>
      <state_interface name="velocity"/>
      <state_interface name="effort"/>
    </joint>
    <transmission name="dip_transmission">
      <plugin>transmission_interface/SimpleTransmission</plugin>
      <joint name="dip_joint" role="joint1">
        <mechanical_reduction>1.0</mechanical_reduction>
        <offset>0</offset>
      </joint>
      <actuator name="dip_actuator" role="actuator1">
        <mechanical_reduction>1.0</mechanical_reduction>
        <offset>0</offset>
      </actuator>
    </transmission>
  </ros2_control>
  <mujoco>
    <compiler angle="degree" balanceinertia="true" convexhull="true" discardvisual="false" eulerseq="xyz" fusestatic="false" meshdir="../meshes/finger/visual" strippath="true" texturedir="../textures/"/>
    <option collision="all" timestep="0.001"/>
  </mujoco>
</robot>
