<?xml version="1.0" ?>
<!-- =================================================================================== -->
<!-- |    This document was autogenerated by xacro from /home/neal/ws_humble/src/tendon_description/xacro/robot_leg/robot_leg.urdf.xacro | -->
<!-- |    EDITING THIS FILE BY HAND IS NOT RECOMMENDED                                 | -->
<!-- =================================================================================== -->
<robot name="tendon">
  <link name="base_link">
    <visual name="base_link_vis">
      <origin rpy="0 0 0" xyz="0 0 0"/>
      <geometry>
        <cylinder length="0.05" radius="0.03"/>
      </geometry>
      <material name="purple">
        <color rgba="0.2 0.2 0.5 1.0"/>
      </material>
    </visual>
    <collision name="base_link_col">
      <origin rpy="0 0 0" xyz="0 0 0"/>
      <geometry>
        <cylinder length="0.05" radius="0.03"/>
      </geometry>
    </collision>
    <inertial>
      <origin rpy="0 0 0" xyz="0 0 0"/>
      <mass value="0.5"/>
      <inertia ixx="0.00021666666666666668" ixy="0" ixz="0" iyy="0.00021666666666666668" iyz="0" izz="0.000225"/>
    </inertial>
  </link>
  <link name="hip_roll_link">
    <visual name="hip_roll_link_vis">
      <origin rpy="0 1.5707964 0" xyz="0 0 0 "/>
      <geometry>
        <cylinder length="0.03" radius="0.02"/>
      </geometry>
      <material name="green">
        <color rgba="0.0 0.8 0.0 0.7"/>
      </material>
    </visual>
    <collision name="hip_roll_link_col">
      <origin rpy="0 1.5707964 0" xyz="0 0 0 "/>
      <geometry>
        <cylinder length="0.03" radius="0.02"/>
      </geometry>
    </collision>
    <inertial>
      <origin rpy="0 1.5707964 0" xyz="0 0 0 "/>
      <mass value="0.1"/>
      <inertia ixx="1.7500000000000002e-05" ixy="0" ixz="0" iyy="1.7500000000000002e-05" iyz="0" izz="2e-05"/>
    </inertial>
  </link>
  <joint name="hip_roll_joint" type="revolute">
    <parent link="base_link"/>
    <child link="hip_roll_link"/>
    <origin rpy="1.5708 0.0002056 1.5708" xyz="-0.0835 0.115 0.0"/>
    <axis xyz="0 0 1"/>
    <limit effort="160.0" lower="-0.8377580409572781" upper="0.8377580409572781" velocity="2.0943951023931953"/>
    <safety_controller k_position="121.0" k_velocity="540.0" soft_lower_limit="-0.7853981633974483" soft_upper_limit="0.7853981633974483"/>
    <dynamics damping="1.3" friction="20.65"/>
  </joint>
  <link name="hip_yaw_link">
    <visual name="hip_yaw_link_vis">
      <origin rpy="0 1.5707964 0" xyz="0 0 0 "/>
      <geometry>
        <cylinder length="0.03" radius="0.02"/>
      </geometry>
      <material name="green">
        <color rgba="0.0 0.8 0.0 0.7"/>
      </material>
    </visual>
    <collision name="hip_yaw_link_col">
      <origin rpy="0 1.5707964 0" xyz="0 0 0 "/>
      <geometry>
        <cylinder length="0.03" radius="0.02"/>
      </geometry>
    </collision>
    <inertial>
      <origin rpy="0 1.5707964 0" xyz="0 0 0 "/>
      <mass value="0.1"/>
      <inertia ixx="1.7500000000000002e-05" ixy="0" ixz="0" iyy="1.7500000000000002e-05" iyz="0" izz="2e-05"/>
    </inertial>
  </link>
  <joint name="hip_yaw_joint" type="revolute">
    <parent link="hip_roll_link"/>
    <child link="hip_yaw_link"/>
    <origin rpy="-1.5707963267949 0.0 0.000205601491495962" xyz="0.0 -0.0158527210417825 0.0835"/>
    <axis xyz="0 0 1"/>
    <limit effort="80.0" lower="-0.8377580409572781" upper="0.8377580409572781" velocity="3.141592653589793"/>
    <safety_controller k_position="121.0" k_velocity="540.0" soft_lower_limit="-0.7853981633974483" soft_upper_limit="0.7853981633974483"/>
    <dynamics damping="1.3" friction="20.65"/>
  </joint>
  <!-- hip pitch -->
  <!-- <xacro:robot-link name="${joint3}_link"
      prefix="${prefix}"
      material_name="metal"
      gazebo="${gazebo}" /> -->
  <link name="hip_pitch_link">
    <visual name="hip_pitch_link_vis">
      <origin rpy="0 1.5707964 0" xyz="0 0 0 "/>
      <geometry>
        <cylinder length="0.03" radius="0.02"/>
      </geometry>
      <material name="green">
        <color rgba="0.0 0.8 0.0 0.7"/>
      </material>
    </visual>
    <collision name="hip_pitch_link_col">
      <origin rpy="0 1.5707964 0" xyz="0 0 0 "/>
      <geometry>
        <cylinder length="0.03" radius="0.02"/>
      </geometry>
    </collision>
    <inertial>
      <origin rpy="0 1.5707964 0" xyz="0 0 0 "/>
      <mass value="0.1"/>
      <inertia ixx="1.7500000000000002e-05" ixy="0" ixz="0" iyy="1.7500000000000002e-05" iyz="0" izz="2e-05"/>
    </inertial>
  </link>
  <joint name="hip_pitch_joint" type="revolute">
    <parent link="hip_yaw_link"/>
    <child link="hip_pitch_link"/>
    <origin rpy="-1.5707963267949 0.0 -1.5707963267949" xyz="0.0 0.0 -0.122575880574935"/>
    <axis xyz="0 0 1"/>
    <limit effort="80.0" lower="-1.8849555921538759" upper="1.8849555921538759" velocity="3.141592653589793"/>
    <safety_controller k_position="121.0" k_velocity="540.0" soft_lower_limit="-1.8325957145940461" soft_upper_limit="1.8325957145940461"/>
    <dynamics damping="0.1" friction="0.1"/>
  </joint>
  <link name="knee_pitch_link">
    <visual name="knee_pitch_link_vis">
      <origin rpy="0 1.5707964 0" xyz="0 0 0 "/>
      <geometry>
        <cylinder length="0.03" radius="0.02"/>
      </geometry>
      <material name="green">
        <color rgba="0.0 0.8 0.0 0.7"/>
      </material>
    </visual>
    <collision name="knee_pitch_link_col">
      <origin rpy="0 1.5707964 0" xyz="0 0 0 "/>
      <geometry>
        <cylinder length="0.03" radius="0.02"/>
      </geometry>
    </collision>
    <inertial>
      <origin rpy="0 1.5707964 0" xyz="0 0 0 "/>
      <mass value="0.1"/>
      <inertia ixx="1.7500000000000002e-05" ixy="0" ixz="0" iyy="1.7500000000000002e-05" iyz="0" izz="2e-05"/>
    </inertial>
  </link>
  <joint name="knee_pitch_joint" type="revolute">
    <parent link="hip_pitch_link"/>
    <child link="knee_pitch_link"/>
    <origin rpy="0.0 0.0 1.5707963267949" xyz="0.0 0.29 0.0"/>
    <axis xyz="0 0 1"/>
    <limit effort="80.0" lower="-0.05235987755982988" upper="1.8675022996339325" velocity="3.141592653589793"/>
    <safety_controller k_position="121.0" k_velocity="540.0" soft_lower_limit="0.0" soft_upper_limit="1.8151424220741028"/>
    <dynamics damping="0.1" friction="0.1"/>
  </joint>
  <link name="ankle_pitch_link">
    <visual name="ankle_pitch_link_vis">
      <origin rpy="0 1.5707964 0" xyz="0 0 0 "/>
      <geometry>
        <cylinder length="0.03" radius="0.02"/>
      </geometry>
      <material name="green">
        <color rgba="0.0 0.8 0.0 0.7"/>
      </material>
    </visual>
    <collision name="ankle_pitch_link_col">
      <origin rpy="0 1.5707964 0" xyz="0 0 0 "/>
      <geometry>
        <cylinder length="0.03" radius="0.02"/>
      </geometry>
    </collision>
    <inertial>
      <origin rpy="0 1.5707964 0" xyz="0 0 0 "/>
      <mass value="0.1"/>
      <inertia ixx="1.7500000000000002e-05" ixy="0" ixz="0" iyy="1.7500000000000002e-05" iyz="0" izz="2e-05"/>
    </inertial>
  </link>
  <joint name="ankle_pitch_joint" type="revolute">
    <parent link="knee_pitch_link"/>
    <child link="ankle_pitch_link"/>
    <origin rpy="0.0 0.0 0.0" xyz="0.339999999999999 0.0 0.0"/>
    <axis xyz="0 0 1"/>
    <limit effort="80.0" lower="-0.5934119456780721" upper="0.4886921905584123" velocity="3.141592653589793"/>
    <safety_controller k_position="121.0" k_velocity="540.0" soft_lower_limit="-0.5410520681182421" soft_upper_limit="0.4363323129985824"/>
    <dynamics damping="0.1" friction="0.1"/>
  </joint>
  <link name="ankle_roll_link">
    <visual name="ankle_roll_link_vis">
      <origin rpy="0 1.5707964 0" xyz="0 0 0 "/>
      <geometry>
        <cylinder length="0.03" radius="0.02"/>
      </geometry>
      <material name="green">
        <color rgba="0.0 0.8 0.0 0.7"/>
      </material>
    </visual>
    <collision name="ankle_roll_link_col">
      <origin rpy="0 1.5707964 0" xyz="0 0 0 "/>
      <geometry>
        <cylinder length="0.03" radius="0.02"/>
      </geometry>
    </collision>
    <inertial>
      <origin rpy="0 1.5707964 0" xyz="0 0 0 "/>
      <mass value="0.1"/>
      <inertia ixx="1.7500000000000002e-05" ixy="0" ixz="0" iyy="1.7500000000000002e-05" iyz="0" izz="2e-05"/>
    </inertial>
  </link>
  <joint name="ankle_roll_joint" type="revolute">
    <parent link="ankle_pitch_link"/>
    <child link="ankle_roll_link"/>
    <origin rpy="1.57079632679495 0.0 0.0" xyz="0.023 0.0 0.0"/>
    <axis xyz="0 0 1"/>
    <limit effort="80.0" lower="-0.8028514559173915" upper="0.5410520681182421" velocity="3.141592653589793"/>
    <safety_controller k_position="121.0" k_velocity="540.0" soft_lower_limit="-0.7504915783575616" soft_upper_limit="0.4886921905584123"/>
    <dynamics damping="0.1" friction="0.1"/>
  </joint>
  <ros2_control name="robot_leg_system" type="system">
    <hardware>
      <plugin>mujoco_ros2_control/MujocoSystem</plugin>
    </hardware>
    <joint name="hip_roll_joint">
      <param name="initial_position">0.0</param>
      <command_interface name="position"/>
      <command_interface name="velocity"/>
      <state_interface name="position">
        <param name="initial_value">0.0</param>
      </state_interface>
      <state_interface name="velocity"/>
      <state_interface name="effort"/>
    </joint>
    <transmission name="hip_roll_transmission">
      <plugin>transmission_interface/SimpleTransmission</plugin>
      <joint name="hip_roll_joint" role="joint1">
        <mechanical_reduction>1.0</mechanical_reduction>
        <offset>0</offset>
      </joint>
      <actuator name="hip_roll_actuator" role="actuator1">
        <mechanical_reduction>1.0</mechanical_reduction>
        <offset>0</offset>
      </actuator>
    </transmission>
    <joint name="hip_yaw_joint">
      <param name="initial_position">0.0</param>
      <command_interface name="position"/>
      <command_interface name="velocity"/>
      <state_interface name="position">
        <param name="initial_value">0.0</param>
      </state_interface>
      <state_interface name="velocity"/>
      <state_interface name="effort"/>
    </joint>
    <transmission name="hip_yaw_transmission">
      <plugin>transmission_interface/SimpleTransmission</plugin>
      <joint name="hip_yaw_joint" role="joint1">
        <mechanical_reduction>1.0</mechanical_reduction>
        <offset>0</offset>
      </joint>
      <actuator name="hip_yaw_actuator" role="actuator1">
        <mechanical_reduction>1.0</mechanical_reduction>
        <offset>0</offset>
      </actuator>
    </transmission>
    <joint name="hip_pitch_joint">
      <param name="initial_position">0.0</param>
      <command_interface name="position"/>
      <command_interface name="velocity"/>
      <state_interface name="position">
        <param name="initial_value">0.0</param>
      </state_interface>
      <state_interface name="velocity"/>
      <state_interface name="effort"/>
    </joint>
    <transmission name="hip_pitch_transmission">
      <plugin>transmission_interface/SimpleTransmission</plugin>
      <joint name="hip_pitch_joint" role="joint1">
        <mechanical_reduction>1.0</mechanical_reduction>
        <offset>0</offset>
      </joint>
      <actuator name="hip_pitch_actuator" role="actuator1">
        <mechanical_reduction>1.0</mechanical_reduction>
        <offset>0</offset>
      </actuator>
    </transmission>
    <joint name="knee_pitch_joint">
      <param name="initial_position">0.0</param>
      <command_interface name="position"/>
      <command_interface name="velocity"/>
      <state_interface name="position">
        <param name="initial_value">0.0</param>
      </state_interface>
      <state_interface name="velocity"/>
      <state_interface name="effort"/>
    </joint>
    <transmission name="knee_pitch_transmission">
      <plugin>transmission_interface/SimpleTransmission</plugin>
      <joint name="knee_pitch_joint" role="joint1">
        <mechanical_reduction>1.0</mechanical_reduction>
        <offset>0</offset>
      </joint>
      <actuator name="knee_pitch_actuator" role="actuator1">
        <mechanical_reduction>1.0</mechanical_reduction>
        <offset>0</offset>
      </actuator>
    </transmission>
    <joint name="ankle_pitch_joint">
      <param name="initial_position">0.0</param>
      <command_interface name="position"/>
      <command_interface name="velocity"/>
      <state_interface name="position">
        <param name="initial_value">0.0</param>
      </state_interface>
      <state_interface name="velocity"/>
      <state_interface name="effort"/>
    </joint>
    <transmission name="ankle_pitch_transmission">
      <plugin>transmission_interface/SimpleTransmission</plugin>
      <joint name="ankle_pitch_joint" role="joint1">
        <mechanical_reduction>1.0</mechanical_reduction>
        <offset>0</offset>
      </joint>
      <actuator name="ankle_pitch_actuator" role="actuator1">
        <mechanical_reduction>1.0</mechanical_reduction>
        <offset>0</offset>
      </actuator>
    </transmission>
    <joint name="ankle_roll_joint">
      <param name="initial_position">0.0</param>
      <command_interface name="position"/>
      <command_interface name="velocity"/>
      <state_interface name="position">
        <param name="initial_value">0.0</param>
      </state_interface>
      <state_interface name="velocity"/>
      <state_interface name="effort"/>
    </joint>
    <transmission name="ankle_roll_transmission">
      <plugin>transmission_interface/SimpleTransmission</plugin>
      <joint name="ankle_roll_joint" role="joint1">
        <mechanical_reduction>1.0</mechanical_reduction>
        <offset>0</offset>
      </joint>
      <actuator name="ankle_roll_actuator" role="actuator1">
        <mechanical_reduction>1.0</mechanical_reduction>
        <offset>0</offset>
      </actuator>
    </transmission>
  </ros2_control>
  <mujoco>
    <compiler angle="degree" balanceinertia="true" convexhull="true" discardvisual="false" eulerseq="xyz" fusestatic="false" meshdir="../meshes/robot_leg/visual" strippath="true" texturedir="../textures/"/>
    <option collision="all" timestep="0.001"/>
  </mujoco>
</robot>
